Workbook
Name mos: '[1]Общие данные'!$C$23:$D$23
Name mulk: '[1]Общие данные'!$C$24:$W$24

Sheet umumiy_malumot
A1: =CONCATENATE(B65," olish uchun ariza") -> mikroqarz olish uchun ariza | B1: №3-BR
A2: =CONCATENATE(B65," olish uchun ariza sanasi QO’L BILAN KIRITILADI") -> mikroqarz olish uchun ariza sanasi QO’L BILAN KIRITILADI | B2: 06.01.2026 | D2: =180+B2 -> 46208
A4: Qarz oluvchi bo’yicha ma’lumotlar
A5: Ariza beruvchining FISh (kim? – Ibragimov Rustam Sadikovich) | B5: TURAYEV ISROIL BURIYEVICH
A6: agar o’zgarishlar bo’lgan bo’lsa oldingi FISh (Sadikov Rustam Sadikovich yoki yo’q) | B6: yo’q | C6: ha | D6: yo’q
A7: Ariza beruvchining FISh (kim? – Ibragimov R.S.) | B7: TURAYEV I.B.
A8: FISh (ariza kimdan? – Ibragimov Rustam Sadikovichdan) | B8: =B5 -> TURAYEV ISROIL BURIYEVICH
A9: FISh (kimdan? – Ibragimov R.S.dan) | B9: =B7 -> TURAYEV I.B.
A10: FISh (kimga? – Ibragimov Rustam Sadikovichga) | B10: =B8 -> TURAYEV ISROIL BURIYEVICH
A11: FISh (kimga? – Ibragimov R.S.ga) | B11: =B9 -> TURAYEV I.B.
A12: FISh (kim bilan? – Ibragimov Rustam Sadikovich bilan) | B12: =B10 -> TURAYEV ISROIL BURIYEVICH
A13: FISh (kim bilan? – Ibragimov R.S. bilan) | B13: =B11 -> TURAYEV I.B.
A14: Fuqaroligi (O’zbekiston Respublikasi) | B14: O’zbekiston Respublikasi
A15: Tug’ilgan sanasi (01.10.2011 yil) | B15: 14.11.1983 yil
A16: Pasport seriyasi (СА №1234567) | B16: AD 6760672
B17: IIV 61013 | D17: =TEXT(C17,"ДД.ММ.ГГГГ") -> 00.01.1900
B18: 45390 | C18: =TEXT(B18,"ДД.ММ.ГГГГ") -> 08.04.2024
B19: 49041 | C19: =TEXT(B19,"ДД.ММ.ГГГГ") -> 07.04.2034
A20: Kim va qachon berilgan (Toshkent shahri Chilonzor IIB tomonidan 2011 yil __.____) | B20: =""&B17&" tomonidan "&C18&" yilda berilgan" -> IIV 61013 tomonidan 08.04.2024 yilda berilgan | C20: =""&B17&" tomonidan "&C18&" yilda berilgan" -> IIV 61013 tomonidan 08.04.2024 yilda berilgan
A21: Pasportni amal qilish muddati (01.10.2011 yilgacha / yoki muddatsiz) | B21: =""&C19&" y." -> 07.04.2034 y. | C21: =""&C19&" yilgacha" -> 07.04.2034 yilgacha
A22: doimiy ro’yhatdan o’tgan joyi (Toshkent sh., Mirobod tumani, Nukus ko’chasi, 1 uy, 1 honadon) | B22: BUXORO VILOYATI KOGON SHAHRI ZAFAROBOD 17-UY | C22: =TEXT(B19,"ДД.ММ.ГГГГ") -> 07.04.2034
A23: doimiy ro’yhatdan o’tgan joyi haqiqatdagi turar joyi bilan mos keladi/mos kelmaydi | B23: mos keladi | C23: mos keladi | D23: mos kelmaydi
A24: Ro’yhatdan o’tish joyida yashash asosi | B24: Mulk huquqi | C24: Mulk huquqi | D24: ijara | F24: служебная | G24: другое | H24: -
A25: Telefon raqami kod bilan ((99871) 277 77 77) | B25: 91 923 50 54 MIJOZ
A26: Mo’ljal | B26: BGGK ZONA
B27: =IF(B23="mos keladi",B22,B28) -> BUXORO VILOYATI KOGON SHAHRI ZAFAROBOD 17-UY
A28: Haqiqatdagi yashash joyi (Toshkent sh., Mirobod tumani, Nukus ko’chasi, 1 uy, 1 honadon) | B28: BUXORO VILOYATI KOGON SHAHRI ZAFAROBOD 17-UY
A29: Haqiqatdagi yashash joyida turish asosi | B29: Mulk huquqi | C29: Mulk huquqi | D29: ijara | F29: xizmat | G29: boshqa | H29: -
A30: Mijozning jinsi | B30: erkak | C30: erkak | D30: ayol
A31: Tug’ilgan joyi (Toshkent) | B31: KOGON SHAHRI
A32: Fuqaroligi (O’zbekiston Respublikasi) | B32: O’zbekiston Respublikasi
A33: Telefon raqami kod bilan ((99871) 277 77 77)TEGILMASIN | B33: =B25 -> 91 923 50 54 MIJOZ
B34: =IF(B23="mos keladi",B26,B35) -> BGGK ZONA
A35: Mo’ljal
A36: Oilaviy ahvoli
A37: Oila a'zolari soni (jami):
A38: Ma’lumoti
A39: Mutaxassisligi
A40: Ish telefoni raqami kod bilan ((99890) 3270000)TEGILMASIN | B40: =B25 -> 91 923 50 54 MIJOZ
A41: Mobil telefon raqami kod bilan ((99890) 3270000) | B41: 50 377 80 88 OTASI TO'LOVCHI
...

Sheet muqova
B2: =umumiy_malumot!B148 -> «PULLOL BUSINESS MIKROMOLIYA TASHKILOTI» MChJ
B12: =umumiy_malumot!B5 -> TURAYEV ISROIL BURIYEVICH
B19: =""&umumiy_malumot!C64&" shartnoma "&umumiy_malumot!B74&"" -> Mikroqarz shartnoma 6 yanvar 2026 y.dan №3-BR
B24: =" Foiz stavkasi: "&umumiy_malumot!B85&"%" -> Foiz stavkasi: 55%
B25: =" "&umumiy_malumot!C64&" muddati: "&umumiy_malumot!B81&" oy" -> Mikroqarz muddati: 36 oy
B26: =" "&umumiy_malumot!C64&" miqdori: "&FIXED(umumiy_malumot!B75,2)&" so'm" -> Mikroqarz miqdori: 33 000 000,00 so'm
B40: ="Toshkent sh., "&umumiy_malumot!B70&"" -> Toshkent sh., 6 yanvar 2026 y.

Sheet anketa
A2: ANKETA
E3: =umumiy_malumot!B68 -> 6 yanvar 2026 y.
A5: Mijozning to'liq ismi sharifi | C5: =umumiy_malumot!B8 -> TURAYEV ISROIL BURIYEVICH
A7: Siz ommaviy mansabdor shaxsmisiz? | D7: Ha
D8: Yo'q
A9: Yaqin qarindoshlaringiz orasida ommaviy mansabdor shaxslar bormi? | D9: Ha
D10: Yo'q
A11: Do'stlaringiz yoki yaqinlaringizdan birontasi ommaviy mansabdor shaxsmi? | D11: Ha
D12: Yo'q
A13: Yuqoridagi savollardan biriga «Ha» deb javob bergan bo'lsangiz, javobingizni qisqacha tushuntirib bering:
A18: Siz bank amaliyotlarini amalga oshirishda uchinchi shaxsning manfaatlarini ifodalaysizmi? | D18: Ha
D19: Yo'q
A20: Agar oldingi savolga «HA» deb javob bergan bo'lsangiz, bank operatsiyalarini bajarich uchun ishonchnomangiz bormi? | D20: Ha
D21: Yo'q
A23: Agar oldingi savolga «YO'Q» deb javob bergan bo'lsangiz, javobingizni qisqacha tushuntirib bering:
A28: Ommaviy mansabdor shaxslar — doimiy, vaqtincha yoki maxsus vakolatli organ tomonidan tayinlangan yoki saylangan, tashkiliy-maʼmuriy funktsiyalarni bajaruvchi hamda xorijiy davlatning qonun chiqaruvchi, ijro etuvchi, maʼmuriy yoki sud organida yoxud xalqaro tashkilotda yuridik ahamiyatga molik harakatlarni amalga oshirishga vakolatli shaxslar, shuningdek xorijiy davlatlar korxonalarining yuqori martabali rahbarlari, taniqli siyosatchilar va xorijiy davlatlar siyosiy partiyalarining taniqli a'zolari.
A30: Anketadagi barcha ma'lumotlar to'g'ri, agar o'zgarishlar bo'lsa, men bu haqida xabardor qilish majburiyatini o'z zimmamga olaman.
A33: =C5 -> TURAYEV ISROIL BURIYEVICH

Sheet mijoz_anketasi
A1: MIJOZNING ANKETASI
A2: Anketa kredit menejeri tomonidan mijozning javoblarini kiritish orqali to'ldiriladi, kerak bo'lganda, Mijoz tomonidan tanlangan javob variantlarini belgilash orqali amalga oshiriladi
A3: 1. MIJOZ HAQIDA MA'LUMOTLAR:
A4: =xulosa!A4:E4 -> Mijozning to'liq ismi sharifi: TURAYEV ISROIL BURIYEVICH
A5: =xulosa!A5:E5 -> Tug'ilgan sanasi: 14.11.1983 yil
A6: =xulosa!A6:E6 -> Pasport seriyasi AD 6760672 IIV 61013 tomonidan 08.04.2024 yilda berilgan, amal qilish muddati - 07.04.2034 y.
A7: ="Fuqaroligi: "&umumiy_malumot!B32&"" -> Fuqaroligi: O’zbekiston Respublikasi
A8: =xulosa!A7:E7 -> Ro‘yxatdan o‘tgan manzili: BUXORO VILOYATI KOGON SHAHRI ZAFAROBOD 17-UY, mo'ljal: BGGK ZONA
A9: =IF(umumiy_malumot!B23="mos keladi"," ",mijoz_anketasi!A10:F10)
A10: ="Haqiqatdan yashash joy manzili: "&umumiy_malumot!B28&"" -> Haqiqatdan yashash joy manzili: BUXORO VILOYATI KOGON SHAHRI ZAFAROBOD 17-UY
A11: =xulosa!A8:E8 -> Ish joyi: lavozimi Yakka tartibdagi tadbirkorda Yakka tartibdagi tadbirkor
A12: 2. Mijoz bilan ulanich uchun aloqa ma'lumotlari:
A13: ="Uy telefoni raqami: "&umumiy_malumot!B40&"" -> Uy telefoni raqami: 91 923 50 54 MIJOZ
A14: ="Uyali telefon raqami: "&umumiy_malumot!B41&"" -> Uyali telefon raqami: 50 377 80 88 OTASI TO'LOVCHI
A15: ="Uyali telefon raqami: "&umumiy_malumot!B42&"" -> Uyali telefon raqami: 93 000 16 05 O'G'LI
A16: ="Uyali telefon raqami: "&umumiy_malumot!B42&"" -> Uyali telefon raqami: 93 000 16 05 O'G'LI
A17: ="Ish telefoni raqami: "&umumiy_malumot!B43&"" -> Ish telefoni raqami:
A18: 3. MIJOZNING ISH JOYI HAQIDA MA'LUMOT:
A19: ="Muassasa nomlanishi:"&umumiy_malumot!B58&"" -> Muassasa nomlanishi:Yakka tartibdagi tadbirkor
A20: ="Ro‘yxatdan o‘tish manzili:"&umumiy_malumot!B50&"" -> Ro‘yxatdan o‘tish manzili:
A21: ="Lavozimi: "&umumiy_malumot!B59&"" -> Lavozimi: Yakka tartibdagi tadbirkor
A22: 4. MIJOZNING OYLIK DAROMADLARI VA XARAJATLARI HAQIDA MA'LUMOT
A23: Daromad manbalari | B23: Mijoz | C23: Turmush o'rtog'i | D23: Boshqa oila a'zolari | E23: Xarajatlar | F23: Мiqdori
A24: ish haqi (asosiy ish) | B24: =umumiy_malumot!B60 -> 5000000 | C24: 0 | D24: 0 | E24: uy-joy va kommunal xizmatlar uchun to'lov | F24: 700000
A25: ish haqi (o‘rindoshlik) | B25: 0 | C25: 0 | D25: 0 | E25: oilaviy xarajatlar | F25: 500000
A26: boshqa daromadlar | B26: =umumiy_malumot!B61 -> 5000000 | C26: 0 | D26: 0 | E26: boshqa xarajatlar | F26: 500000
A27: JAMI | B27: =B24+B25+B26 -> 10000000 | C27: =SUM(C24:C26) -> 0 | D27: =SUM(D24:D26) -> 0 | F27: =SUM(F24:F26) -> 1700000
A28: ="Men, "&umumiy_malumot!B5&", ushbu anketada ko‘rsatilgan barcha ma'lumotlar anketa to'ldirilgan sanada to'g'ri va aniq ekanligini tasdiqlayman." -> Men, TURAYEV ISROIL BURIYEVICH, ushbu anketada ko‘rsatilgan barcha ma'lumotlar anketa to'ldirilgan sanada to'g'ri va aniq ekanligini tasdiqlayman.
A29: ="Men, "&umumiy_malumot!B5&", quyidagilarni tan olaman va roziman::" -> Men, TURAYEV ISROIL BURIYEVICH, quyidagilarni tan olaman va roziman::
A30: ="1. Ushbu anketada ko‘rsatilgan har qanday ma’lumot "&umumiy_malumot!B147&", uning xodimlari va huquqiy vorislari tomonidan istalgan manbaa va ma’lumotlardan foydalangan holda istalgan vaqtda tekshirilishi va qayta tekshirilishi mumkin." -> 1. Ushbu anketada ko‘rsatilgan har qanday ma’lumot «PULLOL BUSINESS MIKROMOLIYA TASHKILOTI» MChJ, uning xodimlari va huquqiy vorislari tomonidan istalgan manbaa va ma’lumotlardan foydalangan holda istalgan vaqtda tekshirilishi va qayta tekshirilishi mumkin.
A31: ="2. Mazkur anketaning "&umumiy_malumot!B147&" tomonidan qabul qilinishi «PULLOL BUSINESS MIKROMOLIYA TASHKILOTI» MChJ tomonidan menga "&umumiy_malumot!B65&" berish majburiyatini yuklamaydi." -> 2. Mazkur anketaning «PULLOL BUSINESS MIKROMOLIYA TASHKILOTI» MChJ tomonidan qabul qilinishi «PULLOL BUSINESS MIKROMOLIYA TASHKILOTI» MChJ tomonidan menga mikroqarz berish majburiyatini yuklamaydi.
A32: Men, _________________________________________________________________ (to'liq ismi sharifi), ushbu anketadagi barcha ma'lumotlar anketa to'ldirilgan sanada to'g'ri ekanligini tasdiqlayman va ushbu anketaning 1- va 2-bandlarini tan olaman va ularga rozilik bildiraman. Mazkur anketaning 4-bo'limida ko'rsatilgan daromadlarim haqidagi ma'lumotlarni qabul qilishingizni va moliyaviy tahlilda foydalanishingizni so’rayman.
A34: Mijozning to'liq ismi sharifi | D34: Sana | E34: Imzo
D35: =umumiy_malumot!B2 -> 06.01.2026

Sheet kredit_ariza
C1: =""&umumiy_malumot!B147&"ning "&umumiy_malumot!A150&"" -> «PULLOL BUSINESS MIKROMOLIYA TASHKILOTI» MChJning Buxoro filiali boshlig'i
D2: =""&umumiy_malumot!B150&"ga" -> IKROMOV B.A.ga
A4: =""&umumiy_malumot!C64&" olish uchun Ariza" -> Mikroqarz olish uchun Ariza
A6: =""&umumiy_malumot!B28&".-da yashovchi O‘zbekiston Respublikasi fuqarosi "&umumiy_malumot!B8&"dan. " -> BUXORO VILOYATI KOGON SHAHRI ZAFAROBOD 17-UY.-da yashovchi O‘zbekiston Respublikasi fuqarosi TURAYEV ISROIL BURIYEVICHdan.
A7: ="Tug'ilgan kuni: "&umumiy_malumot!B15&"" -> Tug'ilgan kuni: 14.11.1983 yil
A8: ="Pasport seriyasi: "&umumiy_malumot!B16&" "&umumiy_malumot!B20&"" -> Pasport seriyasi: AD 6760672 IIV 61013 tomonidan 08.04.2024 yilda berilgan
A9: ="Asosiy ish joyi : "&umumiy_malumot!B58&"" -> Asosiy ish joyi : Yakka tartibdagi tadbirkor
A10: ="Lavozimi: "&umumiy_malumot!B59&"" -> Lavozimi: Yakka tartibdagi tadbirkor
A11: ="O’rtacha oylik daromadi: "&FIXED(mijoz_anketasi!B27,2)&" so'm." -> O’rtacha oylik daromadi: 10 000 000,00 so'm.
A12: ="Menga quyidagi shartlarda "&umumiy_malumot!B65&" berishingizni so’rayman:" -> Menga quyidagi shartlarda mikroqarz berishingizni so’rayman:
A13: =""&umumiy_malumot!C64&" summasi: "&FIXED(umumiy_malumot!B75,2)&" ("&umumiy_malumot!B76&") so'm." -> Mikroqarz summasi: 33 000 000,00 (o'ttiz uch million so'm) so'm.
A14: =""&umumiy_malumot!C64&" muddati: "&umumiy_malumot!B81&" ("&umumiy_malumot!B82&") oy." -> Mikroqarz muddati: 36 (o'ttiz olti) oy.
A15: =""&umumiy_malumot!C64&"dan foydalanganlik uchun foiz stavkasi: yillik "&umumiy_malumot!B85&"% ("&umumiy_malumot!B86&") foiz" -> Mikroqarzdan foydalanganlik uchun foiz stavkasi: yillik 55% (ellik besh) foiz
A16: =""&umumiy_malumot!C64&" bo'yicha asosiy qarz va foizlarni to'lash:" -> Mikroqarz bo'yicha asosiy qarz va foizlarni to'lash:
A17: =" - "&umumiy_malumot!B65&" shartnomasi bo'yicha har oy differensial to'lovlari amalga oshiriladi" -> - mikroqarz shartnomasi bo'yicha har oy differensial to'lovlari amalga oshiriladi
A18: =" - "&umumiy_malumot!B65&" shartnomasi bo'yicha har oy annuitet to'lovlari amalga oshiriladi" -> - mikroqarz shartnomasi bo'yicha har oy annuitet to'lovlari amalga oshiriladi
A19: =IF(umumiy_malumot!B77=umumiy_malumot!C77,kredit_ariza!A17:D17,IF(umumiy_malumot!B77=umumiy_malumot!D77,kredit_ariza!A18:D18)) -> - mikroqarz shartnomasi bo'yicha har oy differensial to'lovlari amalga oshiriladi
A20: =IF(DAY(umumiy_malumot!F67)<15," "," Oxirgi yakuniy to'lov "&umumiy_malumot!B65&" shartnomasi tuzilgan kundan boshlab oxirgi oyning oxirgi kunida amalga oshiriladi")
A21: =""&umumiy_malumot!C64&" ta’minoti::" -> Mikroqarz ta’minoti::
A22: =IF(umumiy_malumot!B103="Avtotransport",A26,A23) -> Egalik huquqi USMONOV NURIDDID IXTIYOROVICHga tegishli bo'lgan garovga olingan avtomobil markasi COBALT, rangi - OQ OLIMPIYSKAYA BELAYA, ishlab chiqarilgan yili - 2016, davlat raqam belgisi 80G291QA, kuzov turi - YENGIL SEDAN, kuzov raqami XWBJF69VEGA010429, dvigatel raqami B15D211163412DJCX0337, shassi raqami - RAKAMSIZ
A23: =IF(umumiy_malumot!B92=umumiy_malumot!C92,A25,IF(umumiy_malumot!B92=umumiy_malumot!D92,A24,0)) -> Egalik huquqi 0ga tegishli bo'lgan umumiy maydoni - 72,13 va yashash maydoni - 37,39 3 - xonali yakka tartibdagi uy-joy, SAMARQAND VILOYATI TAYLOQ TUMANI CHAROG'BON MFY YANGI TAYLOQ QISHLOG'I 6 TURAR JOY 12 QAVAT 58 XONADON
A24: =" - Navbatdagi garov (ipoteka) Egalik huquqi asosida "&umumiy_malumot!C117&"ga "&umumiy_malumot!C126&", umumiy maydoni - "&umumiy_malumot!C130&" va yashash maydoni - "&umumiy_malumot!C133&", manzili: "&umumiy_malumot!C123&"." -> - Navbatdagi garov (ipoteka) Egalik huquqi asosida 0ga 3 - xonali yakka tartibdagi uy-joy, umumiy maydoni - 72,13 va yashash maydoni - 37,39, manzili: SAMARQAND VILOYATI TAYLOQ TUMANI CHAROG'BON MFY YANGI TAYLOQ QISHLOG'I 6 TURAR JOY 12 QAVAT 58 XONADON.
A25: =" Egalik huquqi "&umumiy_malumot!C117&"ga tegishli bo'lgan umumiy maydoni - "&umumiy_malumot!C130&" va yashash maydoni - "&umumiy_malumot!C133&" "&umumiy_malumot!C126&", "&umumiy_malumot!C123&" " -> Egalik huquqi 0ga tegishli bo'lgan umumiy maydoni - 72,13 va yashash maydoni - 37,39 3 - xonali yakka tartibdagi uy-joy, SAMARQAND VILOYATI TAYLOQ TUMANI CHAROG'BON MFY YANGI TAYLOQ QISHLOG'I 6 TURAR JOY 12 QAVAT 58 XONADON
A26: =IF(umumiy_malumot!B92=umumiy_malumot!C92,kredit_ariza!A28:D28,IF(umumiy_malumot!B92=umumiy_malumot!D92,kredit_ariza!A27:D27,0)) -> Egalik huquqi USMONOV NURIDDID IXTIYOROVICHga tegishli bo'lgan garovga olingan avtomobil markasi COBALT, rangi - OQ OLIMPIYSKAYA BELAYA, ishlab chiqarilgan yili - 2016, davlat raqam belgisi 80G291QA, kuzov turi - YENGIL SEDAN, kuzov raqami XWBJF69VEGA010429, dvigatel raqami B15D211163412DJCX0337, shassi raqami - RAKAMSIZ
A27: =" Egalik huquqi "&umumiy_malumot!B117&"ga tegishli bo'lgan "&umumiy_malumot!B125&", "&umumiy_malumot!B133&", davlat raqam belgisi "&umumiy_malumot!B126&", "&umumiy_malumot!B127&", "&umumiy_malumot!B130&" avtotransport vositasi " -> Egalik huquqi USMONOV NURIDDID IXTIYOROVICHga tegishli bo'lgan COBALT, rangi - OQ OLIMPIYSKAYA BELAYA, ishlab chiqarilgan yili - 2016, davlat raqam belgisi 80G291QA, kuzov turi - YENGIL SEDAN, kuzov raqami XWBJF69VEGA010429, dvigatel raqami B15D211163412DJCX0337, shassi raqami - RAKAMSIZ avtotransport vositasi
A28: =" Egalik huquqi "&umumiy_malumot!B117&"ga tegishli bo'lgan garovga olingan avtomobil markasi "&umumiy_malumot!B125&", "&umumiy_malumot!B133&", davlat raqam belgisi "&umumiy_malumot!B126&", "&umumiy_malumot!B127&", "&umumiy_malumot!B130&"" -> Egalik huquqi USMONOV NURIDDID IXTIYOROVICHga tegishli bo'lgan garovga olingan avtomobil markasi COBALT, rangi - OQ OLIMPIYSKAYA BELAYA, ishlab chiqarilgan yili - 2016, davlat raqam belgisi 80G291QA, kuzov turi - YENGIL SEDAN, kuzov raqami XWBJF69VEGA010429, dvigatel raqami B15D211163412DJCX0337, shassi raqami - RAKAMSIZ
A30: ="Mazkur ariza bilan "&umumiy_malumot!B147&"ga men va soʻralayotgan "&umumiy_malumot!B65&" boʻyicha barcha zarur maʼlumotlarni quyida ko’rsatilgan tashkilotlarga taqdim etish va olishga roziligimni bildirib, ushbu amaliyotlarni o’tkazish uchun huquq beraman:" -> Mazkur ariza bilan «PULLOL BUSINESS MIKROMOLIYA TASHKILOTI» MChJga men va soʻralayotgan mikroqarz boʻyicha barcha zarur maʼlumotlarni quyida ko’rsatilgan tashkilotlarga taqdim etish va olishga roziligimni bildirib, ushbu amaliyotlarni o’tkazish uchun huquq beraman:
A31: □ O‘zbekiston Respublikasi Markaziy banki huzuridagi kredit axborotining davlat reestri;
A32: □ Kredit-axborot tahliliy markazi «O‘zbekiston Respublikasi kredit byurosi» MChJ;
A33: □ Garov reestri taqdim etilgan garov mulki haqida.
A34: ="Ariza berilgan sana: "&TEXT(umumiy_malumot!B2,"ДД.ММ.ГГГГ")&"y." -> Ariza berilgan sana: 06.01.2026y.
A36: Ariza berilgan kuniga barcha ma'lumotlar ishonchligini tasdiqlab, ushbu arizani imzolayman
A39: =umumiy_malumot!B5 -> TURAYEV ISROIL BURIYEVICH | D39: P________________
D40: (imzo)

Sheet majburiyatnoma
A3: MAJBURIYATNOMA
A4: =" Men, fuqaro "&umumiy_malumot!B5&" "&umumiy_malumot!B149&" bilan "&umumiy_malumot!B69&" sanasidagi "&umumiy_malumot!B66&"-sonli shartnomaning garov ta'minoti sifatida taqdim etilayotgan mulk "&umumiy_malumot!B125&" rusumli avtotransport vositasini qonunga xilof ravishda o‘zlashtirmaslikka, yashirmaslikka, nobud qilmaslikka yoki unga shikast yetkazmaslik majburiyatini olaman." -> Men, fuqaro TURAYEV ISROIL BURIYEVICH «PULLOL BUSINESS MIKROMOLIYA TASHKILOTI» MChJ bilan 6 yanvar 2026 y. sanasidagi №3-BR-sonli shartnomaning garov ta'minoti sifatida taqdim etilayotgan mulk COBALT rusumli avtotransport vositasini qonunga xilof ravishda o‘zlashtirmaslikka, yashirmaslikka, nobud qilmaslikka yoki unga shikast yetkazmaslik majburiyatini olaman.
A5: Ushbu majburiyatlarimni bajarmagan taqdirimda O'zbekiston Respublikasi jinoyat kodeksining 233-moddasi talablari asosida javobgarlik tog'risida ogohlantrildim.
A7: =umumiy_malumot!B5 -> TURAYEV ISROIL BURIYEVICH | B7: Imzo_____________
A9: =umumiy_malumot!B105 -> USMONOV NURIDDID IXTIYOROVICH | B9: Imzo_____________
A11: ="sana: "&TEXT(umumiy_malumot!B2,"ДД.ММ.ГГГГ")&" y." -> sana: 06.01.2026 y.

Sheet garov_ariza
B6: =umumiy_malumot!B148 -> «PULLOL BUSINESS MIKROMOLIYA TASHKILOTI» MChJ
B7: =""&umumiy_malumot!A150&" "&umumiy_malumot!B150&"ga" -> Buxoro filiali boshlig'i IKROMOV B.A.ga
B8: =""&umumiy_malumot!B111&"dan" -> USMONOV NURIDDID IXTIYOROVICHdan
B9: =umumiy_malumot!B111 -> USMONOV NURIDDID IXTIYOROVICH
B10: =umumiy_malumot!C111 -> 0
B11: dan
A13: =IF(umumiy_malumot!B103="Avtotransport",A14,A15) -> TURAYEV ISROIL BURIYEVICH tomonidan so’ralayotgan 36 (o'ttiz olti) oy muddatga, 33 000 000 (o'ttiz uch million so'm) miqdoridagi mikroqarzning ta’minoti sifatida menga mulk huquqi asosida tegishli bo’lgan COBALT, kuzov turi - YENGIL SEDAN, kuzov raqami XWBJF69VEGA010429, dvigatel raqami B15D211163412DJCX0337, shassi raqami - RAKAMSIZ, rangi - OQ OLIMPIYSKAYA BELAYA, ishlab chiqarilgan yili - 2016, avtotransport vositasini qabul qilishingizni so’rayman:
A14: =""&umumiy_malumot!B12&" tomonidan so’ralayotgan "&umumiy_malumot!B81&" ("&umumiy_malumot!B82&") oy muddatga, "&FIXED(umumiy_malumot!B75,0)&" ("&umumiy_malumot!B76&") miqdoridagi "&umumiy_malumot!B65&"ning ta’minoti sifatida menga mulk huquqi asosida tegishli bo’lgan "&umumiy_malumot!B125&", "&umumiy_malumot!B127&", "&umumiy_malumot!B130&", "&umumiy_malumot!B133&", avtotransport vositasini qabul qilishingizni so’rayman:" -> TURAYEV ISROIL BURIYEVICH tomonidan so’ralayotgan 36 (o'ttiz olti) oy muddatga, 33 000 000 (o'ttiz uch million so'm) miqdoridagi mikroqarzning ta’minoti sifatida menga mulk huquqi asosida tegishli bo’lgan COBALT, kuzov turi - YENGIL SEDAN, kuzov raqami XWBJF69VEGA010429, dvigatel raqami B15D211163412DJCX0337, shassi raqami - RAKAMSIZ, rangi - OQ OLIMPIYSKAYA BELAYA, ishlab chiqarilgan yili - 2016, avtotransport vositasini qabul qilishingizni so’rayman:
A15: =""&umumiy_malumot!B12&" tomonidan so’ralayotgan "&umumiy_malumot!B81&" ("&umumiy_malumot!B82&") oy muddatga, "&FIXED(umumiy_malumot!B75,0)&" ("&umumiy_malumot!B76&") miqdoridagi "&umumiy_malumot!B65&"ning ta’minoti sifatida menga mulk huquqi asosida tegishli bo’lgan "&umumiy_malumot!C126&", umumiy maydoni "&umumiy_malumot!C130&" va yashash maydoni "&umumiy_malumot!C133&" "&umumiy_malumot!C123&" manzilda joylashgan ko'chmas mulkni qabul qilishingizni so’rayman:" -> TURAYEV ISROIL BURIYEVICH tomonidan so’ralayotgan 36 (o'ttiz olti) oy muddatga, 33 000 000 (o'ttiz uch million so'm) miqdoridagi mikroqarzning ta’minoti sifatida menga mulk huquqi asosida tegishli bo’lgan 3 - xonali yakka tartibdagi uy-joy, umumiy maydoni 72,13 va yashash maydoni 37,39 SAMARQAND VILOYATI TAYLOQ TUMANI CHAROG'BON MFY YANGI TAYLOQ QISHLOG'I 6 TURAR JOY 12 QAVAT 58 XONADON manzilda joylashgan ko'chmas mulkni qabul qilishingizni so’rayman:
B18: Sana:
A19: =IF(umumiy_malumot!B94=umumiy_malumot!C94,umumiy_malumot!B112,umumiy_malumot!B7) -> TURAYEV I.B. | B19: =umumiy_malumot!B2 -> 06.01.2026
A20: =IF(umumiy_malumot!B94=umumiy_malumot!D94,CONCATENATE(A23," ",A28,A22),"") -> №202602386000102 06.01.2026 sanasidan xususiy faoliyat ko'rsatuvchi notarius tomonidan BUXORO VILOYATI BUXORO SHAHRI ASHXOBOD KO'CHASI 1/3-UY SHARIPOV ZAFAR JO'RABOYEVICH berilgan ishonchnomaga asosan
A22: =" xususiy faoliyat ko'rsatuvchi notarius tomonidan "&umumiy_malumot!B98&" "&umumiy_malumot!B99&" berilgan ishonchnomaga asosan " -> xususiy faoliyat ko'rsatuvchi notarius tomonidan BUXORO VILOYATI BUXORO SHAHRI ASHXOBOD KO'CHASI 1/3-UY SHARIPOV ZAFAR JO'RABOYEVICH berilgan ishonchnomaga asosan
A23: ="№"&umumiy_malumot!B100& "" -> №202602386000102
A25: =umumiy_malumot!B102 -> 06.01.2026
A26: =TEXT(A25,"ДД.ММ.ГГГГ") -> 06.01.2026
A27: sanasidan
A28: =CONCATENATE(A26,A27) -> 06.01.2026 sanasidan

Sheet xulosa
A1: =""&umumiy_malumot!B147&" mikromoliya tashkilotining Xulosasi" -> «PULLOL BUSINESS MIKROMOLIYA TASHKILOTI» MChJ mikromoliya tashkilotining Xulosasi
A3: MIJOZ HAQIDA MA'LUMOTLAR
A4: ="Mijozning to'liq ismi sharifi: "&umumiy_malumot!B5&"" -> Mijozning to'liq ismi sharifi: TURAYEV ISROIL BURIYEVICH
A5: ="Tug'ilgan sanasi: "&umumiy_malumot!B15&"" -> Tug'ilgan sanasi: 14.11.1983 yil
A6: ="Pasport seriyasi "&umumiy_malumot!B16&" "&umumiy_malumot!B20&", amal qilish muddati - "&umumiy_malumot!B21&"" -> Pasport seriyasi AD 6760672 IIV 61013 tomonidan 08.04.2024 yilda berilgan, amal qilish muddati - 07.04.2034 y.
A7: ="Ro‘yxatdan o‘tgan manzili: "&umumiy_malumot!B28&", mo'ljal: "&umumiy_malumot!B26&"" -> Ro‘yxatdan o‘tgan manzili: BUXORO VILOYATI KOGON SHAHRI ZAFAROBOD 17-UY, mo'ljal: BGGK ZONA
A8: ="Ish joyi: "&umumiy_malumot!B52&" lavozimi "&umumiy_malumot!B49&"da "&umumiy_malumot!B44&"" -> Ish joyi: lavozimi Yakka tartibdagi tadbirkorda Yakka tartibdagi tadbirkor
A10: ="Mijoz tomonidan so’ralgan "&umumiy_malumot!B65&" shartlari:" -> Mijoz tomonidan so’ralgan mikroqarz shartlari:
A11: =kredit_ariza!A13:D13 -> Mikroqarz summasi: 33 000 000,00 (o'ttiz uch million so'm) so'm.
A12: =kredit_ariza!A14:D14 -> Mikroqarz muddati: 36 (o'ttiz olti) oy.
A13: =kredit_ariza!A15:D15 -> Mikroqarzdan foydalanganlik uchun foiz stavkasi: yillik 55% (ellik besh) foiz
A14: =kredit_ariza!A16:D16 -> Mikroqarz bo'yicha asosiy qarz va foizlarni to'lash:
A15: =kredit_ariza!A19:D19 -> - mikroqarz shartnomasi bo'yicha har oy differensial to'lovlari amalga oshiriladi
A16: =kredit_ariza!A20:D20
A17: =kredit_ariza!A21:D21 -> Mikroqarz ta’minoti::
A18: =kredit_ariza!A22:D22 -> Egalik huquqi USMONOV NURIDDID IXTIYOROVICHga tegishli bo'lgan garovga olingan avtomobil markasi COBALT, rangi - OQ OLIMPIYSKAYA BELAYA, ishlab chiqarilgan yili - 2016, davlat raqam belgisi 80G291QA, kuzov turi - YENGIL SEDAN, kuzov raqami XWBJF69VEGA010429, dvigatel raqami B15D211163412DJCX0337, shassi raqami - RAKAMSIZ
A19: Mijozning moliyaviy holati
A20: ="Anketaga muvofiq "&umumiy_malumot!B9&"ning o‘rtacha oylik daromadi "&FIXED(mijoz_anketasi!B27)&" so‘mni tashkil etdi." -> Anketaga muvofiq TURAYEV I.B.ning o‘rtacha oylik daromadi 10 000 000,00 so‘mni tashkil etdi.
A21: ="Mijozning o'rtacha oylik xarajatlari "&FIXED(mijoz_anketasi!F27)&" so'mni tashkil etdi" -> Mijozning o'rtacha oylik xarajatlari 1 700 000,00 so'mni tashkil etdi
A22: =IF(umumiy_malumot!B77=umumiy_malumot!C77,xulosa!A23:E23,xulosa!A24:E24) -> Mikroqarz shartnomasi bo'yicha birinchi oy uchun to'lov 2 955 433,90 so'mni tashkil etadi.
A23: =""&umumiy_malumot!C64&" shartnomasi bo'yicha birinchi oy uchun to'lov "&FIXED(umumiy_malumot!B90)&" so'mni tashkil etadi." -> Mikroqarz shartnomasi bo'yicha birinchi oy uchun to'lov 2 955 433,90 so'mni tashkil etadi.
A24: =""&umumiy_malumot!C64&" bo‘yicha oylik "&umumiy_malumot!B77&" to‘lovi miqdori "&FIXED(umumiy_malumot!B90)&" so‘mni tashkil etadi." -> Mikroqarz bo‘yicha oylik differensial to‘lovi miqdori 2 955 433,90 so‘mni tashkil etadi.
A25: Mijoz quyidagi majburiyatlarga ega: "TOShKENT Sh., АT XАLQ BАNKI BOSh АMАLIYOTLАR BOShQАRMАSI 9 320 690.00 so'm, DENGI VPERED" MCHJ QO'SHMA KORXONA MIKROMOLIYA TASHKILOTI 710 640.00., Ayni paytda muddati o'tgan qarzdorligi mavjud emas. O‘rtacha oylik to‘lov 2 005 011.07 so‘mni tashkil qiladi.
A26: =""&umumiy_malumot!C64&" bo’yicha ta’minot:" -> Mikroqarz bo’yicha ta’minot:
A27: =" - "&umumiy_malumot!B117&" ga mulk huquqi asosida tegishli avtotransport vositasi "&umumiy_malumot!B125&" , quyidagi tafsilotlarga muvofiq:" -> - USMONOV NURIDDID IXTIYOROVICH ga mulk huquqi asosida tegishli avtotransport vositasi COBALT , quyidagi tafsilotlarga muvofiq:
A28: =" - "&umumiy_malumot!C117&" ga mulk huquqi asosida tegishli ko'chmas mulk shaklida "&umumiy_malumot!C126&", manzili: "&umumiy_malumot!C123&", quyidagi tafsilotlarga muvofiq:" -> - 0 ga mulk huquqi asosida tegishli ko'chmas mulk shaklida 3 - xonali yakka tartibdagi uy-joy, manzili: SAMARQAND VILOYATI TAYLOQ TUMANI CHAROG'BON MFY YANGI TAYLOQ QISHLOG'I 6 TURAR JOY 12 QAVAT 58 XONADON, quyidagi tafsilotlarga muvofiq:
A29: =IF(umumiy_malumot!B103="Avtotransport",xulosa!A27:E27,xulosa!A28:E28) -> - USMONOV NURIDDID IXTIYOROVICH ga mulk huquqi asosida tegishli avtotransport vositasi COBALT , quyidagi tafsilotlarga muvofiq:
A30: =dalolatnoma!A29 -> Nomi | B30: =dalolatnoma!B29 -> Kuzov turi va kuzov raqami* | C30: =dalolatnoma!C29 -> Dvigatel va shassi raqami* | D30: =dalolatnoma!D29 -> Ishlab chiqarilgan yili va rangi* | E30: =dalolatnoma!E29 -> Kelishilgan garov qiymati, so'm
A31: =dalolatnoma!A30 -> COBALT | B31: =dalolatnoma!B30 -> kuzov turi - YENGIL SEDAN, kuzov raqami XWBJF69VEGA010429 | C31: =dalolatnoma!C30 -> dvigatel raqami B15D211163412DJCX0337, shassi raqami - RAKAMSIZ | D31: =dalolatnoma!D30 -> rangi - OQ OLIMPIYSKAYA BELAYA, ishlab chiqarilgan yili - 2016 | E31: =dalolatnoma!E30 -> 46 200 000,00 (qirq olti million ikki yuz ming so'm)
A32: =dalolatnoma!A22 -> -* avtotransport egasi: USMONOV NURIDDID IXTIYOROVICH
A33: =dalolatnoma!A23 -> -* texnik pasport: AAF 2401056 01.12.2020 y.
A34: =dalolatnoma!A24 -> -* roʻyxatdan oʻtgan manzili/garaj manzili: BUXORO VILOYATI BUXORO SHAHRI CHO'LPON KO'CHASI 22-A-UY
A35: =dalolatnoma!A25 -> -* davlat raqami: 80G291QA
A37: =""&umumiy_malumot!B147&" mikromoliya tashkilotining Xulosasi" -> «PULLOL BUSINESS MIKROMOLIYA TASHKILOTI» MChJ mikromoliya tashkilotining Xulosasi
A38: =""&umumiy_malumot!B147&" kredit qo‘mitasining xulosasiga quyidagi shartlarda "&umumiy_malumot!B10&"ga "&umumiy_malumot!B65&" berish masalasi kiritiladi:" -> «PULLOL BUSINESS MIKROMOLIYA TASHKILOTI» MChJ kredit qo‘mitasining xulosasiga quyidagi shartlarda TURAYEV ISROIL BURIYEVICHga mikroqarz berish masalasi kiritiladi:
A39: =A11 -> Mikroqarz summasi: 33 000 000,00 (o'ttiz uch million so'm) so'm.
A40: =A12 -> Mikroqarz muddati: 36 (o'ttiz olti) oy.
A41: =A13 -> Mikroqarzdan foydalanganlik uchun foiz stavkasi: yillik 55% (ellik besh) foiz
A42: =A14 -> Mikroqarz bo'yicha asosiy qarz va foizlarni to'lash:
A43: =A15 -> - mikroqarz shartnomasi bo'yicha har oy differensial to'lovlari amalga oshiriladi
...

Sheet qaror
A1: =""&umumiy_malumot!B147&" mikromoliya tashkiloti Kredit qo‘mitasining yig‘ilishi" -> «PULLOL BUSINESS MIKROMOLIYA TASHKILOTI» MChJ mikromoliya tashkiloti Kredit qo‘mitasining yig‘ilishi
A2: =""&H7&" protokolidan ko'chirma" -> №3-BR protokolidan ko'chirma
A3: Toshkent shahri | E3: =umumiy_malumot!B68 -> 6 yanvar 2026 y.
B4: KUN TARTIBI:
A5: =" "&H8&"."&umumiy_malumot!B5&" ga "&umumiy_malumot!B65&" berish masalasini ko‘rib chiqish to‘g‘risida." -> 1.TURAYEV ISROIL BURIYEVICH ga mikroqarz berish masalasini ko‘rib chiqish to‘g‘risida.
A7: =" "&H9&" masala yuzasidan: «PULLOL BUSINESS MIKROMOLIYA TASHKILOTI» MChJ mikromoliya tashkiloti kredit bo‘yicha menejeri "&umumiy_malumot!B5&"ga "&FIXED(umumiy_malumot!B75)&" ("&umumiy_malumot!B76&") so‘m miqdorida, muddati "&umumiy_malumot!B81&" ("&umumiy_malumot!B82&") oyga va yillik "&umumiy_malumot!B85&"% ("&umumiy_malumot!B86&") foiz miqdorida "&umumiy_malumot!B65&" berich bo‘yicha "&umumiy_malumot!B5&"ning kredit arizasi va "&umumiy_malumot!B147&"ning xulosasi bilan ishtirokchilarni tanishtirdi." -> Birinchi masala yuzasidan: «PULLOL BUSINESS MIKROMOLIYA TASHKILOTI» MChJ mikromoliya tashkiloti kredit bo‘yicha menejeri TURAYEV ISROIL BURIYEVICHga 33 000 000,00 (o'ttiz uch million so'm) so‘m miqdorida, muddati 36 (o'ttiz olti) oyga va yillik 55% (ellik besh) foiz miqdorida mikroqarz berich bo‘yicha TURAYEV ISROIL BURIYEVICHning kredit arizasi va «PULLOL BUSINESS MIKROMOLIYA TASHKILOTI» MChJning xulosasi bilan ishtirokchilarni tanishtirdi. | G7: Protokol raqami | H7: =umumiy_malumot!B1 -> №3-BR
G8: Savol raqami | H8: 1 | I8: 1 | J8: 2 | K8: 3 | L8: 4 | M8: 5 | N8: 6 | O8: 7 | P8: 8 | Q8: 9 | R8: 10 | S8: 11 | T8: 12 | U8: 13 | V8: 14 | W8: 15 | X8: 16 | Y8: 17 | Z8: 18 | AA8: 19 | AB8: 20 | AC8: 21 | AD8: 22 | AE8: 23 | AF8: 24 | AG8: 25
G9: Savol raqami qol bilan | H9: =IF(H8=I8,I9,IF(H8=J8,J9,IF(H8=K8,K9,IF(H8=L8,L9,IF(H8=M8,M9,IF(H8=N8,N9,IF(H8=O8,O9,IF(H8=P8,P9,IF(H8=Q8,Q9,IF(H8=R8,R9,IF(H8=S8,S9,IF(H8=T8,T9,IF(H8=U8,U9,IF(H8=V8,V9,IF(H8=W8,W9,IF(H8=X8,X9,IF(H8=Y8,Y9,IF(H8=Z8,Z9,IF(H8=AA8,AA9,IF(H8=AB8,AB9,IF(H8=AC8,AC9,IF(H8=AD8,AD9,IF(H8=AE8,AE9,IF(H8=AF8,AF9,IF(H8=AG8,AG9))))))))))))))))))))))))) -> Birinchi | I9: Birinchi | J9: Ikkinchi | K9: Uchinchi | L9: To'rtinchi | M9: Beshinchi | N9: O'ltinchi | O9: Yettinchi | P9: Sakkizinchi | Q9: Tuqqizinchi | R9: O'ninchi | S9: O'n birinchi | T9: O'n ikkinchi | U9: O'n uchinchi | V9: O'n to'rtinchi | W9: O'n beshinchi | X9: O'n oltinchi | Y9: O'n yettinchi | Z9: O'n sakkizinchi | AA9: O'n tuqqizinchi | AB9: Yigirmanchi | AC9: Yigirma birinchi | AD9: Yigizma ikkinchi | AE9: Yigirma uchinchi | AF9: Yigirma to'rtinchi | AG9: Yigirma beshinchi
A14: =""&umumiy_malumot!C64&" ta’minoti:" -> Mikroqarz ta’minoti:
A16: =xulosa!A18:E18 -> Egalik huquqi USMONOV NURIDDID IXTIYOROVICHga tegishli bo'lgan garovga olingan avtomobil markasi COBALT, rangi - OQ OLIMPIYSKAYA BELAYA, ishlab chiqarilgan yili - 2016, davlat raqam belgisi 80G291QA, kuzov turi - YENGIL SEDAN, kuzov raqami XWBJF69VEGA010429, dvigatel raqami B15D211163412DJCX0337, shassi raqami - RAKAMSIZ
C17: masala yuzasidan berilgan ma’lumotlarni muhokama qilib, Kredit qo‘mitasi a’zolariga taqdim etilgan zarur hujjatlarni o‘rganib, majlisda ishtirok etgan Kredit qo‘mitasi a’zolarining taklif va mulohazalarini inobatga olgan holda | D17: =""&umumiy_malumot!B147&" kredit qo‘mitasi" -> «PULLOL BUSINESS MIKROMOLIYA TASHKILOTI» MChJ kredit qo‘mitasi | E17: =CONCATENATE(C17,D17) -> masala yuzasidan berilgan ma’lumotlarni muhokama qilib, Kredit qo‘mitasi a’zolariga taqdim etilgan zarur hujjatlarni o‘rganib, majlisda ishtirok etgan Kredit qo‘mitasi a’zolarining taklif va mulohazalarini inobatga olgan holda «PULLOL BUSINESS MIKROMOLIYA TASHKILOTI» MChJ kredit qo‘mitasi
A18: =CONCATENATE(H9,E17) -> Birinchi masala yuzasidan berilgan ma’lumotlarni muhokama qilib, Kredit qo‘mitasi a’zolariga taqdim etilgan zarur hujjatlarni o‘rganib, majlisda ishtirok etgan Kredit qo‘mitasi a’zolarining taklif va mulohazalarini inobatga olgan holda «PULLOL BUSINESS MIKROMOLIYA TASHKILOTI» MChJ kredit qo‘mitasi
A19: QAROR QILADI:
A20: =" "&umumiy_malumot!B5&"ga quyidagi shartlarda "&umumiy_malumot!B65&" berish masalasi ma’qullansin:" -> TURAYEV ISROIL BURIYEVICHga quyidagi shartlarda mikroqarz berish masalasi ma’qullansin:
A21: ="1. "&umumiy_malumot!C64&" summasi: "&FIXED(umumiy_malumot!B75)&" ("&umumiy_malumot!B76&") so'm." -> 1. Mikroqarz summasi: 33 000 000,00 (o'ttiz uch million so'm) so'm.
A22: ="2. "&umumiy_malumot!C64&" muddati: "&umumiy_malumot!B81&" ("&umumiy_malumot!B82&") oy " -> 2. Mikroqarz muddati: 36 (o'ttiz olti) oy
A23: ="3. "&umumiy_malumot!C64&"dan foydalanganlik uchun foiz stavkasi:yillik "&umumiy_malumot!B85&"% ("&umumiy_malumot!B86&") foiz." -> 3. Mikroqarzdan foydalanganlik uchun foiz stavkasi:yillik 55% (ellik besh) foiz.
A24: ="4. "&umumiy_malumot!C64&" bo‘yicha asosiy qarz va foizlarni to‘lash:" -> 4. Mikroqarz bo‘yicha asosiy qarz va foizlarni to‘lash:
A25: =kredit_ariza!A19:D19 -> - mikroqarz shartnomasi bo'yicha har oy differensial to'lovlari amalga oshiriladi
A26: ="5. "&umumiy_malumot!C64&" bo‘yicha garov "&xulosa!A29:E29&"" -> 5. Mikroqarz bo‘yicha garov - USMONOV NURIDDID IXTIYOROVICH ga mulk huquqi asosida tegishli avtotransport vositasi COBALT , quyidagi tafsilotlarga muvofiq:
A27: =dalolatnoma!A29 -> Nomi | B27: =dalolatnoma!B29 -> Kuzov turi va kuzov raqami* | C27: =dalolatnoma!C29 -> Dvigatel va shassi raqami* | D27: =dalolatnoma!D29 -> Ishlab chiqarilgan yili va rangi* | E27: =dalolatnoma!E29 -> Kelishilgan garov qiymati, so'm
A28: =dalolatnoma!A30 -> COBALT | B28: =dalolatnoma!B30 -> kuzov turi - YENGIL SEDAN, kuzov raqami XWBJF69VEGA010429 | C28: =dalolatnoma!C30 -> dvigatel raqami B15D211163412DJCX0337, shassi raqami - RAKAMSIZ | D28: =dalolatnoma!D30 -> rangi - OQ OLIMPIYSKAYA BELAYA, ishlab chiqarilgan yili - 2016 | E28: =dalolatnoma!E30 -> 46 200 000,00 (qirq olti million ikki yuz ming so'm)
A29: =dalolatnoma!A22:E22 -> -* avtotransport egasi: USMONOV NURIDDID IXTIYOROVICH
A30: =dalolatnoma!A23:E23 -> -* texnik pasport: AAF 2401056 01.12.2020 y.
A31: =dalolatnoma!A24:E24 -> -* roʻyxatdan oʻtgan manzili/garaj manzili: BUXORO VILOYATI BUXORO SHAHRI CHO'LPON KO'CHASI 22-A-UY
A32: =dalolatnoma!A25:E25 -> -* davlat raqami: 80G291QA
A34: 6. Boshqa shartlar – avtotransport vositasi shaklida garov ta'minlangandan keyin mikroqarz berish.
A36: Qaror bir ovozdan qabul qilindi.
A37: 1. Obidov Abdullo Shokir og'li
A38: 2. Akramov R.N.
A39: 3. Eshbekov S.O.

Sheet Данные для послед. Залога
A1: № | B1: - | E1: ФИО | F1: дата | L1: № договора | M1: Сог. Сумма | N1: сог. Сумма (пропис.)
A2: 1 | B2: ha | C2: yoq | D2: ha | E2: TULYAGANOV XODJIAKBAR IRGASHEVICH | F2: 44207 | G2: =MONTH(F2) -> 1 | H2: =IF(G2=$A$26,$A$28,IF(G2=$B$26,$B$28,IF(G2=$C$26,$C$28,IF(G2=$D$26,$D$28,IF(G2=$E$26,$E$28,IF(G2=$F$26,$F$28,IF(G2=$K$26,$K$28,IF(G2=$L$26,$L$28,IF(G2=$M$26,$M$28,IF(G2=$N$26,$N$28,IF(G2=$O$26,$O$28,IF(G2=$P$26,$P$28,0)))))))))))) -> yanvar | I2: =DAY(F2) -> 11 | J2: =YEAR(F2) -> 2021 | K2: =""&I2&" "&H2&" "&J2&" г." -> 11 yanvar 2021 г. | L2: 5 | M2: 15000000 | N2: on besh million | O2: ="- №"&L2&" от "&K2&", заключенного с ООО «Clever Mikrokredit Tashkiloti» и "&E2&", по согласованной залоговой стоимость - "&FIXED(M2)&" ("&N2&") сум." -> - №5 от 11 yanvar 2021 г., заключенного с ООО «Clever Mikrokredit Tashkiloti» и TULYAGANOV XODJIAKBAR IRGASHEVICH, по согласованной залоговой стоимость - 15 000 000,00 (on besh million) сум. | P2: =IF(D2=$B$2,O2,IF(D2=$C$2,$B$1)) -> - №5 от 11 yanvar 2021 г., заключенного с ООО «Clever Mikrokredit Tashkiloti» и TULYAGANOV XODJIAKBAR IRGASHEVICH, по согласованной залоговой стоимость - 15 000 000,00 (on besh million) сум. | W2: =""&P2&" "&P3&" "&P4&" "&P5&" "&P6&" "&P7&" "&P8&" "&P9&" "&P10&" "&P11&" "&P12&" "&P13&" "&P14&" "&P15&" "&P16&" "&P17&" "&P18&" "&P19&" "&P20&" "&P21&"" -> - №5 от 11 yanvar 2021 г., заключенного с ООО «Clever Mikrokredit Tashkiloti» и TULYAGANOV XODJIAKBAR IRGASHEVICH, по согласованной залоговой стоимость - 15 000 000,00 (on besh million) сум. - №386 от 6 noyabr 2019 г., заключенного с ООО «Clever Mikrokredit Tashkiloti» и YUNUSOVA ZALOXAT MIRSULTANOVNA, по согласованной залоговой стоимость - 15 000 000,00 (on besh million) сум. - №33 от 21 yanvar 2021 г., заключенного с ООО «Clever Mikrokredit Tashkiloti» и YUNUSOVA ZALOXAT MIRSULTANOVNA, по согласованной залоговой стоимость - 15 000 000,00 (on besh million) сум. 0 0 0 0 0 0 0 0 0 0 0 0 0 0 0 0 0
A3: 2 | D3: ha | E3: YUNUSOVA ZALOXAT MIRSULTANOVNA | F3: 43775 | G3: =MONTH(F3) -> 11 | H3: =IF(G3=$A$26,$A$28,IF(G3=$B$26,$B$28,IF(G3=$C$26,$C$28,IF(G3=$D$26,$D$28,IF(G3=$E$26,$E$28,IF(G3=$F$26,$F$28,IF(G3=$K$26,$K$28,IF(G3=$L$26,$L$28,IF(G3=$M$26,$M$28,IF(G3=$N$26,$N$28,IF(G3=$O$26,$O$28,IF(G3=$P$26,$P$28,0)))))))))))) -> noyabr | I3: =DAY(F3) -> 6 | J3: =YEAR(F3) -> 2019 | K3: =""&I3&" "&H3&" "&J3&" г." -> 6 noyabr 2019 г. | L3: 386 | M3: 15000000 | N3: on besh million | O3: ="- №"&L3&" от "&K3&", заключенного с ООО «Clever Mikrokredit Tashkiloti» и "&E3&", по согласованной залоговой стоимость - "&FIXED(M3)&" ("&N3&") сум." -> - №386 от 6 noyabr 2019 г., заключенного с ООО «Clever Mikrokredit Tashkiloti» и YUNUSOVA ZALOXAT MIRSULTANOVNA, по согласованной залоговой стоимость - 15 000 000,00 (on besh million) сум. | P3: =IF(D3=$B$2,O3,IF(D3=$C$2,$B$1)) -> - №386 от 6 noyabr 2019 г., заключенного с ООО «Clever Mikrokredit Tashkiloti» и YUNUSOVA ZALOXAT MIRSULTANOVNA, по согласованной залоговой стоимость - 15 000 000,00 (on besh million) сум.
A4: 3 | D4: ha | E4: YUNUSOVA ZALOXAT MIRSULTANOVNA | F4: 44217 | G4: =MONTH(F4) -> 1 | H4: =IF(G4=$A$26,$A$28,IF(G4=$B$26,$B$28,IF(G4=$C$26,$C$28,IF(G4=$D$26,$D$28,IF(G4=$E$26,$E$28,IF(G4=$F$26,$F$28,IF(G4=$K$26,$K$28,IF(G4=$L$26,$L$28,IF(G4=$M$26,$M$28,IF(G4=$N$26,$N$28,IF(G4=$O$26,$O$28,IF(G4=$P$26,$P$28,0)))))))))))) -> yanvar | I4: =DAY(F4) -> 21 | J4: =YEAR(F4) -> 2021 | K4: =""&I4&" "&H4&" "&J4&" г." -> 21 yanvar 2021 г. | L4: 33 | M4: 15000000 | N4: on besh million | O4: ="- №"&L4&" от "&K4&", заключенного с ООО «Clever Mikrokredit Tashkiloti» и "&E4&", по согласованной залоговой стоимость - "&FIXED(M4)&" ("&N4&") сум." -> - №33 от 21 yanvar 2021 г., заключенного с ООО «Clever Mikrokredit Tashkiloti» и YUNUSOVA ZALOXAT MIRSULTANOVNA, по согласованной залоговой стоимость - 15 000 000,00 (on besh million) сум. | P4: =IF(D4=$B$2,O4,IF(D4=$C$2,$B$1)) -> - №33 от 21 yanvar 2021 г., заключенного с ООО «Clever Mikrokredit Tashkiloti» и YUNUSOVA ZALOXAT MIRSULTANOVNA, по согласованной залоговой стоимость - 15 000 000,00 (on besh million) сум.
A5: 4 | D5: ha | G5: =MONTH(F5) -> 1 | H5: =IF(G5=$A$26,$A$28,IF(G5=$B$26,$B$28,IF(G5=$C$26,$C$28,IF(G5=$D$26,$D$28,IF(G5=$E$26,$E$28,IF(G5=$F$26,$F$28,IF(G5=$K$26,$K$28,IF(G5=$L$26,$L$28,IF(G5=$M$26,$M$28,IF(G5=$N$26,$N$28,IF(G5=$O$26,$O$28,IF(G5=$P$26,$P$28,0)))))))))))) -> yanvar | I5: =DAY(F5) -> 0 | J5: =YEAR(F5) -> 1900 | K5: =""&I5&" "&H5&" "&J5&" г." -> 0 yanvar 1900 г. | P5: =IF(D5=$B$2,O5,IF(D5=$C$2,$B$1)) -> 0
A6: 5 | D6: ha | G6: =MONTH(F6) -> 1 | H6: =IF(G6=$A$26,$A$28,IF(G6=$B$26,$B$28,IF(G6=$C$26,$C$28,IF(G6=$D$26,$D$28,IF(G6=$E$26,$E$28,IF(G6=$F$26,$F$28,IF(G6=$K$26,$K$28,IF(G6=$L$26,$L$28,IF(G6=$M$26,$M$28,IF(G6=$N$26,$N$28,IF(G6=$O$26,$O$28,IF(G6=$P$26,$P$28,0)))))))))))) -> yanvar | I6: =DAY(F6) -> 0 | J6: =YEAR(F6) -> 1900 | K6: =""&I6&" "&H6&" "&J6&" г." -> 0 yanvar 1900 г. | P6: =IF(D6=$B$2,O6,IF(D6=$C$2,$B$1)) -> 0
A7: 6 | D7: ha | G7: =MONTH(F7) -> 1 | H7: =IF(G7=$A$26,$A$28,IF(G7=$B$26,$B$28,IF(G7=$C$26,$C$28,IF(G7=$D$26,$D$28,IF(G7=$E$26,$E$28,IF(G7=$F$26,$F$28,IF(G7=$K$26,$K$28,IF(G7=$L$26,$L$28,IF(G7=$M$26,$M$28,IF(G7=$N$26,$N$28,IF(G7=$O$26,$O$28,IF(G7=$P$26,$P$28,0)))))))))))) -> yanvar | I7: =DAY(F7) -> 0 | J7: =YEAR(F7) -> 1900 | K7: =""&I7&" "&H7&" "&J7&" г." -> 0 yanvar 1900 г. | P7: =IF(D7=$B$2,O7,IF(D7=$C$2,$B$1)) -> 0
A8: 7 | D8: ha | G8: =MONTH(F8) -> 1 | H8: =IF(G8=$A$26,$A$28,IF(G8=$B$26,$B$28,IF(G8=$C$26,$C$28,IF(G8=$D$26,$D$28,IF(G8=$E$26,$E$28,IF(G8=$F$26,$F$28,IF(G8=$K$26,$K$28,IF(G8=$L$26,$L$28,IF(G8=$M$26,$M$28,IF(G8=$N$26,$N$28,IF(G8=$O$26,$O$28,IF(G8=$P$26,$P$28,0)))))))))))) -> yanvar | I8: =DAY(F8) -> 0 | J8: =YEAR(F8) -> 1900 | K8: =""&I8&" "&H8&" "&J8&" г." -> 0 yanvar 1900 г. | P8: =IF(D8=$B$2,O8,IF(D8=$C$2,$B$1)) -> 0
A9: 8 | D9: ha | G9: =MONTH(F9) -> 1 | H9: =IF(G9=$A$26,$A$28,IF(G9=$B$26,$B$28,IF(G9=$C$26,$C$28,IF(G9=$D$26,$D$28,IF(G9=$E$26,$E$28,IF(G9=$F$26,$F$28,IF(G9=$K$26,$K$28,IF(G9=$L$26,$L$28,IF(G9=$M$26,$M$28,IF(G9=$N$26,$N$28,IF(G9=$O$26,$O$28,IF(G9=$P$26,$P$28,0)))))))))))) -> yanvar | I9: =DAY(F9) -> 0 | J9: =YEAR(F9) -> 1900 | K9: =""&I9&" "&H9&" "&J9&" г." -> 0 yanvar 1900 г. | P9: =IF(D9=$B$2,O9,IF(D9=$C$2,$B$1)) -> 0
A10: 9 | D10: ha | G10: =MONTH(F10) -> 1 | H10: =IF(G10=$A$26,$A$28,IF(G10=$B$26,$B$28,IF(G10=$C$26,$C$28,IF(G10=$D$26,$D$28,IF(G10=$E$26,$E$28,IF(G10=$F$26,$F$28,IF(G10=$K$26,$K$28,IF(G10=$L$26,$L$28,IF(G10=$M$26,$M$28,IF(G10=$N$26,$N$28,IF(G10=$O$26,$O$28,IF(G10=$P$26,$P$28,0)))))))))))) -> yanvar | I10: =DAY(F10) -> 0 | J10: =YEAR(F10) -> 1900 | K10: =""&I10&" "&H10&" "&J10&" г." -> 0 yanvar 1900 г. | P10: =IF(D10=$B$2,O10,IF(D10=$C$2,$B$1)) -> 0
A11: 10 | D11: ha | G11: =MONTH(F11) -> 1 | H11: =IF(G11=$A$26,$A$28,IF(G11=$B$26,$B$28,IF(G11=$C$26,$C$28,IF(G11=$D$26,$D$28,IF(G11=$E$26,$E$28,IF(G11=$F$26,$F$28,IF(G11=$K$26,$K$28,IF(G11=$L$26,$L$28,IF(G11=$M$26,$M$28,IF(G11=$N$26,$N$28,IF(G11=$O$26,$O$28,IF(G11=$P$26,$P$28,0)))))))))))) -> yanvar | I11: =DAY(F11) -> 0 | J11: =YEAR(F11) -> 1900 | K11: =""&I11&" "&H11&" "&J11&" г." -> 0 yanvar 1900 г. | P11: =IF(D11=$B$2,O11,IF(D11=$C$2,$B$1)) -> 0
A12: 11 | D12: ha | G12: =MONTH(F12) -> 1 | H12: =IF(G12=$A$26,$A$28,IF(G12=$B$26,$B$28,IF(G12=$C$26,$C$28,IF(G12=$D$26,$D$28,IF(G12=$E$26,$E$28,IF(G12=$F$26,$F$28,IF(G12=$K$26,$K$28,IF(G12=$L$26,$L$28,IF(G12=$M$26,$M$28,IF(G12=$N$26,$N$28,IF(G12=$O$26,$O$28,IF(G12=$P$26,$P$28,0)))))))))))) -> yanvar | I12: =DAY(F12) -> 0 | J12: =YEAR(F12) -> 1900 | K12: =""&I12&" "&H12&" "&J12&" г." -> 0 yanvar 1900 г. | P12: =IF(D12=$B$2,O12,IF(D12=$C$2,$B$1)) -> 0
A13: 12 | D13: ha | G13: =MONTH(F13) -> 1 | H13: =IF(G13=$A$26,$A$28,IF(G13=$B$26,$B$28,IF(G13=$C$26,$C$28,IF(G13=$D$26,$D$28,IF(G13=$E$26,$E$28,IF(G13=$F$26,$F$28,IF(G13=$K$26,$K$28,IF(G13=$L$26,$L$28,IF(G13=$M$26,$M$28,IF(G13=$N$26,$N$28,IF(G13=$O$26,$O$28,IF(G13=$P$26,$P$28,0)))))))))))) -> yanvar | I13: =DAY(F13) -> 0 | J13: =YEAR(F13) -> 1900 | K13: =""&I13&" "&H13&" "&J13&" г." -> 0 yanvar 1900 г. | P13: =IF(D13=$B$2,O13,IF(D13=$C$2,$B$1)) -> 0
A14: 13 | D14: ha | G14: =MONTH(F14) -> 1 | H14: =IF(G14=$A$26,$A$28,IF(G14=$B$26,$B$28,IF(G14=$C$26,$C$28,IF(G14=$D$26,$D$28,IF(G14=$E$26,$E$28,IF(G14=$F$26,$F$28,IF(G14=$K$26,$K$28,IF(G14=$L$26,$L$28,IF(G14=$M$26,$M$28,IF(G14=$N$26,$N$28,IF(G14=$O$26,$O$28,IF(G14=$P$26,$P$28,0)))))))))))) -> yanvar | I14: =DAY(F14) -> 0 | J14: =YEAR(F14) -> 1900 | K14: =""&I14&" "&H14&" "&J14&" г." -> 0 yanvar 1900 г. | P14: =IF(D14=$B$2,O14,IF(D14=$C$2,$B$1)) -> 0
A15: 14 | D15: ha | G15: =MONTH(F15) -> 1 | H15: =IF(G15=$A$26,$A$28,IF(G15=$B$26,$B$28,IF(G15=$C$26,$C$28,IF(G15=$D$26,$D$28,IF(G15=$E$26,$E$28,IF(G15=$F$26,$F$28,IF(G15=$K$26,$K$28,IF(G15=$L$26,$L$28,IF(G15=$M$26,$M$28,IF(G15=$N$26,$N$28,IF(G15=$O$26,$O$28,IF(G15=$P$26,$P$28,0)))))))))))) -> yanvar | I15: =DAY(F15) -> 0 | J15: =YEAR(F15) -> 1900 | K15: =""&I15&" "&H15&" "&J15&" г." -> 0 yanvar 1900 г. | P15: =IF(D15=$B$2,O15,IF(D15=$C$2,$B$1)) -> 0
A16: 15 | D16: ha | G16: =MONTH(F16) -> 1 | H16: =IF(G16=$A$26,$A$28,IF(G16=$B$26,$B$28,IF(G16=$C$26,$C$28,IF(G16=$D$26,$D$28,IF(G16=$E$26,$E$28,IF(G16=$F$26,$F$28,IF(G16=$K$26,$K$28,IF(G16=$L$26,$L$28,IF(G16=$M$26,$M$28,IF(G16=$N$26,$N$28,IF(G16=$O$26,$O$28,IF(G16=$P$26,$P$28,0)))))))))))) -> yanvar | I16: =DAY(F16) -> 0 | J16: =YEAR(F16) -> 1900 | K16: =""&I16&" "&H16&" "&J16&" г." -> 0 yanvar 1900 г. | P16: =IF(D16=$B$2,O16,IF(D16=$C$2,$B$1)) -> 0
... A21: 20 | D21: ha | G21: =MONTH(F21) -> 1 | H21: =IF(G21=$A$26,$A$28,IF(G21=$B$26,$B$28,IF(G21=$C$26,$C$28,IF(G21=$D$26,$D$28,IF(G21=$E$26,$E$28,IF(G21=$F$26,$F$28,IF(G21=$K$26,$K$28,IF(G21=$L$26,$L$28,IF(G21=$M$26,$M$28,IF(G21=$N$26,$N$28,IF(G21=$O$26,$O$28,IF(G21=$P$26,$P$28,0)))))))))))) -> yanvar | I21: =DAY(F21) -> 0 | J21: =YEAR(F21) -> 1900 | K21: =""&I21&" "&H21&" "&J21&" г." -> 0 yanvar 1900 г. | P21: =IF(D21=$B$2,O21,IF(D21=$C$2,$B$1)) -> 0
M22: =SUM(M2:M21)+umumiy_malumot!B136 -> 91200000 | Q22: ottiz yetti million besh yuz ming
A25: =MONTH(F2) -> 1 | B25: =IF(A25=A26,A28,IF(A25=B26,B28,IF(A25=C26,C28,IF(A25=D26,D28,IF(A25=E26,E28,IF(A25=F26,F28,IF(A25=K26,K28,IF(A25=L26,L28,IF(A25=M26,M28,IF(A25=N26,N28,IF(A25=O26,O28,IF(A25=#REF!,#REF!,)))))))))))) -> yanvar | C25: =DAY(F2) -> 11 | D25: =YEAR(F2) -> 2021
A26: 1 | B26: 2 | C26: 3 | D26: 4 | E26: 5 | F26: 6 | K26: 7 | L26: 8 | M26: 9 | N26: 10 | O26: 11 | P26: 12
A28: yanvar | B28: fevral | C28: mart | D28: aprel | E28: may | F28: iyun | K28: июля | L28: avgust | M28: sentyabr | N28: oktyabr | O28: noyabr | P28: dekabr
A29: yanvar | B29: fevral | C29: mart | D29: aprel | E29: may | F29: iyun | K29: июль | L29: avgust | M29: sentyabr | N29: oktyabr | O29: noyabr | P29: dekabr

Sheet График аннуитет.
E1: Приложение №1
F2: ="к договору микрозайма "&umumiy_malumot!B74&"" -> к договору микрозайма 6 yanvar 2026 y.dan №3-BR
A4: График погашения
A6: № | B6: Дата погашения | C6: Остаток основного долга | D6: Сумма погашения, сум
D7: основного долга | E7: процентов* | F7: всего*
A8: 1 | B8: ='График дифференц'!B8 -> 46069 | C8: =umumiy_malumot!B75 -> 33000000 | D8: =IF(A8<umumiy_malumot!$B$81,'График аннуитет.'!F8-'График аннуитет.'!E8,'График аннуитет.'!C8) -> 916666.67 | E8: =ROUND(C8*umumiy_malumot!$B$84/H8,2)*'График аннуитет.'!G8 -> 2038767.2 | F8: =umumiy_malumot!B90 -> 2955433.9 | G8: =B8-umumiy_malumot!B67 -> 41 | H8: =DATE(YEAR(B8),12,31)-DATE(YEAR(B8),1,1)+1 -> 365
A9: 2 | B9: ='График дифференц'!B9 -> 46097 | C9: =C8-D8 -> 32083333 | D9: =IF(A9<umumiy_malumot!$B$81,'График аннуитет.'!F9-'График аннуитет.'!E9,'График аннуитет.'!C9) -> 1601780.9 | E9: =ROUND(C9*umumiy_malumot!$B$84/H9,2)*'График аннуитет.'!G9 -> 1353653 | F9: =IF(A9<umumiy_malumot!$B$81,'График аннуитет.'!F8,'График аннуитет.'!D9+'График аннуитет.'!E9) -> 2955433.9 | G9: =B9-B8 -> 28 | H9: =DATE(YEAR(B9),12,31)-DATE(YEAR(B9),1,1)+1 -> 365
A10: 3 | B10: ='График дифференц'!B10 -> 46127 | C10: =C9-D9 -> 30481552 | D10: =IF(A10<umumiy_malumot!$B$81,'График аннуитет.'!F10-'График аннуитет.'!E10,'График аннуитет.'!C10) -> 1577500.6 | E10: =ROUND(C10*umumiy_malumot!$B$84/H10,2)*'График аннуитет.'!G10 -> 1377933.3 | F10: =IF(A10<umumiy_malumot!$B$81,'График аннуитет.'!F9,'График аннуитет.'!D10+'График аннуитет.'!E10) -> 2955433.9 | G10: =B10-B9 -> 30 | H10: =DATE(YEAR(B10),12,31)-DATE(YEAR(B10),1,1)+1 -> 365
A11: 4 | B11: ='График дифференц'!B11 -> 46157 | C11: =C10-D10 -> 28904052 | D11: =IF(A11<umumiy_malumot!$B$81,'График аннуитет.'!F11-'График аннуитет.'!E11,'График аннуитет.'!C11) -> 1648812.4 | E11: =ROUND(C11*umumiy_malumot!$B$84/H11,2)*'График аннуитет.'!G11 -> 1306621.5 | F11: =IF(A11<umumiy_malumot!$B$81,'График аннуитет.'!F10,'График аннуитет.'!D11+'График аннуитет.'!E11) -> 2955433.9 | G11: =B11-B10 -> 30 | H11: =DATE(YEAR(B11),12,31)-DATE(YEAR(B11),1,1)+1 -> 365
A12: 5 | B12: ='График дифференц'!B12 -> 46188 | C12: =C11-D11 -> 27255239 | D12: =IF(A12<umumiy_malumot!$B$81,'График аннуитет.'!F12-'График аннуитет.'!E12,'График аннуитет.'!C12) -> 1682278.2 | E12: =ROUND(C12*umumiy_malumot!$B$84/H12,2)*'График аннуитет.'!G12 -> 1273155.7 | F12: =IF(A12<umumiy_malumot!$B$81,'График аннуитет.'!F11,'График аннуитет.'!D12+'График аннуитет.'!E12) -> 2955433.9 | G12: =B12-B11 -> 31 | H12: =DATE(YEAR(B12),12,31)-DATE(YEAR(B12),1,1)+1 -> 365
A13: 6 | B13: ='График дифференц'!B13 -> 46218 | C13: =C12-D12 -> 25572961 | D13: =IF(A13<umumiy_malumot!$B$81,'График аннуитет.'!F13-'График аннуитет.'!E13,'График аннуитет.'!C13) -> 1799395.9 | E13: =ROUND(C13*umumiy_malumot!$B$84/H13,2)*'График аннуитет.'!G13 -> 1156038 | F13: =IF(A13<umumiy_malumot!$B$81,'График аннуитет.'!F12,'График аннуитет.'!D13+'График аннуитет.'!E13) -> 2955433.9 | G13: =B13-B12 -> 30 | H13: =DATE(YEAR(B13),12,31)-DATE(YEAR(B13),1,1)+1 -> 365
A14: 7 | B14: ='График дифференц'!B14 -> 46251 | C14: =C13-D13 -> 23773565 | D14: =IF(A14<umumiy_malumot!$B$81,'График аннуитет.'!F14-'График аннуитет.'!E14,'График аннуитет.'!C14) -> 1773269 | E14: =ROUND(C14*umumiy_malumot!$B$84/H14,2)*'График аннуитет.'!G14 -> 1182164.9 | F14: =IF(A14<umumiy_malumot!$B$81,'График аннуитет.'!F13,'График аннуитет.'!D14+'График аннуитет.'!E14) -> 2955433.9 | G14: =B14-B13 -> 33 | H14: =DATE(YEAR(B14),12,31)-DATE(YEAR(B14),1,1)+1 -> 365
A15: 8 | B15: ='График дифференц'!B15 -> 46280 | C15: =C14-D14 -> 22000296 | D15: =IF(A15<umumiy_malumot!$B$81,'График аннуитет.'!F15-'График аннуитет.'!E15,'График аннуитет.'!C15) -> 1994051.1 | E15: =ROUND(C15*umumiy_malumot!$B$84/H15,2)*'График аннуитет.'!G15 -> 961382.77 | F15: =IF(A15<umumiy_malumot!$B$81,'График аннуитет.'!F14,'График аннуитет.'!D15+'График аннуитет.'!E15) -> 2955433.9 | G15: =B15-B14 -> 29 | H15: =DATE(YEAR(B15),12,31)-DATE(YEAR(B15),1,1)+1 -> 365
A16: 9 | B16: ='График дифференц'!B16 -> 46310 | C16: =C15-D15 -> 20006245 | D16: =IF(A16<umumiy_malumot!$B$81,'График аннуитет.'!F16-'График аннуитет.'!E16,'График аннуитет.'!C16) -> 2051041.9 | E16: =ROUND(C16*umumiy_malumot!$B$84/H16,2)*'График аннуитет.'!G16 -> 904392 | F16: =IF(A16<umumiy_malumot!$B$81,'График аннуитет.'!F15,'График аннуитет.'!D16+'График аннуитет.'!E16) -> 2955433.9 | G16: =B16-B15 -> 30 | H16: =DATE(YEAR(B16),12,31)-DATE(YEAR(B16),1,1)+1 -> 365
A17: 10 | B17: ='График дифференц'!B17 -> 46342 | C17: =C16-D16 -> 17955203 | D17: =IF(A17<umumiy_malumot!$B$81,'График аннуитет.'!F17-'График аннуитет.'!E17,'График аннуитет.'!C17) -> 2089648.6 | E17: =ROUND(C17*umumiy_malumot!$B$84/H17,2)*'График аннуитет.'!G17 -> 865785.28 | F17: =IF(A17<umumiy_malumot!$B$81,'График аннуитет.'!F16,'График аннуитет.'!D17+'График аннуитет.'!E17) -> 2955433.9 | G17: =B17-B16 -> 32 | H17: =DATE(YEAR(B17),12,31)-DATE(YEAR(B17),1,1)+1 -> 365
A18: 11 | B18: ='График дифференц'!B18 -> 46371 | C18: =C17-D17 -> 15865555 | D18: =IF(A18<umumiy_malumot!$B$81,'График аннуитет.'!F18-'График аннуитет.'!E18,'График аннуитет.'!C18) -> 2262130.9 | E18: =ROUND(C18*umumiy_malumot!$B$84/H18,2)*'График аннуитет.'!G18 -> 693303 | F18: =IF(A18<umumiy_malumot!$B$81,'График аннуитет.'!F17,'График аннуитет.'!D18+'График аннуитет.'!E18) -> 2955433.9 | G18: =B18-B17 -> 29 | H18: =DATE(YEAR(B18),12,31)-DATE(YEAR(B18),1,1)+1 -> 365
A19: 12 | B19: ='График дифференц'!B19 -> 46402 | C19: =C18-D18 -> 13603424 | D19: =IF(A19<umumiy_malumot!$B$81,'График аннуитет.'!F19-'График аннуитет.'!E19,'График аннуитет.'!C19) -> 2319986.3 | E19: =ROUND(C19*umumiy_malumot!$B$84/H19,2)*'График аннуитет.'!G19 -> 635447.61 | F19: =IF(A19<umumiy_malumot!$B$81,'График аннуитет.'!F18,'График аннуитет.'!D19+'График аннуитет.'!E19) -> 2955433.9 | G19: =B19-B18 -> 31 | H19: =DATE(YEAR(B19),12,31)-DATE(YEAR(B19),1,1)+1 -> 365
A20: 13 | B20: ='График дифференц'!B20 -> 46433 | C20: =C19-D19 -> 11283438 | D20: =IF(A20<umumiy_malumot!$B$81,'График аннуитет.'!F20-'График аннуитет.'!E20,'График аннуитет.'!C20) -> 2428358.3 | E20: =ROUND(C20*umumiy_malumot!$B$84/H20,2)*'График аннуитет.'!G20 -> 527075.64 | F20: =IF(A20<umumiy_malumot!$B$81,'График аннуитет.'!F19,'График аннуитет.'!D20+'График аннуитет.'!E20) -> 2955433.9 | G20: =B20-B19 -> 31 | H20: =DATE(YEAR(B20),12,31)-DATE(YEAR(B20),1,1)+1 -> 365
... A31: 24 | B31: ='График дифференц'!B31 -> 46769 | C31: =C30-D30 -> -22628423 | D31: =IF(A31<umumiy_malumot!$B$81,'График аннуитет.'!F31-'График аннуитет.'!E31,'График аннуитет.'!C31) -> 4077581.1 | E31: =ROUND(C31*umumiy_malumot!$B$84/H31,2)*'График аннуитет.'!G31 -> -1122147.2 | F31: =IF(A31<umumiy_malumot!$B$81,'График аннуитет.'!F30,'График аннуитет.'!D31+'График аннуитет.'!E31) -> 2955433.9 | G31: =B31-B30 -> 33 | H31: =DATE(YEAR(B31),12,31)-DATE(YEAR(B31),1,1)+1 -> 366
A32: =1+A31 -> 25 | B32: ='График дифференц'!B32 -> 46798 | C32: =C31-D31 -> -26706004 | D32: =IF(A32<umumiy_malumot!$B$81,'График аннуитет.'!F32-'График аннуитет.'!E32,'График аннуитет.'!C32) -> 4119261 | E32: =ROUND(C32*umumiy_malumot!$B$84/H32,2)*'График аннуитет.'!G32 -> -1163827.1 | F32: =IF(A32<umumiy_malumot!$B$81,'График аннуитет.'!F31,'График аннуитет.'!D32+'График аннуитет.'!E32) -> 2955433.9 | G32: =B32-B31 -> 29 | H32: =DATE(YEAR(B32),12,31)-DATE(YEAR(B32),1,1)+1 -> 366
A33: =1+A32 -> 26 | B33: ='График дифференц'!B33 -> 46827 | C33: =C32-D32 -> -30825265 | D33: =IF(A33<umumiy_malumot!$B$81,'График аннуитет.'!F33-'График аннуитет.'!E33,'График аннуитет.'!C33) -> 4298775.4 | E33: =ROUND(C33*umumiy_malumot!$B$84/H33,2)*'График аннуитет.'!G33 -> -1343341.5 | F33: =IF(A33<umumiy_malumot!$B$81,'График аннуитет.'!F32,'График аннуитет.'!D33+'График аннуитет.'!E33) -> 2955433.9 | G33: =B33-B32 -> 29 | H33: =DATE(YEAR(B33),12,31)-DATE(YEAR(B33),1,1)+1 -> 366
A34: =1+A33 -> 27 | B34: ='График дифференц'!B34 -> 46860 | C34: =C33-D33 -> -35124040 | D34: =IF(A34<umumiy_malumot!$B$81,'График аннуитет.'!F34-'График аннуитет.'!E34,'График аннуитет.'!C34) -> 4697240.9 | E34: =ROUND(C34*umumiy_malumot!$B$84/H34,2)*'График аннуитет.'!G34 -> -1741807 | F34: =IF(A34<umumiy_malumot!$B$81,'График аннуитет.'!F33,'График аннуитет.'!D34+'График аннуитет.'!E34) -> 2955433.9 | G34: =B34-B33 -> 33 | H34: =DATE(YEAR(B34),12,31)-DATE(YEAR(B34),1,1)+1 -> 366
A35: =1+A34 -> 28 | B35: ='График дифференц'!B35 -> 46888 | C35: =C34-D34 -> -39821281 | D35: =IF(A35<umumiy_malumot!$B$81,'График аннуитет.'!F35-'График аннуитет.'!E35,'График аннуитет.'!C35) -> 4630974.1 | E35: =ROUND(C35*umumiy_malumot!$B$84/H35,2)*'График аннуитет.'!G35 -> -1675540.2 | F35: =IF(A35<umumiy_malumot!$B$81,'График аннуитет.'!F34,'График аннуитет.'!D35+'График аннуитет.'!E35) -> 2955433.9 | G35: =B35-B34 -> 28 | H35: =DATE(YEAR(B35),12,31)-DATE(YEAR(B35),1,1)+1 -> 366
A36: =1+A35 -> 29 | B36: ='График дифференц'!B36 -> 46919 | C36: =C35-D35 -> -44452255 | D36: =IF(A36<umumiy_malumot!$B$81,'График аннуитет.'!F36-'График аннуитет.'!E36,'График аннуитет.'!C36) -> 5026228.9 | E36: =ROUND(C36*umumiy_malumot!$B$84/H36,2)*'График аннуитет.'!G36 -> -2070795 | F36: =IF(A36<umumiy_malumot!$B$81,'График аннуитет.'!F35,'График аннуитет.'!D36+'График аннуитет.'!E36) -> 2955433.9 | G36: =B36-B35 -> 31 | H36: =DATE(YEAR(B36),12,31)-DATE(YEAR(B36),1,1)+1 -> 366
A37: =1+A36 -> 30 | B37: ='График дифференц'!B37 -> 46951 | C37: =C36-D36 -> -49478484 | D37: =IF(A37<umumiy_malumot!$B$81,'График аннуитет.'!F37-'График аннуитет.'!E37,'График аннуитет.'!C37) -> 5334727 | E37: =ROUND(C37*umumiy_malumot!$B$84/H37,2)*'График аннуитет.'!G37 -> -2379293.1 | F37: =IF(A37<umumiy_malumot!$B$81,'График аннуитет.'!F36,'График аннуитет.'!D37+'График аннуитет.'!E37) -> 2955433.9 | G37: =B37-B36 -> 32 | H37: =DATE(YEAR(B37),12,31)-DATE(YEAR(B37),1,1)+1 -> 366
A38: =1+A37 -> 31 | B38: ='График дифференц'!B38 -> 46980 | C38: =C37-D37 -> -54813211 | D38: =IF(A38<umumiy_malumot!$B$81,'График аннуитет.'!F38-'График аннуитет.'!E38,'График аннуитет.'!C38) -> 5344151.7 | E38: =ROUND(C38*umumiy_malumot!$B$84/H38,2)*'График аннуитет.'!G38 -> -2388717.8 | F38: =IF(A38<umumiy_malumot!$B$81,'График аннуитет.'!F37,'График аннуитет.'!D38+'График аннуитет.'!E38) -> 2955433.9 | G38: =B38-B37 -> 29 | H38: =DATE(YEAR(B38),12,31)-DATE(YEAR(B38),1,1)+1 -> 366
A39: =1+A38 -> 32 | B39: ='График дифференц'!B39 -> 47011 | C39: =C38-D38 -> -60157363 | D39: =IF(A39<umumiy_malumot!$B$81,'График аннуитет.'!F39-'График аннуитет.'!E39,'График аннуитет.'!C39) -> 5757846.6 | E39: =ROUND(C39*umumiy_malumot!$B$84/H39,2)*'График аннуитет.'!G39 -> -2802412.7 | F39: =IF(A39<umumiy_malumot!$B$81,'График аннуитет.'!F38,'График аннуитет.'!D39+'График аннуитет.'!E39) -> 2955433.9 | G39: =B39-B38 -> 31 | H39: =DATE(YEAR(B39),12,31)-DATE(YEAR(B39),1,1)+1 -> 366
A40: =1+A39 -> 33 | B40: ='График дифференц'!B40 -> 47042 | C40: =C39-D39 -> -65915210 | D40: =IF(A40<umumiy_malumot!$B$81,'График аннуитет.'!F40-'График аннуитет.'!E40,'График аннуитет.'!C40) -> 6026074.1 | E40: =ROUND(C40*umumiy_malumot!$B$84/H40,2)*'График аннуитет.'!G40 -> -3070640.2 | F40: =IF(A40<umumiy_malumot!$B$81,'График аннуитет.'!F39,'График аннуитет.'!D40+'График аннуитет.'!E40) -> 2955433.9 | G40: =B40-B39 -> 31 | H40: =DATE(YEAR(B40),12,31)-DATE(YEAR(B40),1,1)+1 -> 366
A41: =1+A40 -> 34 | B41: ='График дифференц'!B41 -> 47072 | C41: =C40-D40 -> -71941284 | D41: =IF(A41<umumiy_malumot!$B$81,'График аннуитет.'!F41-'График аннуитет.'!E41,'График аннуитет.'!C41) -> 6198688.6 | E41: =ROUND(C41*umumiy_malumot!$B$84/H41,2)*'График аннуитет.'!G41 -> -3243254.7 | F41: =IF(A41<umumiy_malumot!$B$81,'График аннуитет.'!F40,'График аннуитет.'!D41+'График аннуитет.'!E41) -> 2955433.9 | G41: =B41-B40 -> 30 | H41: =DATE(YEAR(B41),12,31)-DATE(YEAR(B41),1,1)+1 -> 366
A42: =1+A41 -> 35 | B42: ='График дифференц'!B42 -> 47102 | C42: =C41-D41 -> -78139972 | D42: =IF(A42<umumiy_malumot!$B$81,'График аннуитет.'!F42-'График аннуитет.'!E42,'График аннуитет.'!C42) -> 6478137.7 | E42: =ROUND(C42*umumiy_malumot!$B$84/H42,2)*'График аннуитет.'!G42 -> -3522703.8 | F42: =IF(A42<umumiy_malumot!$B$81,'График аннуитет.'!F41,'График аннуитет.'!D42+'График аннуитет.'!E42) -> 2955433.9 | G42: =B42-B41 -> 30 | H42: =DATE(YEAR(B42),12,31)-DATE(YEAR(B42),1,1)+1 -> 366
A43: =1+A42 -> 36 | B43: ='График дифференц'!B43 -> 47124 | C43: =C42-D42 -> -84618110 | D43: =IF(A43<umumiy_malumot!$B$81,'График аннуитет.'!F43-'График аннуитет.'!E43,'График аннуитет.'!C43) -> -84618110 | E43: =ROUND(C43*umumiy_malumot!$B$84/H43,2)*'График аннуитет.'!G43 -> -2805148.3 | F43: =IF(A43<umumiy_malumot!$B$81,'График аннуитет.'!F42,'График аннуитет.'!D43+'График аннуитет.'!E43) -> -87423258 | G43: =B43-B42 -> 22 | H43: =DATE(YEAR(B43),12,31)-DATE(YEAR(B43),1,1)+1 -> 365
... A55: =1+A54 -> 48 | B55: ='График дифференц'!B55 -> FALSE | C55: =C54-D54 -> 0 | D55: =IF(A55<umumiy_malumot!$B$81,'График аннуитет.'!F55-'График аннуитет.'!E55,'График аннуитет.'!C55) -> 0 | E55: =ROUND(C55*umumiy_malumot!$B$84/H55,2)*'График аннуитет.'!G55 -> 0 | F55: =IF(A55<umumiy_malumot!$B$81,'График аннуитет.'!F54,'График аннуитет.'!D55+'График аннуитет.'!E55) -> 0 | G55: =B55-B54 -> 0 | H55: =DATE(YEAR(B55),12,31)-DATE(YEAR(B55),1,1)+1 -> 366
B56: ИТОГО | D56: =SUM(D8:D43) -> 33000000 | E56: =SUM(E8:E43) -> -16983072 | F56: =SUM(F8:F43) -> 16016928
A58: *В случае осуществления погашения платежей по кредиту в даты, отличные от указанных в графике погашения, сумма платежа меняется на сумму процентов, которые начисляются на сумму остатка долга по микрозайму в соответствии с п.п. 2.2. настоящего договора.
A60: =#REF! -> #REF! | D60: =#REF! -> #REF!
A62: =#REF! -> #REF! | D62: =#REF! -> #REF!
A63: =#REF! -> #REF! | D63: =#REF! -> #REF!
A64: =#REF! -> #REF! | D64: ="паспорт серии "&umumiy_malumot!B16&", "&umumiy_malumot!B20&"" -> паспорт серии AD 6760672, IIV 61013 tomonidan 08.04.2024 yilda berilgan
A65: =#REF! -> #REF!
A66: =#REF! -> #REF! | D66: =#REF! -> #REF!
...

Sheet shartnoma
A1: =""&umumiy_malumot!C64&" shartnoma "&umumiy_malumot!B66&"" -> Mikroqarz shartnoma №3-BR
A3: ="Toshkent shahri "&umumiy_malumot!B70&"" -> Toshkent shahri 6 yanvar 2026 y.
