Workbook
Name mos: '[1]Общие данные'!$C$23:$D$23
Name mos: '[2]Общие данные'!$C$23:$D$23
Name mulk: '[1]Общие данные'!$C$24:$W$24
Name mulk: '[2]Общие данные'!$C$24:$W$24

Sheet protokol
A1: =""&umumiy_malumot!B158&" mikromoliya tashkiloti Kredit qo‘mitasining yig‘ilishi" -> «PULLOL BUSINESS MIKROMOLIYA TASHKILOTI» MChJ mikromoliya tashkiloti Kredit qo‘mitasining yig‘ilishi
A2: =""&I7&" protokolidan ko'chirma" -> № 110 protokolidan ko'chirma
A3: Toshkent shahri | F3: =umumiy_malumot!B68 -> 16 fevral 2026 y.
B4: KUN TARTIBI:
A5: =" "&I8&"."&umumiy_malumot!B5&" ga "&umumiy_malumot!B65&" berish masalasini ko‘rib chiqish to‘g‘risida." -> 1.NORINBOYEVA SOXIBA IZZATILLAYEVNA ga mikrokredit berish masalasini ko‘rib chiqish to‘g‘risida.
A7: =" "&I9&" masala yuzasidan: "&umumiy_malumot!B158&" mikromoliya tashkiloti kredit bo‘yicha menejeri "&umumiy_malumot!B5&"ga "&FIXED(umumiy_malumot!B76)&" ("&umumiy_malumot!B77&") so‘m miqdorida, muddati "&umumiy_malumot!B82&" ("&umumiy_malumot!B83&") oyga va yillik "&umumiy_malumot!B86&" %("&umumiy_malumot!B87&") foiz miqdorida "&umumiy_malumot!B65&" berich bo‘yicha "&umumiy_malumot!B5&"ning kredit arizasi va "&umumiy_malumot!B158&"ning xulosasi bilan ishtirokchilarni tanishtirdi." -> Birinchi masala yuzasidan: «PULLOL BUSINESS MIKROMOLIYA TASHKILOTI» MChJ mikromoliya tashkiloti kredit bo‘yicha menejeri NORINBOYEVA SOXIBA IZZATILLAYEVNAga 175 000 000,00 (yuz yetmish besh million so'm) so‘m miqdorida, muddati 36 (O'ttiz olti ) oyga va yillik 55 %(Ellik besh ) foiz miqdorida mikrokredit berich bo‘yicha NORINBOYEVA SOXIBA IZZATILLAYEVNAning kredit arizasi va «PULLOL BUSINESS MIKROMOLIYA TASHKILOTI» MChJning xulosasi bilan ishtirokchilarni tanishtirdi. | H7: Protokol raqami | I7: =umumiy_malumot!B1 -> № 110
H8: Savol raqami | I8: 1 | J8: 1 | K8: 2 | L8: 3 | M8: 4 | N8: 5 | O8: 6 | P8: 7 | Q8: 8 | R8: 9 | S8: 10 | T8: 11 | U8: 12 | V8: 13 | W8: 14 | X8: 15 | Y8: 16 | Z8: 17 | AA8: 18 | AB8: 19 | AC8: 20 | AD8: 21 | AE8: 22 | AF8: 23 | AG8: 24 | AH8: 25
H9: Savol raqami qol bilan | I9: =IF(I8=J8,J9,IF(I8=K8,K9,IF(I8=L8,L9,IF(I8=M8,M9,IF(I8=N8,N9,IF(I8=O8,O9,IF(I8=P8,P9,IF(I8=Q8,Q9,IF(I8=R8,R9,IF(I8=S8,S9,IF(I8=T8,T9,IF(I8=U8,U9,IF(I8=V8,V9,IF(I8=W8,W9,IF(I8=X8,X9,IF(I8=Y8,Y9,IF(I8=Z8,Z9,IF(I8=AA8,AA9,IF(I8=AB8,AB9,IF(I8=AC8,AC9,IF(I8=AD8,AD9,IF(I8=AE8,AE9,IF(I8=AF8,AF9,IF(I8=AG8,AG9,IF(I8=AH8,AH9))))))))))))))))))))))))) -> Birinchi | J9: Birinchi | K9: Ikkinchi | L9: Uchinchi | M9: To'rtinchi | N9: Beshinchi | O9: O'ltinchi | P9: Yettinchi | Q9: Sakkizinchi | R9: Tuqqizinchi | S9: O'ninchi | T9: O'n birinchi | U9: O'n ikkinchi | V9: O'n uchinchi | W9: O'n to'rtinchi | X9: O'n beshinchi | Y9: O'n oltinchi | Z9: O'n yettinchi | AA9: O'n sakkizinchi | AB9: O'n tuqqizinchi | AC9: Yigirmanchi | AD9: Yigirma birinchi | AE9: Yigizma ikkinchi | AF9: Yigirma uchinchi | AG9: Yigirma to'rtinchi | AH9: Yigirma beshinchi
A11: =""&umumiy_malumot!C64&" ta’minoti:" -> Mikrokredit ta’minoti:
A13: =xulosa!A18:E18 -> 1. Egalik huquqi NORINBAYEVA SAPURA MAMADALIYEVNAga tegishli bo'lgan umumiy yer maydoni - 700,qurilish osti maydoni-340.11, umumiy foydali maydoni-114.59, yashash maydoni - 163.19 Yakka tartibdagi uy-joy, TOSHKENT VILOYATI CHINOZ TUMANI ALISHER NAVOIY MFY SOBIR RAHIMOV KO'CHASI 36 UY
A14: ="2. «"&umumiy_malumot!B154&"» АJ sug‘urta kompaniyasi tomonidan Mikroqarz to'lamaslik xavfini "&FIXED(umumiy_malumot!B155,2)&"("&umumiy_malumot!B156&") so ' m miqdoriga sug’urta qilish" -> 2. «АО СК "IMPEX INSURANCE"» АJ sug‘urta kompaniyasi tomonidan Mikroqarz to'lamaslik xavfini 35 000 000,00(o'ttiz besh million so'm) so ' m miqdoriga sug’urta qilish
D15: masala yuzasidan berilgan ma’lumotlarni muhokama qilib, Kredit qo‘mitasi a’zolariga taqdim etilgan zarur hujjatlarni o‘rganib, majlisda ishtirok etgan Kredit qo‘mitasi a’zolarining taklif va mulohazalarini inobatga olgan holda | E15: =""&umumiy_malumot!B158&" kredit qo‘mitasi" -> «PULLOL BUSINESS MIKROMOLIYA TASHKILOTI» MChJ kredit qo‘mitasi | F15: =CONCATENATE(D15,E15) -> masala yuzasidan berilgan ma’lumotlarni muhokama qilib, Kredit qo‘mitasi a’zolariga taqdim etilgan zarur hujjatlarni o‘rganib, majlisda ishtirok etgan Kredit qo‘mitasi a’zolarining taklif va mulohazalarini inobatga olgan holda «PULLOL BUSINESS MIKROMOLIYA TASHKILOTI» MChJ kredit qo‘mitasi
A16: =CONCATENATE(I9,F15) -> Birinchi masala yuzasidan berilgan ma’lumotlarni muhokama qilib, Kredit qo‘mitasi a’zolariga taqdim etilgan zarur hujjatlarni o‘rganib, majlisda ishtirok etgan Kredit qo‘mitasi a’zolarining taklif va mulohazalarini inobatga olgan holda «PULLOL BUSINESS MIKROMOLIYA TASHKILOTI» MChJ kredit qo‘mitasi
A17: QAROR QILADI:
A18: =" "&umumiy_malumot!B5&"ga quyidagi shartlarda "&umumiy_malumot!B65&" berish masalasi ma’qullansin:" -> NORINBOYEVA SOXIBA IZZATILLAYEVNAga quyidagi shartlarda mikrokredit berish masalasi ma’qullansin:
A19: ="1. "&umumiy_malumot!C64&" summasi: "&FIXED(umumiy_malumot!B76)&" ("&umumiy_malumot!B77&") so'm." -> 1. Mikrokredit summasi: 175 000 000,00 (yuz yetmish besh million so'm) so'm.
A20: ="2. "&umumiy_malumot!C64&" muddati: "&umumiy_malumot!B82&" ("&umumiy_malumot!B83&") oy " -> 2. Mikrokredit muddati: 36 (O'ttiz olti ) oy
A21: ="3. "&umumiy_malumot!C64&"dan foydalanganlik uchun foiz stavkasi:yillik "&umumiy_malumot!B86&"% ("&umumiy_malumot!B87&") foiz." -> 3. Mikrokreditdan foydalanganlik uchun foiz stavkasi:yillik 55% (Ellik besh ) foiz.
A22: ="4. "&umumiy_malumot!C64&" bo‘yicha asosiy qarz va foizlarni to‘lash:" -> 4. Mikrokredit bo‘yicha asosiy qarz va foizlarni to‘lash:
A23: =kredit_ariza!A19:D19 -> - mikrokredit shartnomasi bo'yicha har oy differensial to'lovlari amalga oshiriladi
A24: ="5. "&umumiy_malumot!C64&" bo‘yicha ta'minot:" -> 5. Mikrokredit bo‘yicha ta'minot:
A25: ="1. garov "&xulosa!A29:E29&"" -> 1. garov - NORINBAYEVA SAPURA MAMADALIYEVNA ga mulk huquqi asosida tegishli ko'chmas mulk shaklida Yakka tartibdagi uy-joy, manzili: TOSHKENT VILOYATI CHINOZ TUMANI ALISHER NAVOIY MFY SOBIR RAHIMOV KO'CHASI 36 UY, quyidagi tafsilotlarga muvofiq:
A26: =dalolatnoma!A29 -> Nomi | B26: =dalolatnoma!B29 -> Umumiy yer maydoni, (m2) | C26: =dalolatnoma!C29 -> Qurilish osti maydoni, (m2) | D26: =dalolatnoma!D29 -> Umumiy foydali maydoni, (m2) | E26: =dalolatnoma!E29 -> Yashash maydoni, (m2) | F26: =dalolatnoma!F29 -> Kelishilgan garov qiymati, so'm
A27: =dalolatnoma!A30 -> Yakka tartibdagi uy-joy | B27: =dalolatnoma!B30 -> 700 | C27: =dalolatnoma!C30 -> 340.11 | D27: =dalolatnoma!D30 -> 163.19 | E27: =dalolatnoma!E30 -> 114.59 | F27: =dalolatnoma!F30 -> 210 000 000,00 (ikki yuz o'n million so'm)
A28: =dalolatnoma!A22:F22 -> -* ko'chmas mulk egasi: NORINBAYEVA SAPURA MAMADALIYEVNA
A29: =dalolatnoma!A23:F23 -> -* reest raqami: №1727256/Y-25006342
A30: =dalolatnoma!A24:F24 -> -* kadastr raqami: 13.08.2025 y. №11:13:42:02:01:1840
A31: =dalolatnoma!A25:F25 -> -* manzili: TOSHKENT VILOYATI CHINOZ TUMANI ALISHER NAVOIY MFY SOBIR RAHIMOV KO'CHASI 36 UY
A33: ="6. «"&umumiy_malumot!B154&"» АJ sug‘urta kompaniyasi tomonidan "&umumiy_malumot!C64&" to'lamaslik xavfini "&FIXED(umumiy_malumot!B155,2)&"("&umumiy_malumot!B156&") so ' m miqdoriga sug’urta qilish" -> 6. «АО СК "IMPEX INSURANCE"» АJ sug‘urta kompaniyasi tomonidan Mikrokredit to'lamaslik xavfini 35 000 000,00(o'ttiz besh million so'm) so ' m miqdoriga sug’urta qilish
A34: ="7. Boshqa shartlar – "&IF(umumiy_malumot!B110=umumiy_malumot!B111,"avtotransport vositasi",IF(umumiy_malumot!B110=umumiy_malumot!C111,"ko'chmas mulk",0))&" shaklida garov ta'minlangandan keyin "&umumiy_malumot!B65&" berish." -> 7. Boshqa shartlar – ko'chmas mulk shaklida garov ta'minlangandan keyin mikrokredit berish.
A36: Qaror bir ovozdan qabul qilindi.
A41: =umumiy_malumot!B158&" direktori" -> «PULLOL BUSINESS MIKROMOLIYA TASHKILOTI» MChJ direktori | E41: A.Obidov
A45: =umumiy_malumot!A170 -> Kreditlash bo’limi boshlig’i | E45: =umumiy_malumot!B170 -> Akramov R.N.
A48: =umumiy_malumot!A171 -> Monitoring bo’limi boshlig’i | E48: =umumiy_malumot!B171 -> Omanlikov O.O.
A49: =umumiy_malumot!A172 -> Kredit bo'limi menejeri | E49: =umumiy_malumot!B172 -> Eshbekov S. O.

Sheet umumiy_malumot
A1: =CONCATENATE(B65," olish uchun ariza") -> mikrokredit olish uchun ariza | B1: № 110
A2: =CONCATENATE(B65," olish uchun ariza sanasi QO’L BILAN KIRITILADI") -> mikrokredit olish uchun ariza sanasi QO’L BILAN KIRITILADI | B2: 16.02.2026 | D2: =180+B2 -> 46249
A4: Qarz oluvchi bo’yicha ma’lumotlar
A5: Ariza beruvchining FISh (kim? – Ibragimov Rustam Sadikovich) | B5: NORINBOYEVA SOXIBA IZZATILLAYEVNA
A6: agar o’zgarishlar bo’lgan bo’lsa oldingi FISh (Sadikov Rustam Sadikovich yoki yo’q) | B6: yoq | C6: ha | D6: yo’q
A7: Ariza beruvchining FISh (kim? – Ibragimov R.S.) | B7: NORINBOYEVA S.I.
A8: FISh (ariza kimdan? – Ibragimov Rustam Sadikovichdan) | B8: =B5 -> NORINBOYEVA SOXIBA IZZATILLAYEVNA
A9: FISh (kimdan? – Ibragimov R.S.dan) | B9: =B7 -> NORINBOYEVA S.I.
A10: FISh (kimga? – Ibragimov Rustam Sadikovichga) | B10: =B8 -> NORINBOYEVA SOXIBA IZZATILLAYEVNA
A11: FISh (kimga? – Ibragimov R.S.ga) | B11: =B9 -> NORINBOYEVA S.I.
A12: FISh (kim bilan? – Ibragimov Rustam Sadikovich bilan) | B12: =B10 -> NORINBOYEVA SOXIBA IZZATILLAYEVNA
A13: FISh (kim bilan? – Ibragimov R.S. bilan) | B13: =B11 -> NORINBOYEVA S.I.
A14: Fuqaroligi (O’zbekiston Respublikasi) | B14: O’zbekiston Respublikasi
A15: Tug’ilgan sanasi (01.10.2011 yil) | B15: 19.10.1985 yil
A16: Pasport seriyasi (СА №1234567) | B16: AE 5547691
B17: IIV 27256 | D17: =TEXT(C17,"ДД.ММ.ГГГГ") -> 00.01.1900
B18: 46013 | C18: =TEXT(B18,"ДД.ММ.ГГГГ") -> 22.12.2025
B19: =DATE(YEAR(B18)+10,MONTH(B18),DAY(B18)-1) -> 49664 | C19: =TEXT(B19,"ДД.ММ.ГГГГ") -> 21.12.2035
A20: Kim va qachon berilgan (Toshkent shahri Chilonzor IIB tomonidan 2011 yil __.____) | B20: =""&B17&" tomonidan "&C18&" yilda berilgan" -> IIV 27256 tomonidan 22.12.2025 yilda berilgan | C20: =""&B17&" tomonidan "&C18&" yilda berilgan" -> IIV 27256 tomonidan 22.12.2025 yilda berilgan
A21: Pasportni amal qilish muddati (01.10.2011 yilgacha / yoki muddatsiz) | B21: =""&C19&" y." -> 21.12.2035 y. | C21: =""&C19&" yilgacha" -> 21.12.2035 yilgacha
A22: doimiy ro’yhatdan o’tgan joyi (Toshkent sh., Mirobod tumani, Nukus ko’chasi, 1 uy, 1 honadon) | B22: TOSHKENT VILOYATI CHINOZ TUMANI ALISHER NAVOIY MFY SOBIR RAHIMOV KO'CHASI 36 UY | C22: =TEXT(B19,"ДД.ММ.ГГГГ") -> 21.12.2035
A23: doimiy ro’yhatdan o’tgan joyi haqiqatdagi turar joyi bilan mos keladi/mos kelmaydi | B23: mos keladi | C23: mos keladi | D23: mos kelmaydi
A24: Ro’yhatdan o’tish joyida yashash asosi | B24: Mulk huquqi | C24: Mulk huquqi | D24: ijara | E24: служебная | F24: другое | G24: -
A25: Telefon raqami kod bilan ((99871) 277 77 77) | B25: 33 730 30 31 MIJOZ
A26: Mo’ljal | B26: 1 MAKTAB BALNITSA CHINOZ
B27: =IF(B23="mos keladi",B22,B28) -> TOSHKENT VILOYATI CHINOZ TUMANI ALISHER NAVOIY MFY SOBIR RAHIMOV KO'CHASI 36 UY
A28: Haqiqatdagi yashash joyi (Toshkent sh., Mirobod tumani, Nukus ko’chasi, 1 uy, 1 honadon) | B28: TOSHKENT VILOYATI CHINOZ TUMANI ALISHER NAVOIY MFY SOBIR RAHIMOV KO'CHASI 36 UY
A29: Haqiqatdagi yashash joyida turish asosi | B29: Mulk huquqi | C29: Mulk huquqi | D29: ijara | E29: xizmat | F29: boshqa | G29: -
A30: Mijozning jinsi | B30: ayol | C30: erkak | D30: ayol
A31: Tug’ilgan joyi (Toshkent) | B31: CHINOZ TUMANI
A32: Fuqaroligi (O’zbekiston Respublikasi) | B32: O’zbekiston Respublikasi
A33: Telefon raqami kod bilan ((99871) 277 77 77) | B33: =B25 -> 33 730 30 31 MIJOZ
B34: =IF(B23="mos keladi",B26,B35) -> 1 MAKTAB BALNITSA CHINOZ
A35: Mo’ljal
A36: Oilaviy ahvoli
A37: Oila a'zolari soni (jami):
A38: Ma’lumoti
A39: Mutaxassisligi
A40: Ish telefoni raqami kod bilan ((99890) 3270000) | B40: =B25 -> 33 730 30 31 MIJOZ
A41: Mobil telefon raqami kod bilan ((99890) 3270000) | B41: 99 407 50 08 UY EGASI
...

Sheet mijoz_anketasi
A1: MIJOZNING ANKETASI
A2: Anketa kredit menejeri tomonidan mijozning javoblarini kiritish orqali to'ldiriladi, kerak bo'lganda, Mijoz tomonidan tanlangan javob variantlarini belgilash orqali amalga oshiriladi
A3: 1. MIJOZ HAQIDA MA'LUMOTLAR:
A4: =xulosa!A4:E4 -> Mijozning to'liq ismi sharifi: NORINBOYEVA SOXIBA IZZATILLAYEVNA
A5: =xulosa!A5:E5 -> Tug'ilgan sanasi: 19.10.1985 yil
A6: =xulosa!A6:E6 -> Pasport seriyasi AE 5547691 IIV 27256 tomonidan 22.12.2025 yilda berilgan, amal qilish muddati - 21.12.2035 y.
A7: ="Fuqaroligi: "&umumiy_malumot!B32&"" -> Fuqaroligi: O’zbekiston Respublikasi
A8: =xulosa!A7:E7 -> Ro‘yxatdan o‘tgan manzili: TOSHKENT VILOYATI CHINOZ TUMANI ALISHER NAVOIY MFY SOBIR RAHIMOV KO'CHASI 36 UY, mo'ljal: 1 MAKTAB BALNITSA CHINOZ
A9: =IF(umumiy_malumot!B23="mos keladi"," ",mijoz_anketasi!A10:F10)
A10: ="Haqiqatdan yashash joy manzili: "&umumiy_malumot!B28&"" -> Haqiqatdan yashash joy manzili: TOSHKENT VILOYATI CHINOZ TUMANI ALISHER NAVOIY MFY SOBIR RAHIMOV KO'CHASI 36 UY
A11: =xulosa!A8:E8 -> Ish joyi: lavozimi BOLALAR O'YINCHOGINI ISHLAB CHIQARISH (UY SHAROITIDA)da O'Z O'ZINI BAND QILGAN FUQARO
A12: 2. Mijoz bilan ulanich uchun aloqa ma'lumotlari:
A13: ="Uy telefoni raqami: "&umumiy_malumot!B40&"" -> Uy telefoni raqami: 33 730 30 31 MIJOZ
A14: ="Uyali telefon raqami: "&umumiy_malumot!B41&"" -> Uyali telefon raqami: 99 407 50 08 UY EGASI
A15: ="Uyali telefon raqami: "&umumiy_malumot!B42&"" -> Uyali telefon raqami: 94 659 57 51 ADASI
A16: ="Uyali telefon raqami: "&umumiy_malumot!B42&"" -> Uyali telefon raqami: 94 659 57 51 ADASI
A17: ="Ish telefoni raqami: "&umumiy_malumot!B43&"" -> Ish telefoni raqami:
A18: 3. MIJOZNING ISH JOYI HAQIDA MA'LUMOT:
A19: ="Muassasa nomlanishi:"&umumiy_malumot!B58&"" -> Muassasa nomlanishi:O'Z O'ZINI BAND QILGAN FUQARO
A20: ="Ro‘yxatdan o‘tish manzili:"&umumiy_malumot!B46&"" -> Ro‘yxatdan o‘tish manzili:№0012660051
A21: ="Lavozimi: "&umumiy_malumot!B59&"" -> Lavozimi: BOLALAR O'YINCHOGINI ISHLAB CHIQARISH (UY SHAROITIDA)
A22: 4. MIJOZNING OYLIK DAROMADLARI VA XARAJATLARI HAQIDA MA'LUMOT
A23: Daromad manbalari | B23: Mijoz | C23: Turmush o'rtog'i | D23: Boshqa oila a'zolari | E23: Xarajatlar | F23: Мiqdori
A24: ish haqi (asosiy ish) | B24: =umumiy_malumot!B60 -> 20000000 | C24: 0 | D24: 0 | E24: uy-joy va kommunal xizmatlar uchun to'lov | F24: 700000
A25: ish haqi (o‘rindoshlik) | B25: 0 | C25: 0 | D25: 0 | E25: oilaviy xarajatlar | F25: 500000
A26: boshqa daromadlar | B26: =umumiy_malumot!B61 -> 10000000 | C26: 0 | D26: 0 | E26: boshqa xarajatlar | F26: 600000
A27: JAMI | B27: =B24+B25+B26 -> 30000000 | C27: =SUM(C24:C26) -> 0 | D27: =SUM(D24:D26) -> 0 | F27: =SUM(F24:F26) -> 1800000
A28: ="Men, "&umumiy_malumot!B5&", ushbu anketada ko‘rsatilgan barcha ma'lumotlar anketa to'ldirilgan sanada to'g'ri va aniq ekanligini tasdiqlayman." -> Men, NORINBOYEVA SOXIBA IZZATILLAYEVNA, ushbu anketada ko‘rsatilgan barcha ma'lumotlar anketa to'ldirilgan sanada to'g'ri va aniq ekanligini tasdiqlayman.
A29: ="Men, "&umumiy_malumot!B5&", quyidagilarni tan olaman va roziman::" -> Men, NORINBOYEVA SOXIBA IZZATILLAYEVNA, quyidagilarni tan olaman va roziman::
A30: ="1. Ushbu anketada ko‘rsatilgan har qanday ma’lumot "&umumiy_malumot!B158&", uning xodimlari va huquqiy vorislari tomonidan istalgan manbaa va ma’lumotlardan foydalangan holda istalgan vaqtda tekshirilishi va qayta tekshirilishi mumkin." -> 1. Ushbu anketada ko‘rsatilgan har qanday ma’lumot «PULLOL BUSINESS MIKROMOLIYA TASHKILOTI» MChJ, uning xodimlari va huquqiy vorislari tomonidan istalgan manbaa va ma’lumotlardan foydalangan holda istalgan vaqtda tekshirilishi va qayta tekshirilishi mumkin.
A31: ="2. Mazkur anketaning "&umumiy_malumot!B158&" tomonidan qabul qilinishi "&umumiy_malumot!B158&" tomonidan menga "&umumiy_malumot!B65&" berish majburiyatini yuklamaydi." -> 2. Mazkur anketaning «PULLOL BUSINESS MIKROMOLIYA TASHKILOTI» MChJ tomonidan qabul qilinishi «PULLOL BUSINESS MIKROMOLIYA TASHKILOTI» MChJ tomonidan menga mikrokredit berish majburiyatini yuklamaydi.
A32: Men, _________________________________________________________________ (to'liq ismi sharifi), ushbu anketadagi barcha ma'lumotlar anketa to'ldirilgan sanada to'g'ri ekanligini tasdiqlayman va ushbu anketaning 1- va 2-bandlarini tan olaman va ularga rozilik bildiraman. Mazkur anketaning 4-bo'limida ko'rsatilgan daromadlarim haqidagi ma'lumotlarni qabul qilishingizni va moliyaviy tahlilda foydalanishingizni so’rayman.
A34: Mijozning to'liq ismi sharifi | D34: Sana | E34: Imzo
D35: =umumiy_malumot!B2 -> 16.02.2026

Sheet anketa
A2: ANKETA
E3: =umumiy_malumot!B68 -> 16 fevral 2026 y.
A5: Mijozning to'liq ismi sharifi | C5: =umumiy_malumot!B8 -> NORINBOYEVA SOXIBA IZZATILLAYEVNA
A7: Siz ommaviy mansabdor shaxsmisiz? | D7: Ha
D8: Yo'q
A9: Yaqin qarindoshlaringiz orasida ommaviy mansabdor shaxslar bormi? | D9: Ha
D10: Yo'q
A11: Do'stlaringiz yoki yaqinlaringizdan birontasi ommaviy mansabdor shaxsmi? | D11: Ha
D12: Yo'q
A13: Yuqoridagi savollardan biriga «Ha» deb javob bergan bo'lsangiz, javobingizni qisqacha tushuntirib bering:
A18: Siz bank amaliyotlarini amalga oshirishda uchinchi shaxsning manfaatlarini ifodalaysizmi? | D18: Ha
D19: Yo'q
A20: Agar oldingi savolga «HA» deb javob bergan bo'lsangiz, bank operatsiyalarini bajarich uchun ishonchnomangiz bormi? | D20: Ha
D21: Yo'q
A23: Agar oldingi savolga «YO'Q» deb javob bergan bo'lsangiz, javobingizni qisqacha tushuntirib bering:
A28: Ommaviy mansabdor shaxslar — doimiy, vaqtincha yoki maxsus vakolatli organ tomonidan tayinlangan yoki saylangan, tashkiliy-maʼmuriy funktsiyalarni bajaruvchi hamda xorijiy davlatning qonun chiqaruvchi, ijro etuvchi, maʼmuriy yoki sud organida yoxud xalqaro tashkilotda yuridik ahamiyatga molik harakatlarni amalga oshirishga vakolatli shaxslar, shuningdek xorijiy davlatlar korxonalarining yuqori martabali rahbarlari, taniqli siyosatchilar va xorijiy davlatlar siyosiy partiyalarining taniqli a'zolari.
A30: Anketadagi barcha ma'lumotlar to'g'ri, agar o'zgarishlar bo'lsa, men bu haqida xabardor qilish majburiyatini o'z zimmamga olaman.
A33: =C5 -> NORINBOYEVA SOXIBA IZZATILLAYEVNA

Sheet kredit_ariza
C1: =""&umumiy_malumot!B158&"ning "&umumiy_malumot!A161&"" -> «PULLOL BUSINESS MIKROMOLIYA TASHKILOTI» MChJning Direktor
D2: =""&umumiy_malumot!B161&"ga" -> Obidov A.Sh.ga
A4: =""&umumiy_malumot!C64&" olish uchun Ariza" -> Mikrokredit olish uchun Ariza
A6: =""&umumiy_malumot!B28&".-da yashovchi O‘zbekiston Respublikasi fuqarosi "&umumiy_malumot!B8&"dan. " -> TOSHKENT VILOYATI CHINOZ TUMANI ALISHER NAVOIY MFY SOBIR RAHIMOV KO'CHASI 36 UY.-da yashovchi O‘zbekiston Respublikasi fuqarosi NORINBOYEVA SOXIBA IZZATILLAYEVNAdan.
A7: ="Tug'ilgan kuni: "&umumiy_malumot!B15&"" -> Tug'ilgan kuni: 19.10.1985 yil
A8: ="Pasport seriyasi: "&umumiy_malumot!B16&" "&umumiy_malumot!B20&"" -> Pasport seriyasi: AE 5547691 IIV 27256 tomonidan 22.12.2025 yilda berilgan
A9: ="Asosiy ish joyi : "&umumiy_malumot!B58&"" -> Asosiy ish joyi : O'Z O'ZINI BAND QILGAN FUQARO
A10: ="Lavozimi: "&umumiy_malumot!B59&"" -> Lavozimi: BOLALAR O'YINCHOGINI ISHLAB CHIQARISH (UY SHAROITIDA)
A11: ="O’rtacha oylik daromadi: "&FIXED(mijoz_anketasi!B27,2)&" so'm." -> O’rtacha oylik daromadi: 30 000 000,00 so'm.
A12: ="Menga quyidagi shartlarda "&umumiy_malumot!B65&" berishingizni so’rayman:" -> Menga quyidagi shartlarda mikrokredit berishingizni so’rayman:
A13: =""&umumiy_malumot!C64&" summasi: "&FIXED(umumiy_malumot!B76,2)&" ("&umumiy_malumot!B77&") so'm." -> Mikrokredit summasi: 175 000 000,00 (yuz yetmish besh million so'm) so'm.
A14: =""&umumiy_malumot!C64&" muddati: "&umumiy_malumot!B82&" ("&umumiy_malumot!B83&") oy." -> Mikrokredit muddati: 36 (O'ttiz olti ) oy.
A15: =""&umumiy_malumot!C64&"dan foydalanganlik uchun foiz stavkasi: yillik "&umumiy_malumot!B86&"% ("&umumiy_malumot!B87&") foiz" -> Mikrokreditdan foydalanganlik uchun foiz stavkasi: yillik 55% (Ellik besh ) foiz
A16: =""&umumiy_malumot!C64&" bo'yicha asosiy qarz va foizlarni to'lash:" -> Mikrokredit bo'yicha asosiy qarz va foizlarni to'lash:
A17: =" - "&umumiy_malumot!B65&" shartnomasi bo'yicha har oy differensial to'lovlari amalga oshiriladi" -> - mikrokredit shartnomasi bo'yicha har oy differensial to'lovlari amalga oshiriladi
A18: =" - "&umumiy_malumot!B65&" shartnomasi bo'yicha har oy annuitet to'lovlari amalga oshiriladi" -> - mikrokredit shartnomasi bo'yicha har oy annuitet to'lovlari amalga oshiriladi
A19: =IF(umumiy_malumot!B78=umumiy_malumot!C78,kredit_ariza!A17:D17,IF(umumiy_malumot!B78=umumiy_malumot!D78,kredit_ariza!A18:D18)) -> - mikrokredit shartnomasi bo'yicha har oy differensial to'lovlari amalga oshiriladi
A20: =IF(DAY(umumiy_malumot!E67)<15," "," Oxirgi yakuniy to'lov "&umumiy_malumot!B65&" shartnomasi tuzilgan kundan boshlab oxirgi oyning oxirgi kunida amalga oshiriladi") -> Oxirgi yakuniy to'lov mikrokredit shartnomasi tuzilgan kundan boshlab oxirgi oyning oxirgi kunida amalga oshiriladi
A21: =""&umumiy_malumot!C64&" ta’minoti::" -> Mikrokredit ta’minoti::
A22: ="1. "&IF(umumiy_malumot!B110="Avtotransport",A26,A23)&"" -> 1. Egalik huquqi NORINBAYEVA SAPURA MAMADALIYEVNAga tegishli bo'lgan umumiy yer maydoni - 700,qurilish osti maydoni-340.11, umumiy foydali maydoni-114.59, yashash maydoni - 163.19 Yakka tartibdagi uy-joy, TOSHKENT VILOYATI CHINOZ TUMANI ALISHER NAVOIY MFY SOBIR RAHIMOV KO'CHASI 36 UY
A23: =IF(umumiy_malumot!B99=umumiy_malumot!C99,A25,IF(umumiy_malumot!B99=umumiy_malumot!D99,A24,0)) -> Egalik huquqi NORINBAYEVA SAPURA MAMADALIYEVNAga tegishli bo'lgan umumiy yer maydoni - 700,qurilish osti maydoni-340.11, umumiy foydali maydoni-114.59, yashash maydoni - 163.19 Yakka tartibdagi uy-joy, TOSHKENT VILOYATI CHINOZ TUMANI ALISHER NAVOIY MFY SOBIR RAHIMOV KO'CHASI 36 UY
A24: =" - Navbatdagi garov (ipoteka) Egalik huquqi asosida "&umumiy_malumot!C124&"ga "&umumiy_malumot!C133&", umumiy maydoni - "&umumiy_malumot!C137&" va yashash maydoni - "&umumiy_malumot!C140&", manzili: "&umumiy_malumot!C130&"." -> - Navbatdagi garov (ipoteka) Egalik huquqi asosida NORINBAYEVA SAPURA MAMADALIYEVNAga Yakka tartibdagi uy-joy, umumiy maydoni - 163.19 va yashash maydoni - 700, manzili: TOSHKENT VILOYATI CHINOZ TUMANI ALISHER NAVOIY MFY SOBIR RAHIMOV KO'CHASI 36 UY.
A25: =" Egalik huquqi "&umumiy_malumot!C124&"ga tegishli bo'lgan umumiy yer maydoni - "&umumiy_malumot!C140&",qurilish osti maydoni-"&umumiy_malumot!C139&", umumiy foydali maydoni-"&umumiy_malumot!C138&", yashash maydoni - "&umumiy_malumot!C137&" "&umumiy_malumot!C133&", "&umumiy_malumot!C130&" " -> Egalik huquqi NORINBAYEVA SAPURA MAMADALIYEVNAga tegishli bo'lgan umumiy yer maydoni - 700,qurilish osti maydoni-340.11, umumiy foydali maydoni-114.59, yashash maydoni - 163.19 Yakka tartibdagi uy-joy, TOSHKENT VILOYATI CHINOZ TUMANI ALISHER NAVOIY MFY SOBIR RAHIMOV KO'CHASI 36 UY | G25: =" umumiy yer maydoni - "&C140&", qurilish osti maydoni- "&C139&", umumiy foydali maydoni - "&C137&" yashash maydoni - "&C138&"" -> umumiy yer maydoni - , qurilish osti maydoni- , umumiy foydali maydoni - yashash maydoni -
A26: =IF(umumiy_malumot!B99=umumiy_malumot!C99,kredit_ariza!A28:D28,IF(umumiy_malumot!B99=umumiy_malumot!D99,kredit_ariza!A27:D27,0)) -> Egalik huquqi NORINBAYEVA SAPURA MAMADALIYEVNAga tegishli bo'lgan garovga olingan avtomobil markasi CHEVROLET COBALT, rangi - OQ SUMMIT WHITE, ishlab chiqarilgan yili - 2024, davlat raqam belgisi 01Z067RC, kuzov turi - YENGIL SEDAN, kuzov raqami XWBJA69VERA108471, dvigatel raqami B15D213241352MTAX0118, shassi raqami - RAQAMSIZ
A27: =" Egalik huquqi "&umumiy_malumot!B124&"ga tegishli bo'lgan "&umumiy_malumot!B132&", "&umumiy_malumot!B140&", davlat raqam belgisi "&umumiy_malumot!B133&", "&umumiy_malumot!B134&", "&umumiy_malumot!B137&" avtotransport vositasi " -> Egalik huquqi NORINBAYEVA SAPURA MAMADALIYEVNAga tegishli bo'lgan CHEVROLET COBALT, rangi - OQ SUMMIT WHITE, ishlab chiqarilgan yili - 2024, davlat raqam belgisi 01Z067RC, kuzov turi - YENGIL SEDAN, kuzov raqami XWBJA69VERA108471, dvigatel raqami B15D213241352MTAX0118, shassi raqami - RAQAMSIZ avtotransport vositasi
A28: =" Egalik huquqi "&umumiy_malumot!B124&"ga tegishli bo'lgan garovga olingan avtomobil markasi "&umumiy_malumot!B132&", "&umumiy_malumot!B140&", davlat raqam belgisi "&umumiy_malumot!B133&", "&umumiy_malumot!B134&", "&umumiy_malumot!B137&"" -> Egalik huquqi NORINBAYEVA SAPURA MAMADALIYEVNAga tegishli bo'lgan garovga olingan avtomobil markasi CHEVROLET COBALT, rangi - OQ SUMMIT WHITE, ishlab chiqarilgan yili - 2024, davlat raqam belgisi 01Z067RC, kuzov turi - YENGIL SEDAN, kuzov raqami XWBJA69VERA108471, dvigatel raqami B15D213241352MTAX0118, shassi raqami - RAQAMSIZ
A29: ="2. «"&umumiy_malumot!B154&"» АJ sug‘urta kompaniyasi tomonidan "&umumiy_malumot!C64&" to'lamaslik xavfini "&FIXED(umumiy_malumot!B155,2)&"("&umumiy_malumot!B156&") so ' m miqdoriga sug’urta qilish" -> 2. «АО СК "IMPEX INSURANCE"» АJ sug‘urta kompaniyasi tomonidan Mikrokredit to'lamaslik xavfini 35 000 000,00(o'ttiz besh million so'm) so ' m miqdoriga sug’urta qilish
A31: ="Mazkur ariza bilan "&umumiy_malumot!B158&"ga men va soʻralayotgan "&umumiy_malumot!B65&" boʻyicha barcha zarur maʼlumotlarni quyida ko’rsatilgan tashkilotlarga taqdim etish va olishga roziligimni bildirib, ushbu amaliyotlarni o’tkazish uchun huquq beraman:" -> Mazkur ariza bilan «PULLOL BUSINESS MIKROMOLIYA TASHKILOTI» MChJga men va soʻralayotgan mikrokredit boʻyicha barcha zarur maʼlumotlarni quyida ko’rsatilgan tashkilotlarga taqdim etish va olishga roziligimni bildirib, ushbu amaliyotlarni o’tkazish uchun huquq beraman:
A32: □ O‘zbekiston Respublikasi Markaziy banki huzuridagi kredit axborotining davlat reestri;
A33: □ Kredit-axborot tahliliy markazi «O‘zbekiston Respublikasi kredit byurosi» MChJ;
A34: □ Garov reestri taqdim etilgan garov mulki haqida.
A35: ="Ariza berilgan sana: "&TEXT(umumiy_malumot!B2,"ДД.ММ.ГГГГ")&"y." -> Ariza berilgan sana: 16.02.2026y.
A37: Ariza berilgan kuniga barcha ma'lumotlar ishonchligini tasdiqlab, ushbu arizani imzolayman
A40: =umumiy_malumot!B5 -> NORINBOYEVA SOXIBA IZZATILLAYEVNA | D40: ________________
D41: (imzo)
A43: =umumiy_malumot!A161 -> Direktor | D43: =umumiy_malumot!B161 -> Obidov A.Sh.

Sheet majburiyatnoma
A3: MAJBURIYATNOMA
A4: =" Men, fuqaro "&umumiy_malumot!B5&" "&umumiy_malumot!B160&" bilan "&umumiy_malumot!B69&" sanasidagi "&umumiy_malumot!B66&"-sonli shartnomaning garov ta'minoti sifatida taqdim etilayotgan mulk "&umumiy_malumot!B132&" rusumli avtotransport vositasini qonunga xilof ravishda o‘zlashtirmaslikka, yashirmaslikka, nobud qilmaslikka yoki unga shikast yetkazmaslik majburiyatini olaman." -> Men, fuqaro NORINBOYEVA SOXIBA IZZATILLAYEVNA «PULLOL BUSINESS MIKROMOLIYA TASHKILOTI» MChJ bilan 16 fevral 2026 y. sanasidagi № 110-sonli shartnomaning garov ta'minoti sifatida taqdim etilayotgan mulk CHEVROLET COBALT rusumli avtotransport vositasini qonunga xilof ravishda o‘zlashtirmaslikka, yashirmaslikka, nobud qilmaslikka yoki unga shikast yetkazmaslik majburiyatini olaman.
A5: Ushbu majburiyatlarimni bajarmagan taqdirimda O'zbekiston Respublikasi jinoyat kodeksining 233-moddasi talablari asosida javobgarlik tog'risida ogohlantrildim.
A7: =umumiy_malumot!B5 -> NORINBOYEVA SOXIBA IZZATILLAYEVNA | B7: Imzo_____________
A9: =umumiy_malumot!B5 -> NORINBOYEVA SOXIBA IZZATILLAYEVNA | B9: Imzo_____________
A11: ="sana: "&TEXT(umumiy_malumot!B2,"ДД.ММ.ГГГГ")&" y." -> sana: 16.02.2026 y.

Sheet xulosa
A1: =""&umumiy_malumot!B158&" mikromoliya tashkilotining Xulosasi" -> «PULLOL BUSINESS MIKROMOLIYA TASHKILOTI» MChJ mikromoliya tashkilotining Xulosasi
A3: MIJOZ HAQIDA MA'LUMOTLAR
A4: ="Mijozning to'liq ismi sharifi: "&umumiy_malumot!B5&"" -> Mijozning to'liq ismi sharifi: NORINBOYEVA SOXIBA IZZATILLAYEVNA
A5: ="Tug'ilgan sanasi: "&umumiy_malumot!B15&"" -> Tug'ilgan sanasi: 19.10.1985 yil
A6: ="Pasport seriyasi "&umumiy_malumot!B16&" "&umumiy_malumot!B20&", amal qilish muddati - "&umumiy_malumot!B21&"" -> Pasport seriyasi AE 5547691 IIV 27256 tomonidan 22.12.2025 yilda berilgan, amal qilish muddati - 21.12.2035 y.
A7: ="Ro‘yxatdan o‘tgan manzili: "&umumiy_malumot!B22&", mo'ljal: "&umumiy_malumot!B26&"" -> Ro‘yxatdan o‘tgan manzili: TOSHKENT VILOYATI CHINOZ TUMANI ALISHER NAVOIY MFY SOBIR RAHIMOV KO'CHASI 36 UY, mo'ljal: 1 MAKTAB BALNITSA CHINOZ
A8: ="Ish joyi: "&umumiy_malumot!B52&" lavozimi "&umumiy_malumot!B49&"da "&umumiy_malumot!B44&"" -> Ish joyi: lavozimi BOLALAR O'YINCHOGINI ISHLAB CHIQARISH (UY SHAROITIDA)da O'Z O'ZINI BAND QILGAN FUQARO
A10: ="Mijoz tomonidan so’ralgan "&umumiy_malumot!B65&" shartlari:" -> Mijoz tomonidan so’ralgan mikrokredit shartlari:
A11: =kredit_ariza!A13:D13 -> Mikrokredit summasi: 175 000 000,00 (yuz yetmish besh million so'm) so'm.
A12: =kredit_ariza!A14:D14 -> Mikrokredit muddati: 36 (O'ttiz olti ) oy.
A13: =kredit_ariza!A15:D15 -> Mikrokreditdan foydalanganlik uchun foiz stavkasi: yillik 55% (Ellik besh ) foiz
A14: =kredit_ariza!A16:D16 -> Mikrokredit bo'yicha asosiy qarz va foizlarni to'lash:
A15: =kredit_ariza!A19:D19 -> - mikrokredit shartnomasi bo'yicha har oy differensial to'lovlari amalga oshiriladi
A16: =kredit_ariza!A20:D20 -> Oxirgi yakuniy to'lov mikrokredit shartnomasi tuzilgan kundan boshlab oxirgi oyning oxirgi kunida amalga oshiriladi
A17: =kredit_ariza!A21:D21 -> Mikrokredit ta’minoti::
A18: =kredit_ariza!A22:D22 -> 1. Egalik huquqi NORINBAYEVA SAPURA MAMADALIYEVNAga tegishli bo'lgan umumiy yer maydoni - 700,qurilish osti maydoni-340.11, umumiy foydali maydoni-114.59, yashash maydoni - 163.19 Yakka tartibdagi uy-joy, TOSHKENT VILOYATI CHINOZ TUMANI ALISHER NAVOIY MFY SOBIR RAHIMOV KO'CHASI 36 UY
A19: Mijozning moliyaviy holati
A20: ="Anketaga muvofiq "&umumiy_malumot!B9&"ning o‘rtacha oylik daromadi "&FIXED(mijoz_anketasi!B27)&" so‘mni tashkil etdi." -> Anketaga muvofiq NORINBOYEVA S.I.ning o‘rtacha oylik daromadi 30 000 000,00 so‘mni tashkil etdi.
A21: ="Mijozning o'rtacha oylik xarajatlari "&FIXED(mijoz_anketasi!F27)&" so'mni tashkil etdi" -> Mijozning o'rtacha oylik xarajatlari 1 800 000,00 so'mni tashkil etdi
A22: =IF(umumiy_malumot!B78=umumiy_malumot!C78,xulosa!A23:E23,xulosa!A24:E24) -> Mikrokredit shartnomasi bo'yicha birinchi oy uchun to'lov 12 808 694,88 so'mni tashkil etadi.
A23: =""&umumiy_malumot!C64&" shartnomasi bo'yicha birinchi oy uchun to'lov "&FIXED(umumiy_malumot!B91)&" so'mni tashkil etadi." -> Mikrokredit shartnomasi bo'yicha birinchi oy uchun to'lov 12 808 694,88 so'mni tashkil etadi.
A24: =""&umumiy_malumot!C64&" bo‘yicha oylik "&umumiy_malumot!B78&" to‘lovi miqdori "&FIXED(umumiy_malumot!B91)&" so‘mni tashkil etadi." -> Mikrokredit bo‘yicha oylik differensial to‘lovi miqdori 12 808 694,88 so‘mni tashkil etadi.
A25: Mijoz quyidagi majburiyatlarga ega: "TOShKENT Sh., "ANOR BANK" АKTSIYADORLIK JАMIYATI 106 139 813.00 so'm, Ayni paytda muddati o'tgan qarzdorligi mavjud emas. O‘rtacha oylik to‘lov 5 353 870.46 so‘mni tashkil qiladi
A26: =""&umumiy_malumot!C64&" bo’yicha ta’minot:" -> Mikrokredit bo’yicha ta’minot:
A27: =" - "&umumiy_malumot!B124&" ga mulk huquqi asosida tegishli avtotransport vositasi "&umumiy_malumot!B132&" , quyidagi tafsilotlarga muvofiq:" -> - NORINBAYEVA SAPURA MAMADALIYEVNA ga mulk huquqi asosida tegishli avtotransport vositasi CHEVROLET COBALT , quyidagi tafsilotlarga muvofiq:
A28: =" - "&umumiy_malumot!C124&" ga mulk huquqi asosida tegishli ko'chmas mulk shaklida "&umumiy_malumot!C133&", manzili: "&umumiy_malumot!C130&", quyidagi tafsilotlarga muvofiq:" -> - NORINBAYEVA SAPURA MAMADALIYEVNA ga mulk huquqi asosida tegishli ko'chmas mulk shaklida Yakka tartibdagi uy-joy, manzili: TOSHKENT VILOYATI CHINOZ TUMANI ALISHER NAVOIY MFY SOBIR RAHIMOV KO'CHASI 36 UY, quyidagi tafsilotlarga muvofiq:
A29: =IF(umumiy_malumot!B110="Avtotransport",xulosa!A27:E27,xulosa!A28:E28) -> - NORINBAYEVA SAPURA MAMADALIYEVNA ga mulk huquqi asosida tegishli ko'chmas mulk shaklida Yakka tartibdagi uy-joy, manzili: TOSHKENT VILOYATI CHINOZ TUMANI ALISHER NAVOIY MFY SOBIR RAHIMOV KO'CHASI 36 UY, quyidagi tafsilotlarga muvofiq:
A30: =dalolatnoma!A29 -> Nomi | B30: =dalolatnoma!C29 -> Qurilish osti maydoni, (m2) | C30: =dalolatnoma!D29 -> Umumiy foydali maydoni, (m2) | D30: =dalolatnoma!E29 -> Yashash maydoni, (m2) | E30: =dalolatnoma!F29 -> Kelishilgan garov qiymati, so'm
A31: =dalolatnoma!A30 -> Yakka tartibdagi uy-joy | B31: =dalolatnoma!C30 -> 340.11 | C31: =dalolatnoma!D30 -> 163.19 | D31: =dalolatnoma!E30 -> 114.59 | E31: =dalolatnoma!F30 -> 210 000 000,00 (ikki yuz o'n million so'm)
A32: =dalolatnoma!A22 -> -* ko'chmas mulk egasi: NORINBAYEVA SAPURA MAMADALIYEVNA
A33: =dalolatnoma!A23 -> -* reest raqami: №1727256/Y-25006342
A34: =dalolatnoma!A24 -> -* kadastr raqami: 13.08.2025 y. №11:13:42:02:01:1840
A35: =dalolatnoma!A25 -> -* manzili: TOSHKENT VILOYATI CHINOZ TUMANI ALISHER NAVOIY MFY SOBIR RAHIMOV KO'CHASI 36 UY
A36: =""&umumiy_malumot!B158&" mikromoliya tashkilotining Xulosasi" -> «PULLOL BUSINESS MIKROMOLIYA TASHKILOTI» MChJ mikromoliya tashkilotining Xulosasi
A37: =""&umumiy_malumot!B158&" kredit qo‘mitasining xulosasiga quyidagi shartlarda "&umumiy_malumot!B10&"ga "&umumiy_malumot!B65&" berish masalasi kiritiladi:" -> «PULLOL BUSINESS MIKROMOLIYA TASHKILOTI» MChJ kredit qo‘mitasining xulosasiga quyidagi shartlarda NORINBOYEVA SOXIBA IZZATILLAYEVNAga mikrokredit berish masalasi kiritiladi:
A38: =A11 -> Mikrokredit summasi: 175 000 000,00 (yuz yetmish besh million so'm) so'm.
A39: =A12 -> Mikrokredit muddati: 36 (O'ttiz olti ) oy.
A40: =A13 -> Mikrokreditdan foydalanganlik uchun foiz stavkasi: yillik 55% (Ellik besh ) foiz
A41: =A14 -> Mikrokredit bo'yicha asosiy qarz va foizlarni to'lash:
A42: =A15 -> - mikrokredit shartnomasi bo'yicha har oy differensial to'lovlari amalga oshiriladi
...

Sheet shartnoma
A1: =""&umumiy_malumot!C64&" shartnoma "&umumiy_malumot!B66&"" -> Mikrokredit shartnoma № 110
A3: ="Toshkent shahri "&umumiy_malumot!B70&"" -> Toshkent shahri 16 fevral 2026 y.
A5: =""&umumiy_malumot!B158&", bundan buyon «Mikromoliya tashkiloti» deb nomlanuvchi, Ustav va 14.08.2023 yildagi 27-13/968-sonli Litsenziya asosida faoliyat yurituvchi "&umumiy_malumot!A161&" "&umumiy_malumot!B161&" bir tomondan va o‘z manfaati yo‘lida hamda o‘z nomidan harakat qiluvchi O‘zbekiston Respublikasi fuqarosi "&umumiy_malumot!B5&" (pasport raqami "&umumiy_malumot!B16&", "&umumiy_malumot!C20&" ), bundan buyon «Qarz oluvchi» deb nomlanuvchi, boshqa tomondan, birgalikda “Tomonlar” yoki alohida “Tomon” deb nomlanuvchilar, Qarz oluvchi tomonidan "&TEXT(umumiy_malumot!B2,"ДД.ММ.ГГГГ")&" yil,"&umumiy_malumot!B65&" olish uchun ariza berilganligini hisobga olib, ushbu "&umumiy_malumot!C64&" shartnomasini (bundan keyin – «Shartnoma») quyidagilar haqida tuzdilar:" -> «PULLOL BUSINESS MIKROMOLIYA TASHKILOTI» MChJ, bundan buyon «Mikromoliya tashkiloti» deb nomlanuvchi, Ustav va 14.08.2023 yildagi 27-13/968-sonli Litsenziya asosida faoliyat yurituvchi Direktor Obidov A.Sh. bir tomondan va o‘z manfaati yo‘lida hamda o‘z nomidan harakat qiluvchi O‘zbekiston Respublikasi fuqarosi NORINBOYEVA SOXIBA IZZATILLAYEVNA (pasport raqami AE 5547691, IIV 27256 tomonidan 22.12.2025 yilda berilgan ), bundan buyon «Qarz oluvchi» deb nomlanuvchi, boshqa tomondan, birgalikda “Tomonlar” yoki alohida “Tomon” deb nomlanuvchilar, Qarz oluvchi tomonidan 16.02.2026 yil,mikrokredit olish uchun ariza berilganligini hisobga olib, ushbu Mikrokredit shartnomasini (bundan keyin – «Shartnoma») quyidagilar haqida tuzdilar:
A7: 1. SHARTNOMA PREDMETI
A8: ="1.1. Mikromoliya tashkiloti Qarz oluvchiga umumiy miqdori "&FIXED(umumiy_malumot!B76,2)&" ("&umumiy_malumot!C77&") bo‘lgan "&umumiy_malumot!B65&"ni "&umumiy_malumot!B71&" dan "&umumiy_malumot!B73&" gacha bo'lgan muddatga naqd pul va/yoki o'tkazmasi shaklida ajratadi." -> 1.1. Mikromoliya tashkiloti Qarz oluvchiga umumiy miqdori 175 000 000,00 (Yuz yetmish besh million so'm) bo‘lgan mikrokreditni 16 fevral 2026 y. dan 16 fevral 2029 y. gacha bo'lgan muddatga naqd pul va/yoki o'tkazmasi shaklida ajratadi.
A9: ="1.2. Qarz oluvchi to‘lovlilik, muddatlilik va ta’minlanganlik tamoyillariga amal qilgan holda "&umumiy_malumot!B65&"dan foydalanish majburiyatini o‘z zimmasiga oladi." -> 1.2. Qarz oluvchi to‘lovlilik, muddatlilik va ta’minlanganlik tamoyillariga amal qilgan holda mikrokreditdan foydalanish majburiyatini o‘z zimmasiga oladi.
A11: ="2. "&umumiy_malumot!D64&" BERISH VA QAYTARISH TARTIBI" -> 2. MIKROKREDIT BERISH VA QAYTARISH TARTIBI
A12: ="2.1. Ushbu Shartnomaning 1.1.-bandida ko‘rsatilgan summa miqdoridagi "&umumiy_malumot!B65&" Mikromoliya tashkiloti kassasidan naqd pul shaklida va/yoki plastik kartaga o‘tkazish yuli bilan beriladi." -> 2.1. Ushbu Shartnomaning 1.1.-bandida ko‘rsatilgan summa miqdoridagi mikrokredit Mikromoliya tashkiloti kassasidan naqd pul shaklida va/yoki plastik kartaga o‘tkazish yuli bilan beriladi.
A13: ="2.2. "&umumiy_malumot!C64&" berish ushbu Shartnoma tuzilgan va Qarz oluvchi tomonidan ushbu shartnomaning 3-bo‘limiga muvofiq garov ta'minoti ta'minlangandan so‘ng 10 kalendar kundan kechiktirmay amalga oshiriladi." -> 2.2. Mikrokredit berish ushbu Shartnoma tuzilgan va Qarz oluvchi tomonidan ushbu shartnomaning 3-bo‘limiga muvofiq garov ta'minoti ta'minlangandan so‘ng 10 kalendar kundan kechiktirmay amalga oshiriladi.
A14: ="2.3. "&umumiy_malumot!C64&" Qarz oluvchi tomonidan ushbu Shartnomaning ajralmas qismi hisoblanadigan 1-ilovasida ko‘rsatilgan to‘lov jadvalida (bundan keyin - To‘lov jadvali) belgilangan miqdor, tartib va muddatlarda qaytariladi." -> 2.3. Mikrokredit Qarz oluvchi tomonidan ushbu Shartnomaning ajralmas qismi hisoblanadigan 1-ilovasida ko‘rsatilgan to‘lov jadvalida (bundan keyin - To‘lov jadvali) belgilangan miqdor, tartib va muddatlarda qaytariladi.
A15: ="2.4. Mikromoliya tashkiloti, "&umumiy_malumot!B65&" berilgan vaqtdan boshlab, "&umumiy_malumot!B65&" miqdorining qoldiq summasiga "&umumiy_malumot!B86&"% ("&umumiy_malumot!C87&") foiz yillik va yiliga 365/366 kunlik hisobidan foizlar hisoblaydi. To'lov jadvaliga muvofiq asosiy qarz bo'yicha navbatdagi to'lov buzilgan hollarda, "&"foiz stavkasi oshiriladi va Mikromoliya tashkiloti "&umumiy_malumot!B65&"ning muddati o'tgan asosiy qarz summasiga yillik "&umumiy_malumot!B89&"% ("&umumiy_malumot!B90&") foiz miqdorida foizlar hisoblaydi." -> 2.4. Mikromoliya tashkiloti, mikrokredit berilgan vaqtdan boshlab, mikrokredit miqdorining qoldiq summasiga 55% (Ellik besh ) foiz yillik va yiliga 365/366 kunlik hisobidan foizlar hisoblaydi. To'lov jadvaliga muvofiq asosiy qarz bo'yicha navbatdagi to'lov buzilgan hollarda, foiz stavkasi oshiriladi va Mikromoliya tashkiloti mikrokreditning muddati o'tgan asosiy qarz summasiga yillik 155% (bir yuz ellik besh) foiz miqdorida foizlar hisoblaydi.
A16: 2.4.1 Qarz oluvchining xisob raqamlaridan shartnomaning 4.1.2 bandida ko‘rsatilgan tartibda yechib olingan pul mablag‘lari yechib olinganidan so‘ng mijoz tomonidan kredit qarzdorligini so‘ndirish uchun bank kassalari orqali to‘langan pul mablag‘lari yoki mijoz tomonidan kredit qarzdorligini so‘ndirish uchun bank kassalari orqali to‘langandan so‘ng qarz oluvchining xisob raqamlaridan shartnomaning 4.1.2 bandida ko‘rsatilgan tartibda yechib olingan pul mablag‘larining bir oylik kredit to‘lovini so‘ndirishga yo‘naltirilgan miqdoridan ortiqcha qismi qarz oluvchining to‘lov amalga oshirilgan kundan boshlab 3 bank ish kuni ichida yo‘llagan arizasiga asosan qarz oluvchiga qaytarilishi mumkun. 2.5. Foizlar To‘lov jadvaliga muvofiq asosiy qarzni qaytarish uchun belgilangan sanada to‘lanadi. 2.5.1 Qarz oluvchi tomonidan shartnomaning 2.4 bandida ko‘rsatilgan muddatda ortiqcha to‘langan pul mablag‘larini qaytarish to‘g‘risida ariza berilmagan taqdirda to‘langan ortiqcha pul mablag‘lari mijozning asosiy qarzdorligini so‘ndirishga yo‘naltiriladi.
A17: =CONCATENATE(C17,H17,I17) -> 2.6 Qarz oluvchi tomonidan to‘lov jadvalida ko‘rsatilgan muddatdan oldin xamda to‘lov jadvalida ko‘rsatilgan oylik kredit qarzdorligini so‘ndirish miqdoridan ko‘p miqdorda to‘lovni amalga oshirib, to‘langan pul mablag‘larini asosiy kredit qarzdorligini so‘ndirishga yo‘naltirilishini so‘ralganda qarz oluvchining kredit qarzdorligini so‘ndirish uchun to‘lagan pul mablag‘laridan kredit qarzdorligi to‘langan oy uchun to‘lov jadvali bo‘yicha so‘ndirilishi lozim bo‘lgan foiz qarzdorligi summasi, to‘lov jadvalida foiz qarzdorligi so‘ndirilishi ko‘rsatilgan muddatga qadar tashkilotning xisob raqamida saqlanib to‘lov jadvalida ko‘rsatilgan sanada oylik foiz qarzdorligini so‘ndirishga yo‘naltiriladi. 2.6.1. Qarz oluvchi tomonidan olingan mikrokreditni va undan foydalanganlik uchun foizlarni qaytarish bo‘yicha muddati o‘tgan qarzdorlik hosil bo‘lganda Qarz oluvchi tomonidan ko‘rsatilgan qarzdorlikni to‘lash hisobiga to‘lanadigan summalar quyidagi tartibda hisobga olinadi: | C17: 2.6 Qarz oluvchi tomonidan to‘lov jadvalida ko‘rsatilgan muddatdan oldin xamda to‘lov jadvalida ko‘rsatilgan oylik kredit qarzdorligini so‘ndirish miqdoridan ko‘p miqdorda to‘lovni amalga oshirib, to‘langan pul mablag‘larini asosiy kredit qarzdorligini so‘ndirishga yo‘naltirilishini so‘ralganda qarz oluvchining kredit qarzdorligini so‘ndirish uchun to‘lagan pul mablag‘laridan kredit qarzdorligi to‘langan oy uchun to‘lov jadvali bo‘yicha so‘ndirilishi lozim bo‘lgan foiz qarzdorligi summasi, to‘lov jadvalida foiz qarzdorligi so‘ndirilishi ko‘rsatilgan muddatga qadar tashkilotning xisob raqamida saqlanib to‘lov jadvalida ko‘rsatilgan sanada oylik foiz qarzdorligini so‘ndirishga yo‘naltiriladi. 2.6.1. Qarz oluvchi tomonidan olingan | H17: =umumiy_malumot!B65 -> mikrokredit | I17: ni va undan foydalanganlik uchun foizlarni qaytarish bo‘yicha muddati o‘tgan qarzdorlik hosil bo‘lganda Qarz oluvchi tomonidan ko‘rsatilgan qarzdorlikni to‘lash hisobiga to‘lanadigan summalar quyidagi tartibda hisobga olinadi:
A18: - jarima sanksiyalarni to‘lash; - to‘lov muddati o‘tgan foizlarni to‘lash; - to‘lov muddati o‘tgan asosiy qarzni to‘lash; - muddatli qarz bo‘yicha hisoblangan foizlarni to‘lash; - muddatli asosiy qarzni to‘lash; - Mikromoliya tashkilotning boshqa zararlarini qoplash.
A19: ="2.7. Qarz oluvchi Mikromoliya tashkilotining "&umumiy_malumot!B65&" bo‘yicha asosiy summasi, hisoblangan foizlarni, penya va boshqa moliyaviy talablarini ham naqd pul shaklida, ham naqdsiz shaklda qaytarib beradi." -> 2.7. Qarz oluvchi Mikromoliya tashkilotining mikrokredit bo‘yicha asosiy summasi, hisoblangan foizlarni, penya va boshqa moliyaviy talablarini ham naqd pul shaklida, ham naqdsiz shaklda qaytarib beradi.
A20: ="2.8. Qarz oluvchi "&umumiy_malumot!B65&" miqdorini muddatidan oldin qaytarish, shuningdek, bu haqida Mikromoliya tashkilotini albatta ogohlantirgan holda ulardan aniq foydalangan muddat uchun hisoblangan foizlarni to‘lash huquqiga ega." -> 2.8. Qarz oluvchi mikrokredit miqdorini muddatidan oldin qaytarish, shuningdek, bu haqida Mikromoliya tashkilotini albatta ogohlantirgan holda ulardan aniq foydalangan muddat uchun hisoblangan foizlarni to‘lash huquqiga ega.
A21: =CONCATENATE(C21,H21,I21) -> 2.9. Qarz oluvchi jismoniy shaxslarning kreditlar (mikrokreditlar) bo‘yicha qarz yukini hisoblash tartibi, qarz yukining ruxsat etilgan miqdori, shuningdek qarz yuki o‘sishini cheklash to‘g‘risidagi Nizomga muvofiq (O’zbekiston Respublikasi Adliya vazirligi tomonidan 19.12.2019 y. 3205-son bilan ro‘yxatga olingan Markaziy bank Boshqaruvining 28.09.2019 y. 24/5-son qarori bilan tasdiqlangan), qarz yuki ko‘rsatkichi har bir qarz oluvchiga qarz beruvchi tomonidan mikrokredit ajratishda uning summasi va qarz oluvchining amaldagi kredit (mikrokredit) shartnomalari bo‘yicha asosiy qarz qoldig‘i yig‘indisi bazaviy hisoblash miqdorining 50 baravaridan oshganda hisoblanadi. | C21: ="2.9. Qarz oluvchi jismoniy shaxslarning kreditlar ("&umumiy_malumot!B65&"lar) bo‘yicha qarz yukini hisoblash tartibi, qarz yukining ruxsat etilgan miqdori, shuningdek qarz yuki o‘sishini cheklash to‘g‘risidagi Nizomga muvofiq (O’zbekiston Respublikasi Adliya vazirligi tomonidan 19.12.2019 y. 3205-son bilan ro‘yxatga " -> 2.9. Qarz oluvchi jismoniy shaxslarning kreditlar (mikrokreditlar) bo‘yicha qarz yukini hisoblash tartibi, qarz yukining ruxsat etilgan miqdori, shuningdek qarz yuki o‘sishini cheklash to‘g‘risidagi Nizomga muvofiq (O’zbekiston Respublikasi Adliya vazirligi tomonidan 19.12.2019 y. 3205-son bilan ro‘yxatga | H21: ="olingan Markaziy bank Boshqaruvining 28.09.2019 y. 24/5-son qarori bilan tasdiqlangan), qarz yuki ko‘rsatkichi har bir qarz oluvchiga qarz beruvchi tomonidan "&umumiy_malumot!B65&" ajratishda uning summasi va " -> olingan Markaziy bank Boshqaruvining 28.09.2019 y. 24/5-son qarori bilan tasdiqlangan), qarz yuki ko‘rsatkichi har bir qarz oluvchiga qarz beruvchi tomonidan mikrokredit ajratishda uning summasi va | I21: ="qarz oluvchining amaldagi kredit ("&umumiy_malumot!B65&") shartnomalari bo‘yicha asosiy qarz qoldig‘i yig‘indisi bazaviy hisoblash miqdorining 50 baravaridan oshganda hisoblanadi." -> qarz oluvchining amaldagi kredit (mikrokredit) shartnomalari bo‘yicha asosiy qarz qoldig‘i yig‘indisi bazaviy hisoblash miqdorining 50 baravaridan oshganda hisoblanadi.
A22: ="3. "&umumiy_malumot!D64&" TA'MINOTI BO‘YICHA " -> 3. MIKROKREDIT TA'MINOTI BO‘YICHA
A23: ="3.1. Ushbu Shartnoma bo‘yicha taqdim etilgan "&umumiy_malumot!C64&" quyidagi "&umumiy_malumot!C64&" summasiga nisbatan 140% dan kam bo'lmagan, yani birgalikdagi jami qiymati "&FIXED(umumiy_malumot!C75,2)&" ("&umumiy_malumot!D75&") so'm miqdorida bo'lgan garov va "&umumiy_malumot!C64&" to'lamaslik xavfini sug'urta polisi bilan ta'minlanadi:" -> 3.1. Ushbu Shartnoma bo‘yicha taqdim etilgan Mikrokredit quyidagi Mikrokredit summasiga nisbatan 140% dan kam bo'lmagan, yani birgalikdagi jami qiymati 245 000 000,00 (ikki yuz qirq besh million so'm) so'm miqdorida bo'lgan garov va Mikrokredit to'lamaslik xavfini sug'urta polisi bilan ta'minlanadi:
A24: =IF(umumiy_malumot!B110=umumiy_malumot!C110,shartnoma!A28,IF(umumiy_malumot!B110=umumiy_malumot!D110,shartnoma!A25,0)) -> 3.1.1. Mikromoliya tashkiloti, Qarz oluvchi va NORINBAYEVA SAPURA MAMADALIYEVNA tomonidan 2026 yil 16 fevralda imzolangan 1-sonli Garov predmeti qiymatini tasdiqlash dalolatnomasiga muvofiq TOSHKENT VILOYATI CHINOZ TUMANI ALISHER NAVOIY MFY SOBIR RAHIMOV KO'CHASI 36 UY manzilida joylashgan, umumiy yer maydoni - 700, qurilish osti maydoni- 340.11, umumiy foydali maydoni - 163.19 yashash maydoni - 114.59 bo'lgan, Ko'p qavatli uydagi - xonali xonadon ko'rinishidagi ko'chmas mulk (bundan keyin “Garov predmeti”), egalik huquqiga ko'ra NORINBAYEVA SAPURA MAMADALIYEVNAga tegishli va kelishilgan garov qiymati 2026 yil 16 fevralda imzolangan 1-sonli Garov predmeti qiymatini tasdiqlash dalolatnomasiga muvofiq 210 000 000,00 (ikki yuz o'n million so'm) so'mni tashkil qiladi. Garovning aniq shartlari tegishli tarzda notarial tasdiqlangan garov shartnomasi bilan belgilangan.
A25: =IF(umumiy_malumot!B99=umumiy_malumot!C99,shartnoma!A27,IF(umumiy_malumot!B99=umumiy_malumot!D99,shartnoma!A26,0)) -> 3.1.1. Mikromoliya tashkiloti, Qarz oluvchi va NORINBAYEVA SAPURA MAMADALIYEVNA tomonidan 2026 yil 16 fevralda imzolangan 1-sonli Garov predmeti qiymatini tasdiqlash dalolatnomasiga muvofiq TOSHKENT VILOYATI CHINOZ TUMANI ALISHER NAVOIY MFY SOBIR RAHIMOV KO'CHASI 36 UY manzilida joylashgan, umumiy yer maydoni - 700, qurilish osti maydoni- 340.11, umumiy foydali maydoni - 163.19 yashash maydoni - 114.59 bo'lgan, Ko'p qavatli uydagi - xonali xonadon ko'rinishidagi ko'chmas mulk (bundan keyin “Garov predmeti”), egalik huquqiga ko'ra NORINBAYEVA SAPURA MAMADALIYEVNAga tegishli va kelishilgan garov qiymati 2026 yil 16 fevralda imzolangan 1-sonli Garov predmeti qiymatini tasdiqlash dalolatnomasiga muvofiq 210 000 000,00 (ikki yuz o'n million so'm) so'mni tashkil qiladi. Garovning aniq shartlari tegishli tarzda notarial tasdiqlangan garov shartnomasi bilan belgilangan.
A26: ="3.1.1. "&umumiy_malumot!N133&" tomonidan "&umumiy_malumot!B150&" yil "&umumiy_malumot!B152&" "&umumiy_malumot!B151&"da imzolangan 1-sonli navbatdagi garov predmeti qiymatini tasdiqlash dalolatnomasiga muvofiq "&umumiy_malumot!C130&" manzilida joylashgan, "&umumiy_malumot!E133&" bo'lgan, "&umumiy_malumot!E132&" ko'rinishidagi ko'chmas mulk (bundan keyin “navbatdagi garov predmeti”), egalik huquqiga ko'ra "&umumiy_malumot!C124&"ga tegishli va kelishilgan garov qiymati "&umumiy_malumot!B150&" yil "&umumiy_malumot!B152&" "&umumiy_malumot!B151&"da imzolangan 1-sonli Garov predmeti qiymatini tasdiqlash dalolatnomasiga muvofiq "&FIXED(umumiy_malumot!B143,2)&" ("&umumiy_malumot!B145&") so'mni tashkil qiladi. Garovning aniq shartlari tegishli tarzda notarial tasdiqlangan garov shartnomasi bilan belgilangan." -> 3.1.1. Mikromoliya tashkiloti, Qarz oluvchi va NORINBAYEVA SAPURA MAMADALIYEVNA tomonidan 2026 yil 16 fevralda imzolangan 1-sonli navbatdagi garov predmeti qiymatini tasdiqlash dalolatnomasiga muvofiq TOSHKENT VILOYATI CHINOZ TUMANI ALISHER NAVOIY MFY SOBIR RAHIMOV KO'CHASI 36 UY manzilida joylashgan, umumiy yer maydoni - 700, qurilish osti maydoni- 340.11, umumiy foydali maydoni - 163.19 yashash maydoni - 114.59 bo'lgan, Ko'p qavatli uydagi - xonali xonadon ko'rinishidagi ko'chmas mulk (bundan keyin “navbatdagi garov predmeti”), egalik huquqiga ko'ra NORINBAYEVA SAPURA MAMADALIYEVNAga tegishli va kelishilgan garov qiymati 2026 yil 16 fevralda imzolangan 1-sonli Garov predmeti qiymatini tasdiqlash dalolatnomasiga muvofiq 210 000 000,00 (ikki yuz o'n million so'm) so'mni tashkil qiladi. Garovning aniq shartlari tegishli tarzda notarial tasdiqlangan garov shartnomasi bilan belgilangan.
A27: ="3.1.1. "&umumiy_malumot!N133&" tomonidan "&umumiy_malumot!B150&" yil "&umumiy_malumot!B152&" "&umumiy_malumot!B151&"da imzolangan 1-sonli Garov predmeti qiymatini tasdiqlash dalolatnomasiga muvofiq "&umumiy_malumot!C130&" manzilida joylashgan, "&umumiy_malumot!E133&" bo'lgan, "&umumiy_malumot!E132&" ko'rinishidagi ko'chmas mulk (bundan keyin “Garov predmeti”), egalik huquqiga ko'ra "&umumiy_malumot!C124&"ga tegishli va kelishilgan garov qiymati "&umumiy_malumot!B150&" yil "&umumiy_malumot!B152&" "&umumiy_malumot!B151&"da imzolangan 1-sonli Garov predmeti qiymatini tasdiqlash dalolatnomasiga muvofiq "&FIXED(umumiy_malumot!B143,2)&" ("&umumiy_malumot!B145&") so'mni tashkil qiladi. Garovning aniq shartlari tegishli tarzda notarial tasdiqlangan garov shartnomasi bilan belgilangan." -> 3.1.1. Mikromoliya tashkiloti, Qarz oluvchi va NORINBAYEVA SAPURA MAMADALIYEVNA tomonidan 2026 yil 16 fevralda imzolangan 1-sonli Garov predmeti qiymatini tasdiqlash dalolatnomasiga muvofiq TOSHKENT VILOYATI CHINOZ TUMANI ALISHER NAVOIY MFY SOBIR RAHIMOV KO'CHASI 36 UY manzilida joylashgan, umumiy yer maydoni - 700, qurilish osti maydoni- 340.11, umumiy foydali maydoni - 163.19 yashash maydoni - 114.59 bo'lgan, Ko'p qavatli uydagi - xonali xonadon ko'rinishidagi ko'chmas mulk (bundan keyin “Garov predmeti”), egalik huquqiga ko'ra NORINBAYEVA SAPURA MAMADALIYEVNAga tegishli va kelishilgan garov qiymati 2026 yil 16 fevralda imzolangan 1-sonli Garov predmeti qiymatini tasdiqlash dalolatnomasiga muvofiq 210 000 000,00 (ikki yuz o'n million so'm) so'mni tashkil qiladi. Garovning aniq shartlari tegishli tarzda notarial tasdiqlangan garov shartnomasi bilan belgilangan.
A28: =IF(umumiy_malumot!B99=umumiy_malumot!C99,A29,IF(umumiy_malumot!B99=umumiy_malumot!D99,A30,0)) -> 3.1.1. Mikromoliya tashkiloti, Qarz oluvchi va NORINBAYEVA SAPURA MAMADALIYEVNA tomonidan 2026 yil 16 fevralda imzolangan 1-sonli garov predmeti qiymatini tasdiqlash dalolatnomasiga muvofiq OQ SUMMIT WHITE rangli, ishlab chiqarilgan yili – 2024 yil, dvigatel raqami B15D213241352MTAX0118, shassi - RAQAMSIZ, kuzov turi - YENGIL SEDAN, kuzov raqami №XWBJA69VERA108471, davlat raqam belgisi 01Z067RC bo'lgan CHEVROLET COBALT rusumli avtomashinasi (bundan keyin “Garov predmeti”), egalik huquqiga ega NORINBAYEVA SAPURA MAMADALIYEVNAga tegishli va kelishilgan garov qiymati 2026 yil 16 fevralda imzolangan 1-sonli Garov predmeti qiymatini tasdiqlash dalolatnomasiga muvifiq 210 000 000,00 (ikki yuz o'n million so'm) so'mni tashkil qiladi. Garov garovining aniq shartlari tegishli notarial rasmiylashtirilgan garov shartnomasi bilan belgilanadi.
A29: ="3.1.1. "&umumiy_malumot!N133&" tomonidan "&umumiy_malumot!B150&" yil "&umumiy_malumot!B152&" "&umumiy_malumot!B151&"da imzolangan 1-sonli garov predmeti qiymatini tasdiqlash dalolatnomasiga muvofiq "&umumiy_malumot!B141&" rangli, ishlab chiqarilgan yili – "&umumiy_malumot!B142&" yil, dvigatel raqami "&umumiy_malumot!B138&", shassi - "&umumiy_malumot!B139&", kuzov turi - "&umumiy_malumot!B135&", kuzov raqami №"&umumiy_malumot!B136&", davlat raqam belgisi "&umumiy_malumot!B133&" bo'lgan "&umumiy_malumot!B132&" rusumli avtomashinasi (bundan keyin “Garov predmeti”), egalik huquqiga ega "&umumiy_malumot!B124&"ga tegishli va kelishilgan garov qiymati "&umumiy_malumot!B150&" yil "&umumiy_malumot!B152&" "&umumiy_malumot!B151&"da imzolangan 1-sonli Garov predmeti qiymatini tasdiqlash dalolatnomasiga muvifiq "&FIXED(umumiy_malumot!B143,2)&" ("&umumiy_malumot!B145&") so'mni tashkil qiladi. Garov garovining aniq shartlari tegishli notarial rasmiylashtirilgan garov shartnomasi bilan belgilanadi." -> 3.1.1. Mikromoliya tashkiloti, Qarz oluvchi va NORINBAYEVA SAPURA MAMADALIYEVNA tomonidan 2026 yil 16 fevralda imzolangan 1-sonli garov predmeti qiymatini tasdiqlash dalolatnomasiga muvofiq OQ SUMMIT WHITE rangli, ishlab chiqarilgan yili – 2024 yil, dvigatel raqami B15D213241352MTAX0118, shassi - RAQAMSIZ, kuzov turi - YENGIL SEDAN, kuzov raqami №XWBJA69VERA108471, davlat raqam belgisi 01Z067RC bo'lgan CHEVROLET COBALT rusumli avtomashinasi (bundan keyin “Garov predmeti”), egalik huquqiga ega NORINBAYEVA SAPURA MAMADALIYEVNAga tegishli va kelishilgan garov qiymati 2026 yil 16 fevralda imzolangan 1-sonli Garov predmeti qiymatini tasdiqlash dalolatnomasiga muvifiq 210 000 000,00 (ikki yuz o'n million so'm) so'mni tashkil qiladi. Garov garovining aniq shartlari tegishli notarial rasmiylashtirilgan garov shartnomasi bilan belgilanadi.
A30: ="3.1.1. "&umumiy_malumot!N133&" tomonidan "&umumiy_malumot!B150&" yil "&umumiy_malumot!B152&" "&umumiy_malumot!B151&"da imzolangan 1-sonli navbatdagi garov predmeti qiymatini tasdiqlash dalolatnomasiga muvofiq "&umumiy_malumot!B141&" rangli, ishlab chiqarilgan yili – "&umumiy_malumot!B142&" yil, dvigatel raqami "&umumiy_malumot!B138&", shassi - "&umumiy_malumot!B139&", kuzov turi - "&umumiy_malumot!B135&", kuzov raqami №"&umumiy_malumot!B136&", davlat raqam belgisi "&umumiy_malumot!B133&" bo'lgan "&umumiy_malumot!B132&" rusumli avtomashinasi (bundan keyin “navbatdagi garov predmeti”), egalik huquqiga ega "&umumiy_malumot!B124&"ga tegishli va kelishilgan garov qiymati "&umumiy_malumot!B150&" yil "&umumiy_malumot!B152&" "&umumiy_malumot!B151&"da imzolangan 1-sonli Garov predmeti qiymatini tasdiqlash dalolatnomasiga muvifiq "&FIXED(umumiy_malumot!B143,2)&" ("&umumiy_malumot!B145&") so'mni tashkil qiladi. Garov garovining aniq shartlari tegishli notarial rasmiylashtirilgan garov shartnomasi bilan belgilanadi." -> 3.1.1. Mikromoliya tashkiloti, Qarz oluvchi va NORINBAYEVA SAPURA MAMADALIYEVNA tomonidan 2026 yil 16 fevralda imzolangan 1-sonli navbatdagi garov predmeti qiymatini tasdiqlash dalolatnomasiga muvofiq OQ SUMMIT WHITE rangli, ishlab chiqarilgan yili – 2024 yil, dvigatel raqami B15D213241352MTAX0118, shassi - RAQAMSIZ, kuzov turi - YENGIL SEDAN, kuzov raqami №XWBJA69VERA108471, davlat raqam belgisi 01Z067RC bo'lgan CHEVROLET COBALT rusumli avtomashinasi (bundan keyin “navbatdagi garov predmeti”), egalik huquqiga ega NORINBAYEVA SAPURA MAMADALIYEVNAga tegishli va kelishilgan garov qiymati 2026 yil 16 fevralda imzolangan 1-sonli Garov predmeti qiymatini tasdiqlash dalolatnomasiga muvifiq 210 000 000,00 (ikki yuz o'n million so'm) so'mni tashkil qiladi. Garov garovining aniq shartlari tegishli notarial rasmiylashtirilgan garov shartnomasi bilan belgilanadi.
A31: =CONCATENATE(C31,D31) -> 3.1.2. «АО СК "IMPEX INSURANCE"» АJ sug‘urta kompaniyasi (keyingi o'rinlarda-Sug‘urtalovchi) tomonidan Mikrokredit to'lamaslik xavfini Mikrokredit summasiga nisbatan 140% dan hisoblab 35 000 000,00(o'ttiz besh million so'm) so ' m miqdoriga sug’urta qilish. Ushbu shartnoma bo‘yicha Mikrokredit berilgunga qadar Mikromoliya tashkiloti Sug‘urtalovchi 35 000 000,00(o'ttiz besh million so'm) so ' m miqdoridagi Mikrokreditni to‘lamaslik xavfini sug‘urta qilish shartnomasini tuzadi va Sug‘urtalovchi nomiga sug‘urta mukofotini to‘laydi, Qarz oluvchi esa Mikromoliya tashkiloti tomonidan sug‘urta mukofotini to‘langan kuni Mikromoliya tashkiloti tomonidan to‘langan sug‘urta mukofotini Mikromoliya tashkilotiga to‘laydi." | C31: ="3.1.2. «"&umumiy_malumot!B154&"» АJ sug‘urta kompaniyasi (keyingi o'rinlarda-Sug‘urtalovchi) tomonidan "&umumiy_malumot!C64&" to'lamaslik xavfini "&umumiy_malumot!C64&" summasiga nisbatan 140% dan hisoblab "&FIXED(umumiy_malumot!B155,2)&"("&umumiy_malumot!B156&") so ' m miqdoriga sug’urta qilish." -> 3.1.2. «АО СК "IMPEX INSURANCE"» АJ sug‘urta kompaniyasi (keyingi o'rinlarda-Sug‘urtalovchi) tomonidan Mikrokredit to'lamaslik xavfini Mikrokredit summasiga nisbatan 140% dan hisoblab 35 000 000,00(o'ttiz besh million so'm) so ' m miqdoriga sug’urta qilish. | D31: =CONCATENATE(E31,F31) -> Ushbu shartnoma bo‘yicha Mikrokredit berilgunga qadar Mikromoliya tashkiloti Sug‘urtalovchi 35 000 000,00(o'ttiz besh million so'm) so ' m miqdoridagi Mikrokreditni to‘lamaslik xavfini sug‘urta qilish shartnomasini tuzadi va Sug‘urtalovchi nomiga sug‘urta mukofotini to‘laydi, Qarz oluvchi esa Mikromoliya tashkiloti tomonidan sug‘urta mukofotini to‘langan kuni Mikromoliya tashkiloti tomonidan to‘langan sug‘urta mukofotini Mikromoliya tashkilotiga to‘laydi." | E31: =" Ushbu shartnoma bo‘yicha "&umumiy_malumot!C64&" berilgunga qadar Mikromoliya tashkiloti Sug‘urtalovchi "&FIXED(umumiy_malumot!B155,2)&"("&umumiy_malumot!B156&") so ' m miqdoridagi "&umumiy_malumot!C64&"" -> Ushbu shartnoma bo‘yicha Mikrokredit berilgunga qadar Mikromoliya tashkiloti Sug‘urtalovchi 35 000 000,00(o'ttiz besh million so'm) so ' m miqdoridagi Mikrokredit | F31: ni to‘lamaslik xavfini sug‘urta qilish shartnomasini tuzadi va Sug‘urtalovchi nomiga sug‘urta mukofotini to‘laydi, Qarz oluvchi esa Mikromoliya tashkiloti tomonidan sug‘urta mukofotini to‘langan kuni Mikromoliya tashkiloti tomonidan to‘langan sug‘urta mukofotini Mikromoliya tashkilotiga to‘laydi."
A32: =CONCATENATE(A33,B33) -> 3.2. Qonun hujjatlariga muvofiq rasmiylashtirilgan, “Garov predmeti” hisoblangan notarial tasdiqlangan garov shartnomasi, shu jumladan “Garov predmeti”ga taʼqiq quyilganligi tasdiqlovchi xujjat Qarz oluvchi tomonidan ushbu shartnoma tuzilgandan so‘ng 10 bank kuni mobaynida Mikromoliya tashkilotiga taqdim etilishi lozim. Garov shartnomasi belgilangan muddatda taqdim etilmagan hollarda, Mikromoliya tashkiloti Qarz oluvchining manziliga yozma bildirishnoma yuborish orqali mikrokredit berishni rad etish va / yoki ushbu shartnomani bir tomonlama bekor qilish huquqiga egadir. Bunda ushbu shartnoma Qarz oluvchi tomonidan talabnoma olingan vaqtda yoki talabnoma pochta xizmati orqali yuborilgandan keyin uchinchi kuni bekor qilingan hisoblanadi.
A33: 3.2. Qonun hujjatlariga muvofiq rasmiylashtirilgan, “Garov predmeti” hisoblangan notarial tasdiqlangan garov shartnomasi, shu jumladan “Garov predmeti”ga taʼqiq quyilganligi tasdiqlovchi xujjat Qarz oluvchi tomonidan ushbu shartnoma tuzilgandan so‘ng 10 bank kuni mobaynida | B33: =CONCATENATE(A34,B34) -> Mikromoliya tashkilotiga taqdim etilishi lozim. Garov shartnomasi belgilangan muddatda taqdim etilmagan hollarda, Mikromoliya tashkiloti Qarz oluvchining manziliga yozma bildirishnoma yuborish orqali mikrokredit berishni rad etish va / yoki ushbu shartnomani bir tomonlama bekor qilish huquqiga egadir. Bunda ushbu shartnoma Qarz oluvchi tomonidan talabnoma olingan vaqtda yoki talabnoma pochta xizmati orqali yuborilgandan keyin uchinchi kuni bekor qilingan hisoblanadi.
