Workbook
Name mos: '[1]Общие данные'!$C$23:$D$23
Name mulk: '[1]Общие данные'!$C$24:$W$24

Sheet protokol
A1: =""&umumiy_malumot!B147&" mikromoliya tashkiloti Kredit qo‘mitasining yig‘ilishi" -> «PULLOL BUSINESS MIKROMOLIYA TASHKILOTI» MChJ mikromoliya tashkiloti Kredit qo‘mitasining yig‘ilishi
A2: =""&H7&" protokolidan ko'chirma" -> № 56 protokolidan ko'chirma
A3: Toshkent shahri | E3: =umumiy_malumot!B68 -> 2 fevral 2026 y.
B4: KUN TARTIBI:
A5: =" "&H8&"."&umumiy_malumot!B5&" ga "&umumiy_malumot!B65&" berish masalasini ko‘rib chiqish to‘g‘risida." -> 1.QODIROVA NAFISA YO‘LDOSHEVNA ga Mikroqarz berish masalasini ko‘rib chiqish to‘g‘risida.
A7: =" "&H9&" masala yuzasidan: «PULLOL BUSINESS MIKROMOLIYA TASHKILOTI» MChJ kredit bo‘yicha menejeri "&umumiy_malumot!B5&"ga "&FIXED(umumiy_malumot!B75)&" ("&umumiy_malumot!B76&") so‘m miqdorida, muddati "&umumiy_malumot!B81&" ("&umumiy_malumot!B82&") oyga va yillik 55 (Ellik besh) foiz miqdorida "&umumiy_malumot!B65&" berich bo‘yicha "&umumiy_malumot!B5&"ning kredit arizasi va "&umumiy_malumot!B147&"ning xulosasi bilan ishtirokchilarni tanishtirdi." -> Birinchi masala yuzasidan: «PULLOL BUSINESS MIKROMOLIYA TASHKILOTI» MChJ kredit bo‘yicha menejeri QODIROVA NAFISA YO‘LDOSHEVNAga 50 000 000,00 (Ellik million so'm) so‘m miqdorida, muddati 30 (o'ttiz) oyga va yillik 55 (Ellik besh) foiz miqdorida Mikroqarz berich bo‘yicha QODIROVA NAFISA YO‘LDOSHEVNAning kredit arizasi va «PULLOL BUSINESS MIKROMOLIYA TASHKILOTI» MChJning xulosasi bilan ishtirokchilarni tanishtirdi. | G7: Protokol raqami | H7: =umumiy_malumot!B1 -> № 56
G8: Savol raqami | H8: 1 | I8: 1 | J8: 2 | K8: 3 | L8: 4 | M8: 5 | N8: 6 | O8: 7 | P8: 8 | Q8: 9 | R8: 10 | S8: 11 | T8: 12 | U8: 13 | V8: 14 | W8: 15 | X8: 16 | Y8: 17 | Z8: 18 | AA8: 19 | AB8: 20 | AC8: 21 | AD8: 22 | AE8: 23 | AF8: 24 | AG8: 25
G9: Savol raqami qol bilan | H9: =IF(H8=I8,I9,IF(H8=J8,J9,IF(H8=K8,K9,IF(H8=L8,L9,IF(H8=M8,M9,IF(H8=N8,N9,IF(H8=O8,O9,IF(H8=P8,P9,IF(H8=Q8,Q9,IF(H8=R8,R9,IF(H8=S8,S9,IF(H8=T8,T9,IF(H8=U8,U9,IF(H8=V8,V9,IF(H8=W8,W9,IF(H8=X8,X9,IF(H8=Y8,Y9,IF(H8=Z8,Z9,IF(H8=AA8,AA9,IF(H8=AB8,AB9,IF(H8=AC8,AC9,IF(H8=AD8,AD9,IF(H8=AE8,AE9,IF(H8=AF8,AF9,IF(H8=AG8,AG9))))))))))))))))))))))))) -> Birinchi | I9: Birinchi | J9: Ikkinchi | K9: Uchinchi | L9: To'rtinchi | M9: Beshinchi | N9: O'ltinchi | O9: Yettinchi | P9: Sakkizinchi | Q9: Tuqqizinchi | R9: O'ninchi | S9: O'n birinchi | T9: O'n ikkinchi | U9: O'n uchinchi | V9: O'n to'rtinchi | W9: O'n beshinchi | X9: O'n oltinchi | Y9: O'n yettinchi | Z9: O'n sakkizinchi | AA9: O'n tuqqizinchi | AB9: Yigirmanchi | AC9: Yigirma birinchi | AD9: Yigizma ikkinchi | AE9: Yigirma uchinchi | AF9: Yigirma to'rtinchi | AG9: Yigirma beshinchi
A14: =""&umumiy_malumot!B65&" ta’minoti:" -> Mikroqarz ta’minoti:
A16: =xulosa!A18:E18 -> Egalik huquqi QODIROVA NAFISA YO‘LDOSHEVNAga tegishli bo'lgan qurilish osti maydoni - , umumiy maydoni - 49,55 va yashash maydoni - 28,99 Ko'p qavatli uydagi xonadon, TOSHKENT SHAHAR BEKTEMIR TUMANI ROXAT KO'CHASI 12 UY 32 XONADON
C17: masala yuzasidan berilgan ma’lumotlarni muhokama qilib, Kredit qo‘mitasi a’zolariga taqdim etilgan zarur hujjatlarni o‘rganib, majlisda ishtirok etgan Kredit qo‘mitasi a’zolarining taklif va mulohazalarini inobatga olgan holda | D17: =""&umumiy_malumot!B147&" kredit qo‘mitasi" -> «PULLOL BUSINESS MIKROMOLIYA TASHKILOTI» MChJ kredit qo‘mitasi | E17: =CONCATENATE(C17,D17) -> masala yuzasidan berilgan ma’lumotlarni muhokama qilib, Kredit qo‘mitasi a’zolariga taqdim etilgan zarur hujjatlarni o‘rganib, majlisda ishtirok etgan Kredit qo‘mitasi a’zolarining taklif va mulohazalarini inobatga olgan holda «PULLOL BUSINESS MIKROMOLIYA TASHKILOTI» MChJ kredit qo‘mitasi
A18: =CONCATENATE(H9,E17) -> Birinchi masala yuzasidan berilgan ma’lumotlarni muhokama qilib, Kredit qo‘mitasi a’zolariga taqdim etilgan zarur hujjatlarni o‘rganib, majlisda ishtirok etgan Kredit qo‘mitasi a’zolarining taklif va mulohazalarini inobatga olgan holda «PULLOL BUSINESS MIKROMOLIYA TASHKILOTI» MChJ kredit qo‘mitasi
A19: QAROR QILADI:
A20: =" "&umumiy_malumot!B5&"ga quyidagi shartlarda "&umumiy_malumot!B65&" berish masalasi ma’qullansin:" -> QODIROVA NAFISA YO‘LDOSHEVNAga quyidagi shartlarda Mikroqarz berish masalasi ma’qullansin:
A21: ="1. "&umumiy_malumot!B65&" summasi: "&FIXED(umumiy_malumot!B75)&" ("&umumiy_malumot!B76&") so'm." -> 1. Mikroqarz summasi: 50 000 000,00 (Ellik million so'm) so'm.
A22: ="2. "&umumiy_malumot!B65&" muddati: "&umumiy_malumot!B81&" ("&umumiy_malumot!B82&") oy " -> 2. Mikroqarz muddati: 30 (o'ttiz) oy
A23: ="3. "&umumiy_malumot!B65&"dan foydalanganlik uchun foiz stavkasi:yillik "&umumiy_malumot!B85&"% ("&umumiy_malumot!B86&") foiz." -> 3. Mikroqarzdan foydalanganlik uchun foiz stavkasi:yillik 55% (Ellik besh ) foiz.
A24: ="4. "&umumiy_malumot!B65&" bo‘yicha asosiy qarz va foizlarni to‘lash:" -> 4. Mikroqarz bo‘yicha asosiy qarz va foizlarni to‘lash:
A25: =kredit_ariza!A19:D19 -> - Mikroqarz shartnomasi bo'yicha har oy annuitet to'lovlari amalga oshiriladi
A26: ="5. "&umumiy_malumot!B65&" bo‘yicha garov "&xulosa!A29:E29&"" -> 5. Mikroqarz bo‘yicha garov - QODIROVA NAFISA YO‘LDOSHEVNA ga mulk huquqi asosida tegishli ko'chmas mulk shaklida Ko'p qavatli uydagi xonadon, manzili: TOSHKENT SHAHAR BEKTEMIR TUMANI ROXAT KO'CHASI 12 UY 32 XONADON, quyidagi tafsilotlarga muvofiq:
A27: =dalolatnoma!A47 -> Nomi | B27: =dalolatnoma!B47 -> Qurilish osti maydoni | C27: =dalolatnoma!C47 -> Umumiy maydoni | D27: =dalolatnoma!D47 -> Yashash maydoni | E27: =dalolatnoma!E47 -> Kelishilgan garov qiymati, so'm
A28: =dalolatnoma!A48 -> Ko'p qavatli uydagi xonadon | B28: =dalolatnoma!B48 -> 0 | C28: =dalolatnoma!C48 -> 49.55 | D28: =dalolatnoma!D48 -> 28.99 | E28: =dalolatnoma!E48 -> 70 000 000,00 (yetmish million so'm)
A29: =dalolatnoma!A22:E22 -> -* avtotransport egasi: QODIROVA NAFISA YO‘LDOSHEVNA
A30: =dalolatnoma!A23:E23 -> -* texnik pasport:
A31: =dalolatnoma!A24:E24 -> -* roʻyxatdan oʻtgan manzili/garaj manzili: TOSHKENT SHAHAR YANGIXAYOT TUMANI 2 STROITELNAYA TERRITORIYA 17 UY 74 XONADON
A32: =dalolatnoma!A25:E25 -> -* davlat raqami:
A33: =dalolatnoma!A50 -> Наименование | B33: =dalolatnoma!B50 -> Полезная площадь | C33: =dalolatnoma!C50 -> Жилая площадь | D33: =dalolatnoma!D50 -> Общая площадь | E33: =dalolatnoma!E50 -> Согласованная залоговая стоимость, сум
A34: =dalolatnoma!A51 -> Yashash xona | B34: =dalolatnoma!B51 -> 3 | C34: =dalolatnoma!C51 -> 18.82 | D34: =dalolatnoma!D51 -> 0 | E34: =""&FIXED(umumiy_malumot!C136,2)&" ("&umumiy_malumot!B137&")" -> 70 000 000,00 (yetmish million so'm)
A35: =dalolatnoma!A52 -> 0 | B35: =dalolatnoma!B52 -> 0 | C35: =dalolatnoma!C52 -> 0 | D35: =dalolatnoma!D52 -> 0
A36: =dalolatnoma!A53 -> Umumiy maydon | B36: =dalolatnoma!B53 -> 43.96 | C36: =dalolatnoma!C53 -> 18.82 | D36: =dalolatnoma!D53 -> 43.96
A37: =dalolatnoma!A54 -> 0 | B37: =dalolatnoma!B54 -> 0 | C37: =dalolatnoma!C54 -> 0 | D37: =dalolatnoma!D54 -> 0
A38: =dalolatnoma!A55 -> 0 | B38: =dalolatnoma!B55 -> 0 | C38: =dalolatnoma!C55 -> 0 | D38: =dalolatnoma!D55 -> 0
A39: =dalolatnoma!A56 -> 0 | B39: =dalolatnoma!B56 -> 0 | C39: =dalolatnoma!C56 -> 0 | D39: =dalolatnoma!D56 -> 0
A40: =dalolatnoma!A57 -> 0 | B40: =dalolatnoma!B57 -> 0 | C40: =dalolatnoma!C57 -> 0 | D40: =dalolatnoma!D57 -> 0
A41: =dalolatnoma!A58 -> 0 | B41: =dalolatnoma!B58 -> 0 | C41: =dalolatnoma!C58 -> 0 | D41: =dalolatnoma!D58 -> 0
A42: =dalolatnoma!A59 -> 0 | B42: =dalolatnoma!B59 -> 0 | C42: =dalolatnoma!C59 -> 0 | D42: =dalolatnoma!D59 -> 0
A43: =dalolatnoma!A60 -> 0 | B43: =dalolatnoma!B60 -> 0 | C43: =dalolatnoma!C60 -> 0 | D43: =dalolatnoma!D60 -> 0
A44: =dalolatnoma!A61 -> 0 | B44: =dalolatnoma!B61 -> 0 | C44: =dalolatnoma!C61 -> 0 | D44: =dalolatnoma!D61 -> 0
A45: =dalolatnoma!A62 -> JAMI | B45: =dalolatnoma!B62 -> 43.96 | C45: =dalolatnoma!C62 -> 18.82 | D45: =dalolatnoma!D62 -> 43.96 | E45: =FIXED(umumiy_malumot!C136,2) -> 70 000 000,00
A46: =dalolatnoma!A39:E39 -> -* ko'chmas mulk egasi: QODIROVA NAFISA YO‘LDOSHEVNA
...

Sheet График дифференц
E1: Приложение №1
F2: ="к договору микрозайма "&umumiy_malumot!B74&"" -> к договору микрозайма 2 fevral 2026 y.dan № 56
A4: График погашения
L5: =umumiy_malumot!B81 -> 30
A6: № | B6: Дата погашения | C6: Остаток основного долга | D6: Сумма погашения, сум
D7: основного долга | E7: процентов* | F7: всего*
A8: 1 | B8: =umumiy_malumot!B79 -> 46106 | C8: =umumiy_malumot!B75 -> 50000000 | D8: =IF(IF(C8=0,L8,IF(C8>1,I8))="",0,(IF(C8=0,L8,IF(C8>1,I8)))) -> 1666666.7 | E8: =IF(C8=0,N6,IF(C8>1,L8)) -> 3842466 | F8: =IF(C8=0,O6,IF(C8>1,M8)) -> 5509132.6 | G8: =B8-umumiy_malumot!B67 -> 51 | H8: =DATE(YEAR(B8),12,31)-DATE(YEAR(B8),1,1)+1 -> 365 | I8: =IF(umumiy_malumot!B83=0,ROUND(C8/L5,2),"") -> 1666666.7 | L8: =ROUND(C8*umumiy_malumot!$B$84/H8,2)*G8 -> 3842466 | M8: =D8+E8 -> 5509132.6 | O8: =TEXT(B8,"ддд") -> Ср | P8: =IF(O8=$U$8,2,IF(O8=$V$8,1,0)) -> 0 | Q8: =DAY(umumiy_malumot!$B$78)+P8 -> 25 | S8: Чт | T8: Пт | U8: Сб | V8: Вс
A9: 2 | B9: =IF(A9<=umumiy_malumot!$B$81,DATE(YEAR(R9),MONTH(R9),DAY(R9)+P9),0) -> 46139 | C9: =C8-D8 -> 48333333 | D9: =IF(C9=0,L9,IF(C9>1,I9)) -> 1666666.7 | E9: =IF(C9=0,N8,IF(C9>1,L9)) -> 2403424.6 | F9: =IF(C9=0,N8,IF(C9>1,M9)) -> 4070091.3 | G9: =B9-B8 -> 33 | H9: =DATE(YEAR(B9),12,31)-DATE(YEAR(B9),1,1)+1 -> 365 | I9: =IF(I8="",ROUND(C8/(L5-1),2),I8) -> 1666666.7 | L9: =ROUND(C9*umumiy_malumot!$B$84/H9,2)*G9 -> 2403424.6 | M9: =D9+E9 -> 4070091.3 | O9: =TEXT(R9,"ддд") -> Сб | P9: =IF(O9=$U$8,2,IF(O9=$V$8,1,0)) -> 2 | Q9: =DAY(umumiy_malumot!$B$78)+P9 -> 27 | R9: =IF(A9<=umumiy_malumot!$B$81,DATE(YEAR($B$8),MONTH($B$8)+A8,DAY(umumiy_malumot!$B$78)),0) -> 46137
A10: 3 | B10: =IF(A10<=umumiy_malumot!$B$81,DATE(YEAR(R10),MONTH(R10),DAY(R10)+P10),0) -> 46167 | C10: =C9-D9 -> 46666667 | D10: =IF(C10=0,L10,IF(C10>1,I10)) -> 1666666.7 | E10: =IF(C10=0,N9,IF(C10>1,L10)) -> 1968949.6 | F10: =IF(C10=0,N9,IF(C10>1,M10)) -> 3635616.3 | G10: =B10-B9 -> 28 | H10: =DATE(YEAR(B10),12,31)-DATE(YEAR(B10),1,1)+1 -> 365 | I10: =I9 -> 1666666.7 | L10: =ROUND(C10*umumiy_malumot!$B$84/H10,2)*G10 -> 1968949.6 | M10: =D10+E10 -> 3635616.3 | O10: =TEXT(R10,"ддд") -> Пн | P10: =IF(O10=$U$8,2,IF(O10=$V$8,1,0)) -> 0 | Q10: =DAY(umumiy_malumot!$B$78)+P10 -> 25 | R10: =IF(A10<=umumiy_malumot!$B$81,DATE(YEAR($B$8),MONTH($B$8)+A9,DAY(umumiy_malumot!$B$78)),0) -> 46167
A11: 4 | B11: =IF(A11<=umumiy_malumot!$B$81,DATE(YEAR(R11),MONTH(R11),DAY(R11)+P11),0) -> 46198 | C11: =C10-D10 -> 45000000 | D11: =IF(C11=0,L11,IF(C11>1,I11)) -> 1666666.7 | E11: =IF(C11=0,N10,IF(C11>1,L11)) -> 2102054.8 | F11: =IF(C11=0,N10,IF(C11>1,M11)) -> 3768721.5 | G11: =B11-B10 -> 31 | H11: =DATE(YEAR(B11),12,31)-DATE(YEAR(B11),1,1)+1 -> 365 | I11: =I10 -> 1666666.7 | L11: =ROUND(C11*umumiy_malumot!$B$84/H11,2)*G11 -> 2102054.8 | M11: =D11+E11 -> 3768721.5 | O11: =TEXT(R11,"ддд") -> Чт | P11: =IF(O11=$U$8,2,IF(O11=$V$8,1,0)) -> 0 | Q11: =DAY(umumiy_malumot!$B$78)+P11 -> 25 | R11: =IF(A11<=umumiy_malumot!$B$81,DATE(YEAR($B$8),MONTH($B$8)+A10,DAY(umumiy_malumot!$B$78)),0) -> 46198
A12: 5 | B12: =IF(A12<=umumiy_malumot!$B$81,DATE(YEAR(R12),MONTH(R12),DAY(R12)+P12),0) -> 46230 | C12: =C11-D11 -> 43333333 | D12: =IF(C12=0,L12,IF(C12>1,I12)) -> 1666666.7 | E12: =IF(C12=0,N11,IF(C12>1,L12)) -> 2089497.6 | F12: =IF(C12=0,N11,IF(C12>1,M12)) -> 3756164.3 | G12: =B12-B11 -> 32 | H12: =DATE(YEAR(B12),12,31)-DATE(YEAR(B12),1,1)+1 -> 365 | I12: =I11 -> 1666666.7 | J12: =umumiy_malumot!B75 -> 50000000 | L12: =ROUND(C12*umumiy_malumot!$B$84/H12,2)*G12 -> 2089497.6 | M12: =D12+E12 -> 3756164.3 | O12: =TEXT(R12,"ддд") -> Сб | P12: =IF(O12=$U$8,2,IF(O12=$V$8,1,0)) -> 2 | Q12: =DAY(umumiy_malumot!$B$78)+P12 -> 27 | R12: =IF(A12<=umumiy_malumot!$B$81,DATE(YEAR($B$8),MONTH($B$8)+A11,DAY(umumiy_malumot!$B$78)),0) -> 46228
A13: 6 | B13: =IF(A13<=umumiy_malumot!$B$81,DATE(YEAR(R13),MONTH(R13),DAY(IF(A13=umumiy_malumot!$B$81,umumiy_malumot!$B$67,IF(A13<umumiy_malumot!$B$81,(Q13),IF(A13>umumiy_malumot!$B$81,$H$56,0)))))) -> 46259 | C13: =C12-D12 -> 41666667 | D13: =IF(C13=0,L13,IF(C13>1,I13)) -> 1666666.7 | E13: =IF(C13=0,N12,IF(C13>1,L13)) -> 1820776.3 | F13: =IF(C13=0,N12,IF(C13>1,M13)) -> 3487443 | G13: =B13-B12 -> 29 | H13: =DATE(YEAR(B13),12,31)-DATE(YEAR(B13),1,1)+1 -> 365 | I13: =IF(L5=H1,K13,IF(L5>H1,I12)) -> 1666666.7 | J13: =SUM($I$8:I12) -> 8333333.3 | K13: =$J$12-J13 -> 41666667 | L13: =ROUND(C13*umumiy_malumot!$B$84/H13,2)*G13 -> 1820776.3 | M13: =D13+E13 -> 3487443 | O13: =TEXT(R13,"ддд") -> Вт | P13: =IF(O13=$U$8,2,IF(O13=$V$8,1,0)) -> 0 | Q13: =DAY(umumiy_malumot!$B$78)+P13 -> 25 | R13: =IF(A13<=umumiy_malumot!$B$81,DATE(YEAR($B$8),MONTH($B$8)+A12,DAY(umumiy_malumot!$B$78)),0) -> 46259
A14: 7 | B14: =IF(A14<=umumiy_malumot!$B$81,DATE(YEAR(R14),MONTH(R14),DAY(IF(A14=umumiy_malumot!$B$81,umumiy_malumot!$B$67,IF(A14<umumiy_malumot!$B$81,(Q14),IF(A14>umumiy_malumot!$B$81,$H$56,0)))))) -> 46290 | C14: =C13-D13 -> 40000000 | D14: =IF(C14=0,L14,IF(C14>1,I14)) -> 1666666.7 | E14: =IF(C14=0,N13,IF(C14>1,L14)) -> 1868493.1 | F14: =IF(C14=0,N13,IF(C14>1,M14)) -> 3535159.7 | G14: =B14-B13 -> 31 | H14: =DATE(YEAR(B14),12,31)-DATE(YEAR(B14),1,1)+1 -> 365 | I14: =IF($L$5=A14,K14,IF($L$5>A14,I13)) -> 1666666.7 | J14: =SUM($I$8:I13) -> 10000000 | K14: =$J$12-J14 -> 40000000 | L14: =ROUND(C14*umumiy_malumot!$B$84/H14,2)*G14 -> 1868493.1 | M14: =D14+E14 -> 3535159.7 | O14: =TEXT(R14,"ддд") -> Пт | P14: =IF(O14=$U$8,2,IF(O14=$V$8,1,0)) -> 0 | Q14: =DAY(umumiy_malumot!$B$78)+P14 -> 25 | R14: =IF(A14<=umumiy_malumot!$B$81,DATE(YEAR($B$8),MONTH($B$8)+A13,DAY(umumiy_malumot!$B$78)),0) -> 46290
A15: 8 | B15: =IF(A15<=umumiy_malumot!$B$81,DATE(YEAR(R15),MONTH(R15),DAY(IF(A15=umumiy_malumot!$B$81,umumiy_malumot!$B$67,IF(A15<umumiy_malumot!$B$81,(Q15),IF(A15>umumiy_malumot!$B$81,$H$56,0)))))) -> 46321 | C15: =C14-D14 -> 38333333 | D15: =IF(C15=0,L15,IF(C15>1,I15)) -> 1666666.7 | E15: =IF(C15=0,N14,IF(C15>1,L15)) -> 1790639.4 | F15: =IF(C15=0,N14,IF(C15>1,M15)) -> 3457306 | G15: =B15-B14 -> 31 | H15: =DATE(YEAR(B15),12,31)-DATE(YEAR(B15),1,1)+1 -> 365 | I15: =IF($L$5=A15,K15,IF($L$5>A15,I14)) -> 1666666.7 | J15: =SUM($I$8:I14) -> 11666667 | K15: =$J$12-J15 -> 38333333 | L15: =ROUND(C15*umumiy_malumot!$B$84/H15,2)*G15 -> 1790639.4 | M15: =D15+E15 -> 3457306 | O15: =TEXT(R15,"ддд") -> Вс | P15: =IF(O15=$U$8,2,IF(O15=$V$8,1,0)) -> 1 | Q15: =DAY(umumiy_malumot!$B$78)+P15 -> 26 | R15: =IF(A15<=umumiy_malumot!$B$81,DATE(YEAR($B$8),MONTH($B$8)+A14,DAY(umumiy_malumot!$B$78)),0) -> 46320
A16: 9 | B16: =IF(A16<=umumiy_malumot!$B$81,DATE(YEAR(R16),MONTH(R16),DAY(IF(A16=umumiy_malumot!$B$81,umumiy_malumot!$B$67,IF(A16<umumiy_malumot!$B$81,(Q16),IF(A16>umumiy_malumot!$B$81,$H$56,0)))))) -> 46351 | C16: =C15-D15 -> 36666667 | D16: =IF(C16=0,L16,IF(C16>1,I16)) -> 1666666.7 | E16: =IF(C16=0,N15,IF(C16>1,L16)) -> 1657534.2 | F16: =IF(C16=0,N15,IF(C16>1,M16)) -> 3324200.9 | G16: =B16-B15 -> 30 | H16: =DATE(YEAR(B16),12,31)-DATE(YEAR(B16),1,1)+1 -> 365 | I16: =IF($L$5=A16,K16,IF($L$5>A16,I15)) -> 1666666.7 | J16: =SUM($I$8:I15) -> 13333333 | K16: =$J$12-J16 -> 36666667 | L16: =ROUND(C16*umumiy_malumot!$B$84/H16,2)*G16 -> 1657534.2 | M16: =D16+E16 -> 3324200.9 | O16: =TEXT(R16,"ддд") -> Ср | P16: =IF(O16=$U$8,2,IF(O16=$V$8,1,0)) -> 0 | Q16: =DAY(umumiy_malumot!$B$78)+P16 -> 25 | R16: =IF(A16<=umumiy_malumot!$B$81,DATE(YEAR($B$8),MONTH($B$8)+A15,DAY(umumiy_malumot!$B$78)),0) -> 46351
A17: 10 | B17: =IF(A17<=umumiy_malumot!$B$81,DATE(YEAR(R17),MONTH(R17),DAY(IF(A17=umumiy_malumot!$B$81,umumiy_malumot!$B$67,IF(A17<umumiy_malumot!$B$81,(Q17),IF(A17>umumiy_malumot!$B$81,$H$56,0)))))) -> 46381 | C17: =C16-D16 -> 35000000 | D17: =IF(C17=0,L17,IF(C17>1,I17)) -> 1666666.7 | E17: =IF(C17=0,N16,IF(C17>1,L17)) -> 1582191.9 | F17: =IF(C17=0,N16,IF(C17>1,M17)) -> 3248858.6 | G17: =B17-B16 -> 30 | H17: =DATE(YEAR(B17),12,31)-DATE(YEAR(B17),1,1)+1 -> 365 | I17: =IF($L$5=A17,K17,IF($L$5>A17,I16)) -> 1666666.7 | J17: =SUM($I$8:I16) -> 15000000 | K17: =$J$12-J17 -> 35000000 | L17: =ROUND(C17*umumiy_malumot!$B$84/H17,2)*G17 -> 1582191.9 | M17: =D17+E17 -> 3248858.6 | O17: =TEXT(R17,"ддд") -> Пт | P17: =IF(O17=$U$8,2,IF(O17=$V$8,1,0)) -> 0 | Q17: =DAY(umumiy_malumot!$B$78)+P17 -> 25 | R17: =IF(A17<=umumiy_malumot!$B$81,DATE(YEAR($B$8),MONTH($B$8)+A16,DAY(umumiy_malumot!$B$78)),0) -> 46381
A18: 11 | B18: =IF(A18<=umumiy_malumot!$B$81,DATE(YEAR(R18),MONTH(R18),DAY(IF(A18=umumiy_malumot!$B$81,umumiy_malumot!$B$67,IF(A18<umumiy_malumot!$B$81,(Q18),IF(A18>umumiy_malumot!$B$81,$H$56,0)))))) -> 46412 | C18: =C17-D17 -> 33333333 | D18: =IF(C18=0,L18,IF(C18>1,I18)) -> 1666666.7 | E18: =IF(C18=0,N17,IF(C18>1,L18)) -> 1557077.6 | F18: =IF(C18=0,N17,IF(C18>1,M18)) -> 3223744.3 | G18: =B18-B17 -> 31 | H18: =DATE(YEAR(B18),12,31)-DATE(YEAR(B18),1,1)+1 -> 365 | I18: =IF($L$5=A18,K18,IF($L$5>A18,I17)) -> 1666666.7 | J18: =SUM($I$8:I17) -> 16666667 | K18: =$J$12-J18 -> 33333333 | L18: =ROUND(C18*umumiy_malumot!$B$84/H18,2)*G18 -> 1557077.6 | M18: =D18+E18 -> 3223744.3 | O18: =TEXT(R18,"ддд") -> Пн | P18: =IF(O18=$U$8,2,IF(O18=$V$8,1,0)) -> 0 | Q18: =DAY(umumiy_malumot!$B$78)+P18 -> 25 | R18: =IF(A18<=umumiy_malumot!$B$81,DATE(YEAR($B$8),MONTH($B$8)+A17,DAY(umumiy_malumot!$B$78)),0) -> 46412
A19: 12 | B19: =IF(A19<=umumiy_malumot!$B$81,DATE(YEAR(R19),MONTH(R19),DAY(IF(A19=umumiy_malumot!$B$81,umumiy_malumot!$B$67,IF(A19<umumiy_malumot!$B$81,(Q19),IF(A19>umumiy_malumot!$B$81,$H$56,0)))))) -> 46443 | C19: =C18-D18 -> 31666667 | D19: =IF(C19=0,L19,IF(C19>1,I19)) -> 1666666.7 | E19: =IF(C19=0,N18,IF(C19>1,L19)) -> 1479223.6 | F19: =IF(C19=0,N18,IF(C19>1,M19)) -> 3145890.3 | G19: =B19-B18 -> 31 | H19: =DATE(YEAR(B19),12,31)-DATE(YEAR(B19),1,1)+1 -> 365 | I19: =IF($L$5=A19,K19,IF($L$5>A19,I18)) -> 1666666.7 | J19: =SUM($I$8:I18) -> 18333333 | K19: =$J$12-J19 -> 31666667 | L19: =ROUND(C19*umumiy_malumot!$B$84/H19,2)*G19 -> 1479223.6 | M19: =D19+E19 -> 3145890.3 | O19: =TEXT(R19,"ддд") -> Чт | P19: =IF(O19=$U$8,2,IF(O19=$V$8,1,0)) -> 0 | Q19: =DAY(umumiy_malumot!$B$78)+P19 -> 25 | R19: =IF(A19<=umumiy_malumot!$B$81,DATE(YEAR($B$8),MONTH($B$8)+A18,DAY(umumiy_malumot!$B$78)),0) -> 46443
A20: 13 | B20: =IF(A20<=umumiy_malumot!$B$81,DATE(YEAR(R20),MONTH(R20),DAY(IF(A20=umumiy_malumot!$B$81,umumiy_malumot!$B$67,IF(A20<umumiy_malumot!$B$81,(Q20),IF(A20>umumiy_malumot!$B$81,$H$56,0)))))) -> 46471 | C20: =C19-D19 -> 30000000 | D20: =IF(C20=0,L20,IF(C20>1,I20)) -> 1666666.7 | E20: =IF(C20=0,N19,IF(C20>1,L20)) -> 1265753.4 | F20: =IF(C20=0,N19,IF(C20>1,M20)) -> 2932420.1 | G20: =B20-B19 -> 28 | H20: =DATE(YEAR(B20),12,31)-DATE(YEAR(B20),1,1)+1 -> 365 | I20: =IF($L$5=A20,K20,IF($L$5>A20,I19)) -> 1666666.7 | J20: =SUM($I$8:I19) -> 20000000 | K20: =$J$12-J20 -> 30000000 | L20: =ROUND(C20*umumiy_malumot!$B$84/H20,2)*G20 -> 1265753.4 | M20: =D20+E20 -> 2932420.1 | O20: =TEXT(R20,"ддд") -> Чт | P20: =IF(O20=$U$8,2,IF(O20=$V$8,1,0)) -> 0 | Q20: =DAY(umumiy_malumot!$B$78)+P20 -> 25 | R20: =IF(A20<=umumiy_malumot!$B$81,DATE(YEAR($B$8),MONTH($B$8)+A19,DAY(umumiy_malumot!$B$78)),0) -> 46471
A21: 14 | B21: =IF(A21<=umumiy_malumot!$B$81,DATE(YEAR(R21),MONTH(R21),DAY(IF(A21=umumiy_malumot!$B$81,umumiy_malumot!$B$67,IF(A21<umumiy_malumot!$B$81,(Q21),IF(A21>umumiy_malumot!$B$81,$H$56,0)))))) -> 46503 | C21: =C20-D20 -> 28333333 | D21: =IF(C21=0,L21,IF(C21>1,I21)) -> 1666666.7 | E21: =IF(C21=0,N20,IF(C21>1,L21)) -> 1366209.9 | F21: =IF(C21=0,N20,IF(C21>1,M21)) -> 3032876.6 | G21: =B21-B20 -> 32 | H21: =DATE(YEAR(B21),12,31)-DATE(YEAR(B21),1,1)+1 -> 365 | I21: =IF($L$5=A21,K21,IF($L$5>A21,I20)) -> 1666666.7 | J21: =SUM($I$8:I20) -> 21666667 | K21: =$J$12-J21 -> 28333333 | L21: =ROUND(C21*umumiy_malumot!$B$84/H21,2)*G21 -> 1366209.9 | M21: =D21+E21 -> 3032876.6 | O21: =TEXT(R21,"ддд") -> Вс | P21: =IF(O21=$U$8,2,IF(O21=$V$8,1,0)) -> 1 | Q21: =DAY(umumiy_malumot!$B$78)+P21 -> 26 | R21: =IF(A21<=umumiy_malumot!$B$81,DATE(YEAR($B$8),MONTH($B$8)+A20,DAY(umumiy_malumot!$B$78)),0) -> 46502
A22: 15 | B22: =IF(A22<=umumiy_malumot!$B$81,DATE(YEAR(R22),MONTH(R22),DAY(IF(A22=umumiy_malumot!$B$81,umumiy_malumot!$B$67,IF(A22<umumiy_malumot!$B$81,(Q22),IF(A22>umumiy_malumot!$B$81,$H$56,0)))))) -> 46532 | C22: =C21-D21 -> 26666667 | D22: =IF(C22=0,L22,IF(C22>1,I22)) -> 1666666.7 | E22: =IF(C22=0,N21,IF(C22>1,L22)) -> 1165296.9 | F22: =IF(C22=0,N21,IF(C22>1,M22)) -> 2831963.5 | G22: =B22-B21 -> 29 | H22: =DATE(YEAR(B22),12,31)-DATE(YEAR(B22),1,1)+1 -> 365 | I22: =IF($L$5=A22,K22,IF($L$5>A22,I21)) -> 1666666.7 | J22: =SUM($I$8:I21) -> 23333333 | K22: =$J$12-J22 -> 26666667 | L22: =ROUND(C22*umumiy_malumot!$B$84/H22,2)*G22 -> 1165296.9 | M22: =D22+E22 -> 2831963.5 | O22: =TEXT(R22,"ддд") -> Вт | P22: =IF(O22=$U$8,2,IF(O22=$V$8,1,0)) -> 0 | Q22: =DAY(umumiy_malumot!$B$78)+P22 -> 25 | R22: =IF(A22<=umumiy_malumot!$B$81,DATE(YEAR($B$8),MONTH($B$8)+A21,DAY(umumiy_malumot!$B$78)),0) -> 46532
A23: 16 | B23: =IF(A23<=umumiy_malumot!$B$81,DATE(YEAR(R23),MONTH(R23),DAY(IF(A23=umumiy_malumot!$B$81,umumiy_malumot!$B$67,IF(A23<umumiy_malumot!$B$81,(Q23),IF(A23>umumiy_malumot!$B$81,$H$56,0)))))) -> 46563 | C23: =C22-D22 -> 25000000 | D23: =IF(C23=0,L23,IF(C23>1,I23)) -> 1666666.7 | E23: =IF(C23=0,N22,IF(C23>1,L23)) -> 1167808.1 | F23: =IF(C23=0,N22,IF(C23>1,M23)) -> 2834474.8 | G23: =B23-B22 -> 31 | H23: =DATE(YEAR(B23),12,31)-DATE(YEAR(B23),1,1)+1 -> 365 | I23: =IF($L$5=A23,K23,IF($L$5>A23,I22)) -> 1666666.7 | J23: =SUM($I$8:I22) -> 25000000 | K23: =$J$12-J23 -> 25000000 | L23: =ROUND(C23*umumiy_malumot!$B$84/H23,2)*G23 -> 1167808.1 | M23: =D23+E23 -> 2834474.8 | O23: =TEXT(R23,"ддд") -> Пт | P23: =IF(O23=$U$8,2,IF(O23=$V$8,1,0)) -> 0 | Q23: =DAY(umumiy_malumot!$B$78)+P23 -> 25 | R23: =IF(A23<=umumiy_malumot!$B$81,DATE(YEAR($B$8),MONTH($B$8)+A22,DAY(umumiy_malumot!$B$78)),0) -> 46563
A24: 17 | B24: =IF(A24<=umumiy_malumot!$B$81,DATE(YEAR(R24),MONTH(R24),DAY(IF(A24=umumiy_malumot!$B$81,umumiy_malumot!$B$67,IF(A24<umumiy_malumot!$B$81,(Q24),IF(A24>umumiy_malumot!$B$81,$H$56,0)))))) -> 46594 | C24: =C23-D23 -> 23333333 | D24: =IF(C24=0,L24,IF(C24>1,I24)) -> 1666666.7 | E24: =IF(C24=0,N23,IF(C24>1,L24)) -> 1089954.4 | F24: =IF(C24=0,N23,IF(C24>1,M24)) -> 2756621.1 | G24: =B24-B23 -> 31 | H24: =DATE(YEAR(B24),12,31)-DATE(YEAR(B24),1,1)+1 -> 365 | I24: =IF($L$5=A24,K24,IF($L$5>A24,I23)) -> 1666666.7 | J24: =SUM($I$8:I23) -> 26666667 | K24: =$J$12-J24 -> 23333333 | L24: =ROUND(C24*umumiy_malumot!$B$84/H24,2)*G24 -> 1089954.4 | M24: =D24+E24 -> 2756621.1 | O24: =TEXT(R24,"ддд") -> Вс | P24: =IF(O24=$U$8,2,IF(O24=$V$8,1,0)) -> 1 | Q24: =DAY(umumiy_malumot!$B$78)+P24 -> 26 | R24: =IF(A24<=umumiy_malumot!$B$81,DATE(YEAR($B$8),MONTH($B$8)+A23,DAY(umumiy_malumot!$B$78)),0) -> 46593
A25: 18 | B25: =IF(A25<=umumiy_malumot!$B$81,DATE(YEAR(R25),MONTH(R25),DAY(IF(A25=umumiy_malumot!$B$81,umumiy_malumot!$B$67,IF(A25<umumiy_malumot!$B$81,(Q25),IF(A25>umumiy_malumot!$B$81,$H$56,0)))))) -> 46624 | C25: =C24-D24 -> 21666667 | D25: =IF(C25=0,L25,IF(C25>1,I25)) -> 1666666.7 | E25: =IF(C25=0,N24,IF(C25>1,L25)) -> 979452 | F25: =IF(C25=0,N24,IF(C25>1,M25)) -> 2646118.7 | G25: =B25-B24 -> 30 | H25: =DATE(YEAR(B25),12,31)-DATE(YEAR(B25),1,1)+1 -> 365 | I25: =IF($L$5=A25,K25,IF($L$5>A25,I24)) -> 1666666.7 | J25: =SUM($I$8:I24) -> 28333333 | K25: =$J$12-J25 -> 21666667 | L25: =ROUND(C25*umumiy_malumot!$B$84/H25,2)*G25 -> 979452 | M25: =D25+E25 -> 2646118.7 | O25: =TEXT(R25,"ддд") -> Ср | P25: =IF(O25=$U$8,2,IF(O25=$V$8,1,0)) -> 0 | Q25: =DAY(umumiy_malumot!$B$78)+P25 -> 25 | R25: =IF(A25<=umumiy_malumot!$B$81,DATE(YEAR($B$8),MONTH($B$8)+A24,DAY(umumiy_malumot!$B$78)),0) -> 46624
... A31: 24 | B31: =IF(A31<=umumiy_malumot!$B$81,DATE(YEAR(R31),MONTH(R31),DAY(IF(A31=umumiy_malumot!$B$81,umumiy_malumot!$B$67,IF(A31<umumiy_malumot!$B$81,(Q31),IF(A31>umumiy_malumot!$B$81,$H$56,0)))))) -> 46808 | C31: =C30-D30 -> 11666667 | D31: =IF(C31=0,L31,IF(C31>1,I31)) -> 1666666.7 | E31: =IF(C31=0,N30,IF(C31>1,L31)) -> 543488.28 | F31: =IF(C31=0,N30,IF(C31>1,M31)) -> 2210155 | G31: =B31-B30 -> 31 | H31: =DATE(YEAR(B31),12,31)-DATE(YEAR(B31),1,1)+1 -> 366 | I31: =IF($L$5=A31,K31,IF($L$5>A31,I30)) -> 1666666.7 | J31: =SUM($I$8:I30) -> 38333333 | K31: =$J$12-J31 -> 11666667 | L31: =ROUND(C31*umumiy_malumot!$B$84/H31,2)*G31 -> 543488.28 | M31: =D31+E31 -> 2210155 | O31: =TEXT(R31,"ддд") -> Пт | P31: =IF(O31=$U$8,2,IF(O31=$V$8,1,0)) -> 0 | Q31: =DAY(umumiy_malumot!$B$78)+P31 -> 25 | R31: =IF(A31<=umumiy_malumot!$B$81,DATE(YEAR($B$8),MONTH($B$8)+A30,DAY(umumiy_malumot!$B$78)),0) -> 46808
A32: =1+A31 -> 25 | B32: =IF(A32<=umumiy_malumot!$B$81,DATE(YEAR(R32),MONTH(R32),DAY(IF(A32=umumiy_malumot!$B$81,umumiy_malumot!$B$67,IF(A32<umumiy_malumot!$B$81,(Q32),IF(A32>umumiy_malumot!$B$81,$H$56,0)))))) -> 46839 | C32: =C31-D31 -> 9999999.9 | D32: =IF(C32=0,L32,IF(C32>1,I32)) -> 1666666.7 | E32: =IF(C32=0,N31,IF(C32>1,L32)) -> 465846.92 | F32: =IF(C32=0,N31,IF(C32>1,M32)) -> 2132513.6 | G32: =B32-B31 -> 31 | H32: =DATE(YEAR(B32),12,31)-DATE(YEAR(B32),1,1)+1 -> 366 | I32: =IF($L$5=A32,K32,IF($L$5>A32,I31)) -> 1666666.7 | J32: =SUM($I$8:I31) -> 40000000 | K32: =$J$12-J32 -> 9999999.9 | L32: =ROUND(C32*umumiy_malumot!$B$84/H32,2)*G32 -> 465846.92 | M32: =D32+E32 -> 2132513.6 | O32: =TEXT(R32,"ддд") -> Сб | P32: =IF(O32=$U$8,2,IF(O32=$V$8,1,0)) -> 2 | Q32: =DAY(umumiy_malumot!$B$78)+P32 -> 27 | R32: =IF(A32<=umumiy_malumot!$B$81,DATE(YEAR($B$8),MONTH($B$8)+A31,DAY(umumiy_malumot!$B$78)),0) -> 46837
A33: =1+A32 -> 26 | B33: =IF(A33<=umumiy_malumot!$B$81,DATE(YEAR(R33),MONTH(R33),DAY(IF(A33=umumiy_malumot!$B$81,umumiy_malumot!$B$67,IF(A33<umumiy_malumot!$B$81,(Q33),IF(A33>umumiy_malumot!$B$81,$H$56,0)))))) -> 46868 | C33: =C32-D32 -> 8333333.2 | D33: =IF(C33=0,L33,IF(C33>1,I33)) -> 1666666.7 | E33: =IF(C33=0,N32,IF(C33>1,L33)) -> 363160.33 | F33: =IF(C33=0,N32,IF(C33>1,M33)) -> 2029827 | G33: =B33-B32 -> 29 | H33: =DATE(YEAR(B33),12,31)-DATE(YEAR(B33),1,1)+1 -> 366 | I33: =IF($L$5=A33,K33,IF($L$5>A33,I32)) -> 1666666.7 | J33: =SUM($I$8:I32) -> 41666667 | K33: =$J$12-J33 -> 8333333.2 | L33: =ROUND(C33*umumiy_malumot!$B$84/H33,2)*G33 -> 363160.33 | M33: =D33+E33 -> 2029827 | O33: =TEXT(R33,"ддд") -> Вт | P33: =IF(O33=$U$8,2,IF(O33=$V$8,1,0)) -> 0 | Q33: =DAY(umumiy_malumot!$B$78)+P33 -> 25 | R33: =IF(A33<=umumiy_malumot!$B$81,DATE(YEAR($B$8),MONTH($B$8)+A32,DAY(umumiy_malumot!$B$78)),0) -> 46868
A34: =1+A33 -> 27 | B34: =IF(A34<=umumiy_malumot!$B$81,DATE(YEAR(R34),MONTH(R34),DAY(IF(A34=umumiy_malumot!$B$81,umumiy_malumot!$B$67,IF(A34<umumiy_malumot!$B$81,(Q34),IF(A34>umumiy_malumot!$B$81,$H$56,0)))))) -> 46898 | C34: =C33-D33 -> 6666666.6 | D34: =IF(C34=0,L34,IF(C34>1,I34)) -> 1666666.7 | E34: =IF(C34=0,N33,IF(C34>1,L34)) -> 300546.3 | F34: =IF(C34=0,N33,IF(C34>1,M34)) -> 1967213 | G34: =B34-B33 -> 30 | H34: =DATE(YEAR(B34),12,31)-DATE(YEAR(B34),1,1)+1 -> 366 | I34: =IF($L$5=A34,K34,IF($L$5>A34,I33)) -> 1666666.7 | J34: =SUM($I$8:I33) -> 43333333 | K34: =$J$12-J34 -> 6666666.6 | L34: =ROUND(C34*umumiy_malumot!$B$84/H34,2)*G34 -> 300546.3 | M34: =D34+E34 -> 1967213 | O34: =TEXT(R34,"ддд") -> Чт | P34: =IF(O34=$U$8,2,IF(O34=$V$8,1,0)) -> 0 | Q34: =DAY(umumiy_malumot!$B$78)+P34 -> 25 | R34: =IF(A34<=umumiy_malumot!$B$81,DATE(YEAR($B$8),MONTH($B$8)+A33,DAY(umumiy_malumot!$B$78)),0) -> 46898
A35: =1+A34 -> 28 | B35: =IF(A35<=umumiy_malumot!$B$81,DATE(YEAR(R35),MONTH(R35),DAY(IF(A35=umumiy_malumot!$B$81,umumiy_malumot!$B$67,IF(A35<umumiy_malumot!$B$81,(Q35),IF(A35>umumiy_malumot!$B$81,$H$56,0)))))) -> 46930 | C35: =C34-D34 -> 4999999.9 | D35: =IF(C35=0,L35,IF(C35>1,I35)) -> 1666666.7 | E35: =IF(C35=0,N34,IF(C35>1,L35)) -> 240437.12 | F35: =IF(C35=0,N34,IF(C35>1,M35)) -> 1907103.8 | G35: =B35-B34 -> 32 | H35: =DATE(YEAR(B35),12,31)-DATE(YEAR(B35),1,1)+1 -> 366 | I35: =IF($L$5=A35,K35,IF($L$5>A35,I34)) -> 1666666.7 | J35: =SUM($I$8:I34) -> 45000000 | K35: =$J$12-J35 -> 4999999.9 | L35: =ROUND(C35*umumiy_malumot!$B$84/H35,2)*G35 -> 240437.12 | M35: =D35+E35 -> 1907103.8 | O35: =TEXT(R35,"ддд") -> Вс | P35: =IF(O35=$U$8,2,IF(O35=$V$8,1,0)) -> 1 | Q35: =DAY(umumiy_malumot!$B$78)+P35 -> 26 | R35: =IF(A35<=umumiy_malumot!$B$81,DATE(YEAR($B$8),MONTH($B$8)+A34,DAY(umumiy_malumot!$B$78)),0) -> 46929
A36: =1+A35 -> 29 | B36: =IF(A36<=umumiy_malumot!$B$81,DATE(YEAR(R36),MONTH(R36),DAY(IF(A36=umumiy_malumot!$B$81,umumiy_malumot!$B$67,IF(A36<umumiy_malumot!$B$81,(Q36),IF(A36>umumiy_malumot!$B$81,$H$56,0)))))) -> 46959 | C36: =C35-D35 -> 3333333.2 | D36: =IF(C36=0,L36,IF(C36>1,I36)) -> 1666666.7 | E36: =IF(C36=0,N35,IF(C36>1,L36)) -> 145264.19 | F36: =IF(C36=0,N35,IF(C36>1,M36)) -> 1811930.9 | G36: =B36-B35 -> 29 | H36: =DATE(YEAR(B36),12,31)-DATE(YEAR(B36),1,1)+1 -> 366 | I36: =IF($L$5=A36,K36,IF($L$5>A36,I35)) -> 1666666.7 | J36: =SUM($I$8:I35) -> 46666667 | K36: =$J$12-J36 -> 3333333.2 | L36: =ROUND(C36*umumiy_malumot!$B$84/H36,2)*G36 -> 145264.19 | M36: =D36+E36 -> 1811930.9 | O36: =TEXT(R36,"ддд") -> Вт | P36: =IF(O36=$U$8,2,IF(O36=$V$8,1,0)) -> 0 | Q36: =DAY(umumiy_malumot!$B$78)+P36 -> 25 | R36: =IF(A36<=umumiy_malumot!$B$81,DATE(YEAR($B$8),MONTH($B$8)+A35,DAY(umumiy_malumot!$B$78)),0) -> 46959
A37: =1+A36 -> 30 | B37: =IF(A37<=umumiy_malumot!$B$81,DATE(YEAR(R37),MONTH(R37),DAY(IF(A37=umumiy_malumot!$B$81,umumiy_malumot!$B$67,IF(A37<umumiy_malumot!$B$81,(Q37),IF(A37>umumiy_malumot!$B$81,$H$56,0)))))) -> 46967 | C37: =C36-D36 -> 1666666.6 | D37: =IF(C37=0,L37,IF(C37>1,I37)) -> 1666666.6 | E37: =IF(C37=0,N36,IF(C37>1,L37)) -> 20036.4 | F37: =IF(C37=0,N36,IF(C37>1,M37)) -> 1686703 | G37: =B37-B36 -> 8 | H37: =DATE(YEAR(B37),12,31)-DATE(YEAR(B37),1,1)+1 -> 366 | I37: =IF($L$5=A37,K37,IF($L$5>A37,I36)) -> 1666666.6 | J37: =SUM($I$8:I36) -> 48333333 | K37: =$J$12-J37 -> 1666666.6 | L37: =ROUND(C37*umumiy_malumot!$B$84/H37,2)*G37 -> 20036.4 | M37: =D37+E37 -> 1686703 | O37: =TEXT(R37,"ддд") -> Пт | P37: =IF(O37=$U$8,2,IF(O37=$V$8,1,0)) -> 0 | Q37: =DAY(umumiy_malumot!$B$78)+P37 -> 25 | R37: =IF(A37<=umumiy_malumot!$B$81,DATE(YEAR($B$8),MONTH($B$8)+A36,DAY(umumiy_malumot!$B$78)),0) -> 46990
A38: =1+A37 -> 31 | B38: =IF(A38<=umumiy_malumot!$B$81,DATE(YEAR(R38),MONTH(R38),DAY(IF(A38=umumiy_malumot!$B$81,umumiy_malumot!$B$67,IF(A38<umumiy_malumot!$B$81,(Q38),IF(A38>umumiy_malumot!$B$81,$H$56,0)))))) -> FALSE | C38: =C37-D37 -> -3.7252903e-09 | D38: =IF(C38=0,L38,IF(C38>1,I38)) -> FALSE | E38: =IF(C38=0,N37,IF(C38>1,L38)) -> FALSE | F38: =IF(C38=0,N37,IF(C38>1,M38)) -> FALSE | G38: =B38-B37 -> -46967 | H38: =DATE(YEAR(B38),12,31)-DATE(YEAR(B38),1,1)+1 -> 366 | I38: =IF($L$5=A38,K38,IF($L$5>A38,I37)) -> FALSE | J38: =SUM($I$8:I37) -> 50000000 | K38: =$J$12-J38 -> 0 | L38: =ROUND(C38*umumiy_malumot!$B$84/H38,2)*G38 -> 0 | M38: =D38+E38 -> 0 | O38: =TEXT(R38,"ддд") -> Сб | P38: =IF(O38=$U$8,2,IF(O38=$V$8,1,0)) -> 2 | Q38: =DAY(umumiy_malumot!$B$78)+P38 -> 27 | R38: =IF(A38<=umumiy_malumot!$B$81,DATE(YEAR($B$8),MONTH($B$8)+A37,DAY(umumiy_malumot!$B$78)),0) -> 0
A39: =1+A38 -> 32 | B39: =IF(A39<=umumiy_malumot!$B$81,DATE(YEAR(R39),MONTH(R39),DAY(IF(A39=umumiy_malumot!$B$81,umumiy_malumot!$B$67,IF(A39<umumiy_malumot!$B$81,(Q39),IF(A39>umumiy_malumot!$B$81,$H$56,0)))))) -> FALSE | C39: =C38-D38 -> -3.7252903e-09 | D39: =IF(C39=0,L39,IF(C39>1,I39)) -> FALSE | E39: =IF(C39=0,N38,IF(C39>1,L39)) -> FALSE | F39: =IF(C39=0,N38,IF(C39>1,M39)) -> FALSE | G39: =B39-B38 -> 0 | H39: =DATE(YEAR(B39),12,31)-DATE(YEAR(B39),1,1)+1 -> 366 | I39: =IF($L$5=A39,K39,IF($L$5>A39,I38)) -> FALSE | J39: =SUM($I$8:I38) -> 50000000 | K39: =$J$12-J39 -> 0 | L39: =ROUND(C39*umumiy_malumot!$B$84/H39,2)*G39 -> 0 | M39: =D39+E39 -> 0 | O39: =TEXT(R39,"ддд") -> Сб | P39: =IF(O39=$U$8,2,IF(O39=$V$8,1,0)) -> 2 | Q39: =DAY(umumiy_malumot!$B$78)+P39 -> 27 | R39: =IF(A39<=umumiy_malumot!$B$81,DATE(YEAR($B$8),MONTH($B$8)+A38,DAY(umumiy_malumot!$B$78)),0) -> 0
A40: =1+A39 -> 33 | B40: =IF(A40<=umumiy_malumot!$B$81,DATE(YEAR(R40),MONTH(R40),DAY(IF(A40=umumiy_malumot!$B$81,umumiy_malumot!$B$67,IF(A40<umumiy_malumot!$B$81,(Q40),IF(A40>umumiy_malumot!$B$81,$H$56,0)))))) -> FALSE | C40: =C39-D39 -> -3.7252903e-09 | D40: =IF(C40=0,L40,IF(C40>1,I40)) -> FALSE | E40: =IF(C40=0,N39,IF(C40>1,L40)) -> FALSE | F40: =IF(C40=0,N39,IF(C40>1,M40)) -> FALSE | G40: =B40-B39 -> 0 | H40: =DATE(YEAR(B40),12,31)-DATE(YEAR(B40),1,1)+1 -> 366 | I40: =IF($L$5=A40,K40,IF($L$5>A40,I39)) -> FALSE | J40: =SUM($I$8:I39) -> 50000000 | K40: =$J$12-J40 -> 0 | L40: =ROUND(C40*umumiy_malumot!$B$84/H40,2)*G40 -> 0 | M40: =D40+E40 -> 0 | O40: =TEXT(R40,"ддд") -> Сб | P40: =IF(O40=$U$8,2,IF(O40=$V$8,1,0)) -> 2 | Q40: =DAY(umumiy_malumot!$B$78)+P40 -> 27 | R40: =IF(A40<=umumiy_malumot!$B$81,DATE(YEAR($B$8),MONTH($B$8)+A39,DAY(umumiy_malumot!$B$78)),0) -> 0
A41: =1+A40 -> 34 | B41: =IF(A41<=umumiy_malumot!$B$81,DATE(YEAR(R41),MONTH(R41),DAY(IF(A41=umumiy_malumot!$B$81,umumiy_malumot!$B$67,IF(A41<umumiy_malumot!$B$81,(Q41),IF(A41>umumiy_malumot!$B$81,$H$56,0)))))) -> FALSE | C41: =C40-D40 -> -3.7252903e-09 | D41: =IF(C41=0,L41,IF(C41>1,I41)) -> FALSE | E41: =IF(C41=0,N40,IF(C41>1,L41)) -> FALSE | F41: =IF(C41=0,N40,IF(C41>1,M41)) -> FALSE | G41: =B41-B40 -> 0 | H41: =DATE(YEAR(B41),12,31)-DATE(YEAR(B41),1,1)+1 -> 366 | I41: =IF($L$5=A41,K41,IF($L$5>A41,I40)) -> FALSE | J41: =SUM($I$8:I40) -> 50000000 | K41: =$J$12-J41 -> 0 | L41: =ROUND(C41*umumiy_malumot!$B$84/H41,2)*G41 -> 0 | M41: =D41+E41 -> 0 | O41: =TEXT(R41,"ддд") -> Сб | P41: =IF(O41=$U$8,2,IF(O41=$V$8,1,0)) -> 2 | Q41: =DAY(umumiy_malumot!$B$78)+P41 -> 27 | R41: =IF(A41<=umumiy_malumot!$B$81,DATE(YEAR($B$8),MONTH($B$8)+A40,DAY(umumiy_malumot!$B$78)),0) -> 0
A42: =1+A41 -> 35 | B42: =IF(A42<=umumiy_malumot!$B$81,DATE(YEAR(R42),MONTH(R42),DAY(IF(A42=umumiy_malumot!$B$81,umumiy_malumot!$B$67,IF(A42<umumiy_malumot!$B$81,(Q42),IF(A42>umumiy_malumot!$B$81,$H$56,0)))))) -> FALSE | C42: =C41-D41 -> -3.7252903e-09 | D42: =IF(C42=0,L42,IF(C42>1,I42)) -> FALSE | E42: =IF(C42=0,N41,IF(C42>1,L42)) -> FALSE | F42: =IF(C42=0,N41,IF(C42>1,M42)) -> FALSE | G42: =B42-B41 -> 0 | H42: =DATE(YEAR(B42),12,31)-DATE(YEAR(B42),1,1)+1 -> 366 | I42: =IF($L$5=A42,K42,IF($L$5>A42,I41)) -> FALSE | J42: =SUM($I$8:I41) -> 50000000 | K42: =$J$12-J42 -> 0 | L42: =ROUND(C42*umumiy_malumot!$B$84/H42,2)*G42 -> 0 | M42: =D42+E42 -> 0 | O42: =TEXT(R42,"ддд") -> Сб | P42: =IF(O42=$U$8,2,IF(O42=$V$8,1,0)) -> 2 | Q42: =DAY(umumiy_malumot!$B$78)+P42 -> 27 | R42: =IF(A42<=umumiy_malumot!$B$81,DATE(YEAR($B$8),MONTH($B$8)+A41,DAY(umumiy_malumot!$B$78)),0) -> 0
A43: =1+A42 -> 36 | B43: =IF(A43<=umumiy_malumot!$B$81,DATE(YEAR(R43),MONTH(R43),DAY(IF(A43=umumiy_malumot!$B$81,umumiy_malumot!$B$67,IF(A43<umumiy_malumot!$B$81,(Q43),IF(A43>umumiy_malumot!$B$81,$H$56,0)))))) -> FALSE | C43: =C42-D42 -> -3.7252903e-09 | D43: =IF(C43=0,L43,IF(C43>1,I43)) -> FALSE | E43: =IF(C43=0,N42,IF(C43>1,L43)) -> FALSE | F43: =IF(C43=0,N42,IF(C43>1,M43)) -> FALSE | G43: =B43-B42 -> 0 | H43: =DATE(YEAR(B43),12,31)-DATE(YEAR(B43),1,1)+1 -> 366 | I43: =IF($L$5=A43,K43,IF($L$5>A43,I42)) -> FALSE | J43: =SUM($I$8:I42) -> 50000000 | K43: =$J$12-J43 -> 0 | L43: =ROUND(C43*umumiy_malumot!$B$84/H43,2)*G43 -> 0 | M43: =D43+E43 -> 0 | O43: =TEXT(R43,"ддд") -> Сб | P43: =IF(O43=$U$8,2,IF(O43=$V$8,1,0)) -> 2 | Q43: =DAY(umumiy_malumot!$B$78)+P43 -> 27 | R43: =IF(A43<=umumiy_malumot!$B$81,DATE(YEAR($B$8),MONTH($B$8)+A42,DAY(umumiy_malumot!$B$78)),0) -> 0
... A55: =1+A54 -> 48 | B55: =IF(A55<=umumiy_malumot!$B$81,DATE(YEAR(R55),MONTH(R55),DAY(IF(A55=umumiy_malumot!$B$81,umumiy_malumot!$B$67,IF(A55<umumiy_malumot!$B$81,(Q55),IF(A55>umumiy_malumot!$B$81,$H$56,0)))))) -> FALSE | C55: =C54-D54 -> -3.7252903e-09 | D55: =IF(C55=0,L55,IF(C55>1,I55)) -> FALSE | E55: =IF(C55=0,N54,IF(C55>1,L55)) -> FALSE | F55: =IF(C55=0,N54,IF(C55>1,M55)) -> FALSE | G55: =B55-B54 -> 0 | H55: =DATE(YEAR(B55),12,31)-DATE(YEAR(B55),1,1)+1 -> 366 | I55: =IF($L$5=A55,K55,IF($L$5>A55,I54)) -> FALSE | J55: =SUM($I$8:I54) -> 50000000 | K55: =$J$12-J55 -> 0 | L55: =ROUND(C55*umumiy_malumot!$B$84/H55,2)*G55 -> 0 | M55: =D55+E55 -> 0 | O55: =TEXT(R55,"ддд") -> Сб | P55: =IF(O55=$U$8,2,IF(O55=$V$8,1,0)) -> 2 | Q55: =DAY(umumiy_malumot!$B$78)+P55 -> 27 | R55: =IF(A55<=umumiy_malumot!$B$81,DATE(YEAR($B$8),MONTH($B$8)+A54,DAY(umumiy_malumot!$B$78)),0) -> 0
B56: ИТОГО | D56: =SUM(D8:D55) -> 50000000 | E56: =SUM(E8:E55) -> 37126503 | F56: =SUM(F8:F55) -> 87126503
A58: *В случае осуществления погашения платежей по кредиту в даты, отличные от указанных в графике погашения, сумма платежа меняется на сумму процентов, которые начисляются на сумму остатка долга по микрозайму в соответствии с п.п. 2.2. настоящего договора.
...

Sheet Данные для послед. Залога
A1: № | B1: - | E1: ФИО | F1: дата | L1: № договора | M1: Сог. Сумма | N1: сог. Сумма (пропис.)
A2: 1 | B2: ha | C2: yoq | D2: ha | E2: TULYAGANOV XODJIAKBAR IRGASHEVICH | F2: 44207 | G2: =MONTH(F2) -> 1 | H2: =IF(G2=$A$26,$A$28,IF(G2=$B$26,$B$28,IF(G2=$C$26,$C$28,IF(G2=$D$26,$D$28,IF(G2=$E$26,$E$28,IF(G2=$F$26,$F$28,IF(G2=$K$26,$K$28,IF(G2=$L$26,$L$28,IF(G2=$M$26,$M$28,IF(G2=$N$26,$N$28,IF(G2=$O$26,$O$28,IF(G2=$P$26,$P$28,0)))))))))))) -> yanvar | I2: =DAY(F2) -> 11 | J2: =YEAR(F2) -> 2021 | K2: =""&I2&" "&H2&" "&J2&" г." -> 11 yanvar 2021 г. | L2: 5 | M2: 15000000 | N2: on besh million | O2: ="- №"&L2&" от "&K2&", заключенного с ООО «Clever Mikrokredit Tashkiloti» и "&E2&", по согласованной залоговой стоимость - "&FIXED(M2)&" ("&N2&") сум." -> - №5 от 11 yanvar 2021 г., заключенного с ООО «Clever Mikrokredit Tashkiloti» и TULYAGANOV XODJIAKBAR IRGASHEVICH, по согласованной залоговой стоимость - 15 000 000,00 (on besh million) сум. | P2: =IF(D2=$B$2,O2,IF(D2=$C$2,$B$1)) -> - №5 от 11 yanvar 2021 г., заключенного с ООО «Clever Mikrokredit Tashkiloti» и TULYAGANOV XODJIAKBAR IRGASHEVICH, по согласованной залоговой стоимость - 15 000 000,00 (on besh million) сум. | W2: =""&P2&" "&P3&" "&P4&" "&P5&" "&P6&" "&P7&" "&P8&" "&P9&" "&P10&" "&P11&" "&P12&" "&P13&" "&P14&" "&P15&" "&P16&" "&P17&" "&P18&" "&P19&" "&P20&" "&P21&"" -> - №5 от 11 yanvar 2021 г., заключенного с ООО «Clever Mikrokredit Tashkiloti» и TULYAGANOV XODJIAKBAR IRGASHEVICH, по согласованной залоговой стоимость - 15 000 000,00 (on besh million) сум. - №386 от 6 noyabr 2019 г., заключенного с ООО «Clever Mikrokredit Tashkiloti» и YUNUSOVA ZALOXAT MIRSULTANOVNA, по согласованной залоговой стоимость - 15 000 000,00 (on besh million) сум. - №33 от 21 yanvar 2021 г., заключенного с ООО «Clever Mikrokredit Tashkiloti» и YUNUSOVA ZALOXAT MIRSULTANOVNA, по согласованной залоговой стоимость - 15 000 000,00 (on besh million) сум. 0 0 0 0 0 0 0 0 0 0 0 0 0 0 0 0 0
A3: 2 | D3: ha | E3: YUNUSOVA ZALOXAT MIRSULTANOVNA | F3: 43775 | G3: =MONTH(F3) -> 11 | H3: =IF(G3=$A$26,$A$28,IF(G3=$B$26,$B$28,IF(G3=$C$26,$C$28,IF(G3=$D$26,$D$28,IF(G3=$E$26,$E$28,IF(G3=$F$26,$F$28,IF(G3=$K$26,$K$28,IF(G3=$L$26,$L$28,IF(G3=$M$26,$M$28,IF(G3=$N$26,$N$28,IF(G3=$O$26,$O$28,IF(G3=$P$26,$P$28,0)))))))))))) -> noyabr | I3: =DAY(F3) -> 6 | J3: =YEAR(F3) -> 2019 | K3: =""&I3&" "&H3&" "&J3&" г." -> 6 noyabr 2019 г. | L3: 386 | M3: 15000000 | N3: on besh million | O3: ="- №"&L3&" от "&K3&", заключенного с ООО «Clever Mikrokredit Tashkiloti» и "&E3&", по согласованной залоговой стоимость - "&FIXED(M3)&" ("&N3&") сум." -> - №386 от 6 noyabr 2019 г., заключенного с ООО «Clever Mikrokredit Tashkiloti» и YUNUSOVA ZALOXAT MIRSULTANOVNA, по согласованной залоговой стоимость - 15 000 000,00 (on besh million) сум. | P3: =IF(D3=$B$2,O3,IF(D3=$C$2,$B$1)) -> - №386 от 6 noyabr 2019 г., заключенного с ООО «Clever Mikrokredit Tashkiloti» и YUNUSOVA ZALOXAT MIRSULTANOVNA, по согласованной залоговой стоимость - 15 000 000,00 (on besh million) сум.
A4: 3 | D4: ha | E4: YUNUSOVA ZALOXAT MIRSULTANOVNA | F4: 44217 | G4: =MONTH(F4) -> 1 | H4: =IF(G4=$A$26,$A$28,IF(G4=$B$26,$B$28,IF(G4=$C$26,$C$28,IF(G4=$D$26,$D$28,IF(G4=$E$26,$E$28,IF(G4=$F$26,$F$28,IF(G4=$K$26,$K$28,IF(G4=$L$26,$L$28,IF(G4=$M$26,$M$28,IF(G4=$N$26,$N$28,IF(G4=$O$26,$O$28,IF(G4=$P$26,$P$28,0)))))))))))) -> yanvar | I4: =DAY(F4) -> 21 | J4: =YEAR(F4) -> 2021 | K4: =""&I4&" "&H4&" "&J4&" г." -> 21 yanvar 2021 г. | L4: 33 | M4: 15000000 | N4: on besh million | O4: ="- №"&L4&" от "&K4&", заключенного с ООО «Clever Mikrokredit Tashkiloti» и "&E4&", по согласованной залоговой стоимость - "&FIXED(M4)&" ("&N4&") сум." -> - №33 от 21 yanvar 2021 г., заключенного с ООО «Clever Mikrokredit Tashkiloti» и YUNUSOVA ZALOXAT MIRSULTANOVNA, по согласованной залоговой стоимость - 15 000 000,00 (on besh million) сум. | P4: =IF(D4=$B$2,O4,IF(D4=$C$2,$B$1)) -> - №33 от 21 yanvar 2021 г., заключенного с ООО «Clever Mikrokredit Tashkiloti» и YUNUSOVA ZALOXAT MIRSULTANOVNA, по согласованной залоговой стоимость - 15 000 000,00 (on besh million) сум.
A5: 4 | D5: ha | G5: =MONTH(F5) -> 1 | H5: =IF(G5=$A$26,$A$28,IF(G5=$B$26,$B$28,IF(G5=$C$26,$C$28,IF(G5=$D$26,$D$28,IF(G5=$E$26,$E$28,IF(G5=$F$26,$F$28,IF(G5=$K$26,$K$28,IF(G5=$L$26,$L$28,IF(G5=$M$26,$M$28,IF(G5=$N$26,$N$28,IF(G5=$O$26,$O$28,IF(G5=$P$26,$P$28,0)))))))))))) -> yanvar | I5: =DAY(F5) -> 0 | J5: =YEAR(F5) -> 1900 | K5: =""&I5&" "&H5&" "&J5&" г." -> 0 yanvar 1900 г. | P5: =IF(D5=$B$2,O5,IF(D5=$C$2,$B$1)) -> 0
A6: 5 | D6: ha | G6: =MONTH(F6) -> 1 | H6: =IF(G6=$A$26,$A$28,IF(G6=$B$26,$B$28,IF(G6=$C$26,$C$28,IF(G6=$D$26,$D$28,IF(G6=$E$26,$E$28,IF(G6=$F$26,$F$28,IF(G6=$K$26,$K$28,IF(G6=$L$26,$L$28,IF(G6=$M$26,$M$28,IF(G6=$N$26,$N$28,IF(G6=$O$26,$O$28,IF(G6=$P$26,$P$28,0)))))))))))) -> yanvar | I6: =DAY(F6) -> 0 | J6: =YEAR(F6) -> 1900 | K6: =""&I6&" "&H6&" "&J6&" г." -> 0 yanvar 1900 г. | P6: =IF(D6=$B$2,O6,IF(D6=$C$2,$B$1)) -> 0
A7: 6 | D7: ha | G7: =MONTH(F7) -> 1 | H7: =IF(G7=$A$26,$A$28,IF(G7=$B$26,$B$28,IF(G7=$C$26,$C$28,IF(G7=$D$26,$D$28,IF(G7=$E$26,$E$28,IF(G7=$F$26,$F$28,IF(G7=$K$26,$K$28,IF(G7=$L$26,$L$28,IF(G7=$M$26,$M$28,IF(G7=$N$26,$N$28,IF(G7=$O$26,$O$28,IF(G7=$P$26,$P$28,0)))))))))))) -> yanvar | I7: =DAY(F7) -> 0 | J7: =YEAR(F7) -> 1900 | K7: =""&I7&" "&H7&" "&J7&" г." -> 0 yanvar 1900 г. | P7: =IF(D7=$B$2,O7,IF(D7=$C$2,$B$1)) -> 0
A8: 7 | D8: ha | G8: =MONTH(F8) -> 1 | H8: =IF(G8=$A$26,$A$28,IF(G8=$B$26,$B$28,IF(G8=$C$26,$C$28,IF(G8=$D$26,$D$28,IF(G8=$E$26,$E$28,IF(G8=$F$26,$F$28,IF(G8=$K$26,$K$28,IF(G8=$L$26,$L$28,IF(G8=$M$26,$M$28,IF(G8=$N$26,$N$28,IF(G8=$O$26,$O$28,IF(G8=$P$26,$P$28,0)))))))))))) -> yanvar | I8: =DAY(F8) -> 0 | J8: =YEAR(F8) -> 1900 | K8: =""&I8&" "&H8&" "&J8&" г." -> 0 yanvar 1900 г. | P8: =IF(D8=$B$2,O8,IF(D8=$C$2,$B$1)) -> 0
A9: 8 | D9: ha | G9: =MONTH(F9) -> 1 | H9: =IF(G9=$A$26,$A$28,IF(G9=$B$26,$B$28,IF(G9=$C$26,$C$28,IF(G9=$D$26,$D$28,IF(G9=$E$26,$E$28,IF(G9=$F$26,$F$28,IF(G9=$K$26,$K$28,IF(G9=$L$26,$L$28,IF(G9=$M$26,$M$28,IF(G9=$N$26,$N$28,IF(G9=$O$26,$O$28,IF(G9=$P$26,$P$28,0)))))))))))) -> yanvar | I9: =DAY(F9) -> 0 | J9: =YEAR(F9) -> 1900 | K9: =""&I9&" "&H9&" "&J9&" г." -> 0 yanvar 1900 г. | P9: =IF(D9=$B$2,O9,IF(D9=$C$2,$B$1)) -> 0
A10: 9 | D10: ha | G10: =MONTH(F10) -> 1 | H10: =IF(G10=$A$26,$A$28,IF(G10=$B$26,$B$28,IF(G10=$C$26,$C$28,IF(G10=$D$26,$D$28,IF(G10=$E$26,$E$28,IF(G10=$F$26,$F$28,IF(G10=$K$26,$K$28,IF(G10=$L$26,$L$28,IF(G10=$M$26,$M$28,IF(G10=$N$26,$N$28,IF(G10=$O$26,$O$28,IF(G10=$P$26,$P$28,0)))))))))))) -> yanvar | I10: =DAY(F10) -> 0 | J10: =YEAR(F10) -> 1900 | K10: =""&I10&" "&H10&" "&J10&" г." -> 0 yanvar 1900 г. | P10: =IF(D10=$B$2,O10,IF(D10=$C$2,$B$1)) -> 0
A11: 10 | D11: ha | G11: =MONTH(F11) -> 1 | H11: =IF(G11=$A$26,$A$28,IF(G11=$B$26,$B$28,IF(G11=$C$26,$C$28,IF(G11=$D$26,$D$28,IF(G11=$E$26,$E$28,IF(G11=$F$26,$F$28,IF(G11=$K$26,$K$28,IF(G11=$L$26,$L$28,IF(G11=$M$26,$M$28,IF(G11=$N$26,$N$28,IF(G11=$O$26,$O$28,IF(G11=$P$26,$P$28,0)))))))))))) -> yanvar | I11: =DAY(F11) -> 0 | J11: =YEAR(F11) -> 1900 | K11: =""&I11&" "&H11&" "&J11&" г." -> 0 yanvar 1900 г. | P11: =IF(D11=$B$2,O11,IF(D11=$C$2,$B$1)) -> 0
A12: 11 | D12: ha | G12: =MONTH(F12) -> 1 | H12: =IF(G12=$A$26,$A$28,IF(G12=$B$26,$B$28,IF(G12=$C$26,$C$28,IF(G12=$D$26,$D$28,IF(G12=$E$26,$E$28,IF(G12=$F$26,$F$28,IF(G12=$K$26,$K$28,IF(G12=$L$26,$L$28,IF(G12=$M$26,$M$28,IF(G12=$N$26,$N$28,IF(G12=$O$26,$O$28,IF(G12=$P$26,$P$28,0)))))))))))) -> yanvar | I12: =DAY(F12) -> 0 | J12: =YEAR(F12) -> 1900 | K12: =""&I12&" "&H12&" "&J12&" г." -> 0 yanvar 1900 г. | P12: =IF(D12=$B$2,O12,IF(D12=$C$2,$B$1)) -> 0
A13: 12 | D13: ha | G13: =MONTH(F13) -> 1 | H13: =IF(G13=$A$26,$A$28,IF(G13=$B$26,$B$28,IF(G13=$C$26,$C$28,IF(G13=$D$26,$D$28,IF(G13=$E$26,$E$28,IF(G13=$F$26,$F$28,IF(G13=$K$26,$K$28,IF(G13=$L$26,$L$28,IF(G13=$M$26,$M$28,IF(G13=$N$26,$N$28,IF(G13=$O$26,$O$28,IF(G13=$P$26,$P$28,0)))))))))))) -> yanvar | I13: =DAY(F13) -> 0 | J13: =YEAR(F13) -> 1900 | K13: =""&I13&" "&H13&" "&J13&" г." -> 0 yanvar 1900 г. | P13: =IF(D13=$B$2,O13,IF(D13=$C$2,$B$1)) -> 0
A14: 13 | D14: ha | G14: =MONTH(F14) -> 1 | H14: =IF(G14=$A$26,$A$28,IF(G14=$B$26,$B$28,IF(G14=$C$26,$C$28,IF(G14=$D$26,$D$28,IF(G14=$E$26,$E$28,IF(G14=$F$26,$F$28,IF(G14=$K$26,$K$28,IF(G14=$L$26,$L$28,IF(G14=$M$26,$M$28,IF(G14=$N$26,$N$28,IF(G14=$O$26,$O$28,IF(G14=$P$26,$P$28,0)))))))))))) -> yanvar | I14: =DAY(F14) -> 0 | J14: =YEAR(F14) -> 1900 | K14: =""&I14&" "&H14&" "&J14&" г." -> 0 yanvar 1900 г. | P14: =IF(D14=$B$2,O14,IF(D14=$C$2,$B$1)) -> 0
A15: 14 | D15: ha | G15: =MONTH(F15) -> 1 | H15: =IF(G15=$A$26,$A$28,IF(G15=$B$26,$B$28,IF(G15=$C$26,$C$28,IF(G15=$D$26,$D$28,IF(G15=$E$26,$E$28,IF(G15=$F$26,$F$28,IF(G15=$K$26,$K$28,IF(G15=$L$26,$L$28,IF(G15=$M$26,$M$28,IF(G15=$N$26,$N$28,IF(G15=$O$26,$O$28,IF(G15=$P$26,$P$28,0)))))))))))) -> yanvar | I15: =DAY(F15) -> 0 | J15: =YEAR(F15) -> 1900 | K15: =""&I15&" "&H15&" "&J15&" г." -> 0 yanvar 1900 г. | P15: =IF(D15=$B$2,O15,IF(D15=$C$2,$B$1)) -> 0
A16: 15 | D16: ha | G16: =MONTH(F16) -> 1 | H16: =IF(G16=$A$26,$A$28,IF(G16=$B$26,$B$28,IF(G16=$C$26,$C$28,IF(G16=$D$26,$D$28,IF(G16=$E$26,$E$28,IF(G16=$F$26,$F$28,IF(G16=$K$26,$K$28,IF(G16=$L$26,$L$28,IF(G16=$M$26,$M$28,IF(G16=$N$26,$N$28,IF(G16=$O$26,$O$28,IF(G16=$P$26,$P$28,0)))))))))))) -> yanvar | I16: =DAY(F16) -> 0 | J16: =YEAR(F16) -> 1900 | K16: =""&I16&" "&H16&" "&J16&" г." -> 0 yanvar 1900 г. | P16: =IF(D16=$B$2,O16,IF(D16=$C$2,$B$1)) -> 0
... A21: 20 | D21: ha | G21: =MONTH(F21) -> 1 | H21: =IF(G21=$A$26,$A$28,IF(G21=$B$26,$B$28,IF(G21=$C$26,$C$28,IF(G21=$D$26,$D$28,IF(G21=$E$26,$E$28,IF(G21=$F$26,$F$28,IF(G21=$K$26,$K$28,IF(G21=$L$26,$L$28,IF(G21=$M$26,$M$28,IF(G21=$N$26,$N$28,IF(G21=$O$26,$O$28,IF(G21=$P$26,$P$28,0)))))))))))) -> yanvar | I21: =DAY(F21) -> 0 | J21: =YEAR(F21) -> 1900 | K21: =""&I21&" "&H21&" "&J21&" г." -> 0 yanvar 1900 г. | P21: =IF(D21=$B$2,O21,IF(D21=$C$2,$B$1)) -> 0
M22: =SUM(M2:M21)+umumiy_malumot!B136 -> 115000000 | Q22: ottiz yetti million besh yuz ming
A25: =MONTH(F2) -> 1 | B25: =IF(A25=A26,A28,IF(A25=B26,B28,IF(A25=C26,C28,IF(A25=D26,D28,IF(A25=E26,E28,IF(A25=F26,F28,IF(A25=K26,K28,IF(A25=L26,L28,IF(A25=M26,M28,IF(A25=N26,N28,IF(A25=O26,O28,IF(A25=#REF!,#REF!,)))))))))))) -> yanvar | C25: =DAY(F2) -> 11 | D25: =YEAR(F2) -> 2021
A26: 1 | B26: 2 | C26: 3 | D26: 4 | E26: 5 | F26: 6 | K26: 7 | L26: 8 | M26: 9 | N26: 10 | O26: 11 | P26: 12
A28: yanvar | B28: fevral | C28: mart | D28: aprel | E28: may | F28: iyun | K28: июля | L28: avgust | M28: sentyabr | N28: oktyabr | O28: noyabr | P28: dekabr
A29: yanvar | B29: fevral | C29: mart | D29: aprel | E29: may | F29: iyun | K29: июль | L29: avgust | M29: sentyabr | N29: oktyabr | O29: noyabr | P29: dekabr

Sheet umumiy_malumot
A1: =CONCATENATE(B65," olish uchun ariza") -> Mikroqarz olish uchun ariza | B1: № 56
A2: =CONCATENATE(B65," olish uchun ariza sanasi QO’L BILAN KIRITILADI") -> Mikroqarz olish uchun ariza sanasi QO’L BILAN KIRITILADI | B2: 02.02.2026 | D2: =180+B2 -> 46235
A4: Qarz oluvchi bo’yicha ma’lumotlar
A5: Ariza beruvchining FISh (kim? – Ibragimov Rustam Sadikovich) | B5: QODIROVA NAFISA YO‘LDOSHEVNA
A6: agar o’zgarishlar bo’lgan bo’lsa oldingi FISh (Sadikov Rustam Sadikovich yoki yo’q) | B6: yo’q | C6: ha | D6: yo’q
A7: Ariza beruvchining FISh (kim? – Ibragimov R.S.) | B7: QODIROVA N.Y.
A8: FISh (ariza kimdan? – Ibragimov Rustam Sadikovichdan) | B8: =B5 -> QODIROVA NAFISA YO‘LDOSHEVNA
A9: FISh (kimdan? – Ibragimov R.S.dan) | B9: =B7 -> QODIROVA N.Y.
A10: FISh (kimga? – Ibragimov Rustam Sadikovichga) | B10: =B8 -> QODIROVA NAFISA YO‘LDOSHEVNA
A11: FISh (kimga? – Ibragimov R.S.ga) | B11: =B9 -> QODIROVA N.Y.
A12: FISh (kim bilan? – Ibragimov Rustam Sadikovich bilan) | B12: =B10 -> QODIROVA NAFISA YO‘LDOSHEVNA
A13: FISh (kim bilan? – Ibragimov R.S. bilan) | B13: =B11 -> QODIROVA N.Y.
A14: Fuqaroligi (O’zbekiston Respublikasi) | B14: O’zbekiston Respublikasi
A15: Tug’ilgan sanasi (01.10.2011 yil) | B15: 16.07.1982 yil
A16: Pasport seriyasi (СА №1234567) | B16: AD 9088376
B17: IIV 26296 | D17: =TEXT(C17,"ДД.ММ.ГГГГ") -> 00.01.1900
B18: 45586 | C18: =TEXT(B18,"ДД.ММ.ГГГГ") -> 21.10.2024
B19: =DATE(YEAR(B18)+10,MONTH(B18),DAY(B18)-1) -> 49237 | C19: =TEXT(B19,"ДД.ММ.ГГГГ") -> 20.10.2034
A20: Kim va qachon berilgan (Toshkent shahri Chilonzor IIB tomonidan 2011 yil __.____) | B20: =""&B17&" tomonidan "&C18&" yilda berilgan" -> IIV 26296 tomonidan 21.10.2024 yilda berilgan | C20: =""&B17&" tomonidan "&C18&" yilda berilgan" -> IIV 26296 tomonidan 21.10.2024 yilda berilgan
A21: Pasportni amal qilish muddati (01.10.2011 yilgacha / yoki muddatsiz) | B21: =""&C19&" y." -> 20.10.2034 y. | C21: =""&C19&" yilgacha" -> 20.10.2034 yilgacha
A22: doimiy ro’yhatdan o’tgan joyi (Toshkent sh., Mirobod tumani, Nukus ko’chasi, 1 uy, 1 honadon) | B22: TOSHKENT SHAHAR YANGIXAYOT TUMANI 2 STROITELNAYA TERRITORIYA 17 UY 74 XONADON
A23: doimiy ro’yhatdan o’tgan joyi haqiqatdagi turar joyi bilan mos keladi/mos kelmaydi | B23: mos kelmaydi | C23: mos keladi | D23: mos kelmaydi
A24: Ro’yhatdan o’tish joyida yashash asosi | B24: Mulk huquqi | C24: Mulk huquqi | D24: ijara | E24: служебная | F24: другое | G24: -
A25: Telefon raqami kod bilan ((99871) 277 77 77) | B25: 90 809 80 43 MIJOZ
A26: Mo’ljal | B26: 2 BEKAT
B27: =IF(B23="mos keladi",B22,B28) -> TOSHKENT SHAHAR BEKTEMIR TUMANI ROXAT KO'CHASI 12 UY 32 XONADON
A28: Haqiqatdagi yashash joyi (Toshkent sh., Mirobod tumani, Nukus ko’chasi, 1 uy, 1 honadon) | B28: TOSHKENT SHAHAR BEKTEMIR TUMANI ROXAT KO'CHASI 12 UY 32 XONADON
A29: Haqiqatdagi yashash joyida turish asosi | B29: Mulk huquqi | C29: Mulk huquqi | D29: ijara | E29: xizmat | F29: boshqa | G29: -
A30: Mijozning jinsi | B30: ayol | C30: erkak | D30: ayol
A31: Tug’ilgan joyi (Toshkent) | B31: FARG'ONA SHAHRI
A32: Fuqaroligi (O’zbekiston Respublikasi) | B32: O’zbekiston Respublikasi
A33: Telefon raqami kod bilan ((99871) 277 77 77) | B33: =B25 -> 90 809 80 43 MIJOZ
B34: =IF(B23="mos keladi",B26,B35) -> 0
A35: Mo’ljal
A36: Oilaviy ahvoli
A37: Oila a'zolari soni (jami):
A38: Ma’lumoti
A39: Mutaxassisligi
A40: Ish telefoni raqami kod bilan ((99890) 3270000) | B40: =B33 -> 90 809 80 43 MIJOZ
A41: Mobil telefon raqami kod bilan ((99890) 3270000) | B41: 90 120 24 08 ERI
...

Sheet График аннуитет.
E1: Приложение №1
F2: ="к договору микрозайма "&umumiy_malumot!B74&"" -> к договору микрозайма 2 fevral 2026 y.dan № 56
A4: График погашения
A6: № | B6: Дата погашения | C6: Остаток основного долга | D6: Сумма погашения, сум
D7: основного долга | E7: процентов* | F7: всего*
A8: 1 | B8: ='График дифференц'!B8 -> 46106 | C8: =umumiy_malumot!B75 -> 50000000 | D8: =IF(A8<umumiy_malumot!$B$81,'График аннуитет.'!F8-'График аннуитет.'!E8,'График аннуитет.'!C8) -> -742465.97 | E8: =ROUND(C8*umumiy_malumot!$B$84/H8,2)*'График аннуитет.'!G8 -> 3842466 | F8: =umumiy_malumot!B90 -> 3100000 | G8: =B8-umumiy_malumot!B67 -> 51 | H8: =DATE(YEAR(B8),12,31)-DATE(YEAR(B8),1,1)+1 -> 365
A9: 2 | B9: ='График дифференц'!B9 -> 46139 | C9: =C8-D8 -> 50742466 | D9: =IF(A9<umumiy_malumot!$B$81,'График аннуитет.'!F9-'График аннуитет.'!E9,'График аннуитет.'!C9) -> 576778.75 | E9: =ROUND(C9*umumiy_malumot!$B$84/H9,2)*'График аннуитет.'!G9 -> 2523221.2 | F9: =IF(A9<umumiy_malumot!$B$81,'График аннуитет.'!F8,'График аннуитет.'!D9+'График аннуитет.'!E9) -> 3100000 | G9: =B9-B8 -> 33 | H9: =DATE(YEAR(B9),12,31)-DATE(YEAR(B9),1,1)+1 -> 365
A10: 3 | B10: ='График дифференц'!B10 -> 46167 | C10: =C9-D9 -> 50165687 | D10: =IF(A10<umumiy_malumot!$B$81,'График аннуитет.'!F10-'График аннуитет.'!E10,'График аннуитет.'!C10) -> 983420.36 | E10: =ROUND(C10*umumiy_malumot!$B$84/H10,2)*'График аннуитет.'!G10 -> 2116579.6 | F10: =IF(A10<umumiy_malumot!$B$81,'График аннуитет.'!F9,'График аннуитет.'!D10+'График аннуитет.'!E10) -> 3100000 | G10: =B10-B9 -> 28 | H10: =DATE(YEAR(B10),12,31)-DATE(YEAR(B10),1,1)+1 -> 365
A11: 4 | B11: ='График дифференц'!B11 -> 46198 | C11: =C10-D10 -> 49182267 | D11: =IF(A11<umumiy_malumot!$B$81,'График аннуитет.'!F11-'График аннуитет.'!E11,'График аннуитет.'!C11) -> 802581.63 | E11: =ROUND(C11*umumiy_malumot!$B$84/H11,2)*'График аннуитет.'!G11 -> 2297418.4 | F11: =IF(A11<umumiy_malumot!$B$81,'График аннуитет.'!F10,'График аннуитет.'!D11+'График аннуитет.'!E11) -> 3100000 | G11: =B11-B10 -> 31 | H11: =DATE(YEAR(B11),12,31)-DATE(YEAR(B11),1,1)+1 -> 365
A12: 5 | B12: ='График дифференц'!B12 -> 46230 | C12: =C11-D11 -> 48379685 | D12: =IF(A12<umumiy_malumot!$B$81,'График аннуитет.'!F12-'График аннуитет.'!E12,'График аннуитет.'!C12) -> 767171.2 | E12: =ROUND(C12*umumiy_malumot!$B$84/H12,2)*'График аннуитет.'!G12 -> 2332828.8 | F12: =IF(A12<umumiy_malumot!$B$81,'График аннуитет.'!F11,'График аннуитет.'!D12+'График аннуитет.'!E12) -> 3100000 | G12: =B12-B11 -> 32 | H12: =DATE(YEAR(B12),12,31)-DATE(YEAR(B12),1,1)+1 -> 365
A13: 6 | B13: ='График дифференц'!B13 -> 46259 | C13: =C12-D12 -> 47612514 | D13: =IF(A13<umumiy_malumot!$B$81,'График аннуитет.'!F13-'График аннуитет.'!E13,'График аннуитет.'!C13) -> 1019398.5 | E13: =ROUND(C13*umumiy_malumot!$B$84/H13,2)*'График аннуитет.'!G13 -> 2080601.5 | F13: =IF(A13<umumiy_malumot!$B$81,'График аннуитет.'!F12,'График аннуитет.'!D13+'График аннуитет.'!E13) -> 3100000 | G13: =B13-B12 -> 29 | H13: =DATE(YEAR(B13),12,31)-DATE(YEAR(B13),1,1)+1 -> 365
A14: 7 | B14: ='График дифференц'!B14 -> 46290 | C14: =C13-D13 -> 46593116 | D14: =IF(A14<umumiy_malumot!$B$81,'График аннуитет.'!F14-'График аннуитет.'!E14,'График аннуитет.'!C14) -> 923527.2 | E14: =ROUND(C14*umumiy_malumot!$B$84/H14,2)*'График аннуитет.'!G14 -> 2176472.8 | F14: =IF(A14<umumiy_malumot!$B$81,'График аннуитет.'!F13,'График аннуитет.'!D14+'График аннуитет.'!E14) -> 3100000 | G14: =B14-B13 -> 31 | H14: =DATE(YEAR(B14),12,31)-DATE(YEAR(B14),1,1)+1 -> 365
A15: 8 | B15: ='График дифференц'!B15 -> 46321 | C15: =C14-D14 -> 45669588 | D15: =IF(A15<umumiy_malumot!$B$81,'График аннуитет.'!F15-'График аннуитет.'!E15,'График аннуитет.'!C15) -> 966667.11 | E15: =ROUND(C15*umumiy_malumot!$B$84/H15,2)*'График аннуитет.'!G15 -> 2133332.9 | F15: =IF(A15<umumiy_malumot!$B$81,'График аннуитет.'!F14,'График аннуитет.'!D15+'График аннуитет.'!E15) -> 3100000 | G15: =B15-B14 -> 31 | H15: =DATE(YEAR(B15),12,31)-DATE(YEAR(B15),1,1)+1 -> 365
A16: 9 | B16: ='График дифференц'!B16 -> 46351 | C16: =C15-D15 -> 44702921 | D16: =IF(A16<umumiy_malumot!$B$81,'График аннуитет.'!F16-'График аннуитет.'!E16,'График аннуитет.'!C16) -> 1079182.9 | E16: =ROUND(C16*umumiy_malumot!$B$84/H16,2)*'График аннуитет.'!G16 -> 2020817.1 | F16: =IF(A16<umumiy_malumot!$B$81,'График аннуитет.'!F15,'График аннуитет.'!D16+'График аннуитет.'!E16) -> 3100000 | G16: =B16-B15 -> 30 | H16: =DATE(YEAR(B16),12,31)-DATE(YEAR(B16),1,1)+1 -> 365
A17: 10 | B17: ='График дифференц'!B17 -> 46381 | C17: =C16-D16 -> 43623738 | D17: =IF(A17<umumiy_malumot!$B$81,'График аннуитет.'!F17-'График аннуитет.'!E17,'График аннуитет.'!C17) -> 1127968 | E17: =ROUND(C17*umumiy_malumot!$B$84/H17,2)*'График аннуитет.'!G17 -> 1972032 | F17: =IF(A17<umumiy_malumot!$B$81,'График аннуитет.'!F16,'График аннуитет.'!D17+'График аннуитет.'!E17) -> 3100000 | G17: =B17-B16 -> 30 | H17: =DATE(YEAR(B17),12,31)-DATE(YEAR(B17),1,1)+1 -> 365
A18: 11 | B18: ='График дифференц'!B18 -> 46412 | C18: =C17-D17 -> 42495770 | D18: =IF(A18<umumiy_malumot!$B$81,'График аннуитет.'!F18-'График аннуитет.'!E18,'График аннуитет.'!C18) -> 1114923.7 | E18: =ROUND(C18*umumiy_malumot!$B$84/H18,2)*'График аннуитет.'!G18 -> 1985076.3 | F18: =IF(A18<umumiy_malumot!$B$81,'График аннуитет.'!F17,'График аннуитет.'!D18+'График аннуитет.'!E18) -> 3100000 | G18: =B18-B17 -> 31 | H18: =DATE(YEAR(B18),12,31)-DATE(YEAR(B18),1,1)+1 -> 365
A19: 12 | B19: ='График дифференц'!B19 -> 46443 | C19: =C18-D18 -> 41380847 | D19: =IF(A19<umumiy_malumot!$B$81,'График аннуитет.'!F19-'График аннуитет.'!E19,'График аннуитет.'!C19) -> 1167004.3 | E19: =ROUND(C19*umumiy_malumot!$B$84/H19,2)*'График аннуитет.'!G19 -> 1932995.7 | F19: =IF(A19<umumiy_malumot!$B$81,'График аннуитет.'!F18,'График аннуитет.'!D19+'График аннуитет.'!E19) -> 3100000 | G19: =B19-B18 -> 31 | H19: =DATE(YEAR(B19),12,31)-DATE(YEAR(B19),1,1)+1 -> 365
A20: 13 | B20: ='График дифференц'!B20 -> 46471 | C20: =C19-D19 -> 40213842 | D20: =IF(A20<umumiy_malumot!$B$81,'График аннуитет.'!F20-'График аннуитет.'!E20,'График аннуитет.'!C20) -> 1403306.4 | E20: =ROUND(C20*umumiy_malumot!$B$84/H20,2)*'График аннуитет.'!G20 -> 1696693.6 | F20: =IF(A20<umumiy_malumot!$B$81,'График аннуитет.'!F19,'График аннуитет.'!D20+'График аннуитет.'!E20) -> 3100000 | G20: =B20-B19 -> 28 | H20: =DATE(YEAR(B20),12,31)-DATE(YEAR(B20),1,1)+1 -> 365
... A31: 24 | B31: ='График дифференц'!B31 -> 46808 | C31: =C30-D30 -> 22653106 | D31: =IF(A31<umumiy_malumot!$B$81,'График аннуитет.'!F31-'График аннуитет.'!E31,'График аннуитет.'!C31) -> 2044711.9 | E31: =ROUND(C31*umumiy_malumot!$B$84/H31,2)*'График аннуитет.'!G31 -> 1055288.1 | F31: =IF(A31<umumiy_malumot!$B$81,'График аннуитет.'!F30,'График аннуитет.'!D31+'График аннуитет.'!E31) -> 3100000 | G31: =B31-B30 -> 31 | H31: =DATE(YEAR(B31),12,31)-DATE(YEAR(B31),1,1)+1 -> 366
A32: =1+A31 -> 25 | B32: ='График дифференц'!B32 -> 46839 | C32: =C31-D31 -> 20608394 | D32: =IF(A32<umumiy_malumot!$B$81,'График аннуитет.'!F32-'График аннуитет.'!E32,'График аннуитет.'!C32) -> 2139964.1 | E32: =ROUND(C32*umumiy_malumot!$B$84/H32,2)*'График аннуитет.'!G32 -> 960035.9 | F32: =IF(A32<umumiy_malumot!$B$81,'График аннуитет.'!F31,'График аннуитет.'!D32+'График аннуитет.'!E32) -> 3100000 | G32: =B32-B31 -> 31 | H32: =DATE(YEAR(B32),12,31)-DATE(YEAR(B32),1,1)+1 -> 366
A33: =1+A32 -> 26 | B33: ='График дифференц'!B33 -> 46868 | C33: =C32-D32 -> 18468430 | D33: =IF(A33<umumiy_malumot!$B$81,'График аннуитет.'!F33-'График аннуитет.'!E33,'График аннуитет.'!C33) -> 2295159.8 | E33: =ROUND(C33*umumiy_malumot!$B$84/H33,2)*'График аннуитет.'!G33 -> 804840.19 | F33: =IF(A33<umumiy_malumot!$B$81,'График аннуитет.'!F32,'График аннуитет.'!D33+'График аннуитет.'!E33) -> 3100000 | G33: =B33-B32 -> 29 | H33: =DATE(YEAR(B33),12,31)-DATE(YEAR(B33),1,1)+1 -> 366
A34: =1+A33 -> 27 | B34: ='График дифференц'!B34 -> 46898 | C34: =C33-D33 -> 16173270 | D34: =IF(A34<umumiy_malumot!$B$81,'График аннуитет.'!F34-'График аннуитет.'!E34,'График аннуитет.'!C34) -> 2370877.3 | E34: =ROUND(C34*umumiy_malumot!$B$84/H34,2)*'График аннуитет.'!G34 -> 729122.7 | F34: =IF(A34<umumiy_malumot!$B$81,'График аннуитет.'!F33,'График аннуитет.'!D34+'График аннуитет.'!E34) -> 3100000 | G34: =B34-B33 -> 30 | H34: =DATE(YEAR(B34),12,31)-DATE(YEAR(B34),1,1)+1 -> 366
A35: =1+A34 -> 28 | B35: ='График дифференц'!B35 -> 46930 | C35: =C34-D34 -> 13802393 | D35: =IF(A35<umumiy_malumot!$B$81,'График аннуитет.'!F35-'График аннуитет.'!E35,'График аннуитет.'!C35) -> 2436278.4 | E35: =ROUND(C35*umumiy_malumot!$B$84/H35,2)*'График аннуитет.'!G35 -> 663721.6 | F35: =IF(A35<umumiy_malumot!$B$81,'График аннуитет.'!F34,'График аннуитет.'!D35+'График аннуитет.'!E35) -> 3100000 | G35: =B35-B34 -> 32 | H35: =DATE(YEAR(B35),12,31)-DATE(YEAR(B35),1,1)+1 -> 366
A36: =1+A35 -> 29 | B36: ='График дифференц'!B36 -> 46959 | C36: =C35-D35 -> 11366115 | D36: =IF(A36<umumiy_malumot!$B$81,'График аннуитет.'!F36-'График аннуитет.'!E36,'График аннуитет.'!C36) -> 2604673.3 | E36: =ROUND(C36*umumiy_malumot!$B$84/H36,2)*'График аннуитет.'!G36 -> 495326.67 | F36: =IF(A36<umumiy_malumot!$B$81,'График аннуитет.'!F35,'График аннуитет.'!D36+'График аннуитет.'!E36) -> 3100000 | G36: =B36-B35 -> 29 | H36: =DATE(YEAR(B36),12,31)-DATE(YEAR(B36),1,1)+1 -> 366
